{
 "cells": [
  {
   "cell_type": "markdown",
   "metadata": {},
   "source": [
    "# Setup"
   ]
  },
  {
   "cell_type": "markdown",
   "metadata": {},
   "source": [
    "## Packages"
   ]
  },
  {
   "cell_type": "code",
   "execution_count": 39,
   "metadata": {},
   "outputs": [],
   "source": [
    "import pandas as pd\n",
    "import numpy as np\n",
    "import yaml\n",
    "from tqdm import tqdm\n",
    "import time\n",
    "\n",
    "# for using configuration files like yamls. This is to help key our keys safe\n",
    "import hydra\n",
    "from omegaconf import DictConfig, OmegaConf\n",
    "\n",
    "import multiprocessing\n",
    "import requests\n",
    "\n",
    "import urllib\n",
    "import os\n",
    "import json\n",
    "\n",
    "\n",
    "# unzip files\n",
    "import gzip\n",
    "import shutil\n",
    "\n",
    "# @hydra.main(config_path=\"../conf\", config_name=\"main\", version_base=None)"
   ]
  },
  {
   "cell_type": "code",
   "execution_count": null,
   "metadata": {},
   "outputs": [],
   "source": [
    "from semanticscholar import SemanticScholar\n",
    "sch = SemanticScholar(api_key=keys['s2_api_key'])"
   ]
  },
  {
   "cell_type": "code",
   "execution_count": 9,
   "metadata": {
    "scrolled": true
   },
   "outputs": [
    {
     "name": "stdout",
     "output_type": "stream",
     "text": [
      "{'project_id': 'w210-capstone-ta', 'instance': {'name': 'w210-therapeutic-accelerator', 'region': 'us-central1'}, 'database': {'user': 'postgres', 'password': 'Q]-/difiAH57&pt.', 'name': 'articles'}, 'semantic_scholar': {'latest': 'http://api.semanticscholar.org/datasets/v1/release/latest', 'release': 'http://api.semanticscholar.org/datasets/v1/release', 'papers': 'http://api.semanticscholar.org/datasets/v1/release/latest/dataset/papers'}, 'paths': {'root': '/home/nick_lee_berkeley_edu/', 'mount': 'mount-folder'}}\n"
     ]
    }
   ],
   "source": [
    "with open(\"../config/main.yaml\", \"r\") as f:\n",
    "    config = yaml.load(f, Loader=yaml.FullLoader)\n",
    "\n",
    "print(config)\n",
    "\n",
    "with open(\"../config/keys.yaml\", \"r\") as f:\n",
    "    keys = yaml.load(f, Loader=yaml.FullLoader)\n",
    "\n",
    "root_path = \"/home/nick_lee_berkeley_edu/\"\n",
    "mount_path = os.path.join(root_path, \"mount-folder\")"
   ]
  },
  {
   "cell_type": "markdown",
   "metadata": {},
   "source": [
    "# Functions"
   ]
  },
  {
   "cell_type": "code",
   "execution_count": 42,
   "metadata": {},
   "outputs": [],
   "source": [
    "# download paper\n",
    "def get_paper(url, file_path): \n",
    "    \"\"\" url to the file and the file_name to download it as \"\"\"\n",
    "    if os.path.isfile(file_path) == False:\n",
    "            try: \n",
    "                urllib.request.urlretrieve(url, file_path)\n",
    "                urllib.request.urlcleanup()\n",
    "            except: \n",
    "                print(f\"Error for {file_path}\")\n",
    "        else: \n",
    "            print(f\"{i}, File Exists\")\n",
    "    \n",
    "\n",
    "def unzip_file(zip_file_path, ext_file_path): \n",
    "    \"\"\" make sure the current working directory is set to where you want the files \"\"\"\n",
    "    if os.path.isfile(ext_file_path) == False:\n",
    "        try: \n",
    "            with gzip.open(zip_file_path, 'rb') as f_in:\n",
    "                with open(ext_file_path, 'wb') as f_out:\n",
    "                    shutil.copyfileobj(f_in, f_out)\n",
    "        except: \n",
    "            print(f\"Was not able to extract file {ext_file_path}\")\n",
    "    else:\n",
    "        print(f\"{i}, File Exists\")"
   ]
  },
  {
   "cell_type": "code",
   "execution_count": null,
   "metadata": {},
   "outputs": [],
   "source": [
    "# Multithreading\n",
    "def download(link, filelocation):\n",
    "    r = requests.get(link, stream=True)\n",
    "    with open(filelocation, 'wb') as f:\n",
    "        for chunk in r.iter_content(1024):\n",
    "            if chunk:\n",
    "                f.write(chunk)\n",
    "\n",
    "def createNewDownloadThread(link, filelocation):\n",
    "    download_thread = threading.Thread(target=download, args=(link,filelocation))\n",
    "    download_thread.start()\n",
    "\n",
    "# for i in range(0,5):\n",
    "#     file = \"C:\\\\test\" + str(i) + \".png\"\n",
    "#     print file\n",
    "#     createNewDownloadThread(\"http://stackoverflow.com/users/flair/2374517.png\", file)"
   ]
  },
  {
   "cell_type": "markdown",
   "metadata": {},
   "source": [
    "# Get Papers and latests releases"
   ]
  },
  {
   "cell_type": "code",
   "execution_count": 4,
   "metadata": {},
   "outputs": [],
   "source": [
    "# Get info about the papers dataset\n",
    "papers = requests.get(config['semantic_scholar']['papers'],\n",
    "                      headers={'x-api-key':keys['x-api-key']}).json()"
   ]
  },
  {
   "cell_type": "code",
   "execution_count": 1,
   "metadata": {},
   "outputs": [],
   "source": [
    "# Get info about the latest release\n",
    "latest_release = requests.get(config['semantic_scholar']['latest']).json()\n",
    "\n",
    "# Get info about past releases\n",
    "dataset_ids = requests.get(config['semantic_scholar']['release']).json()\n",
    "earliest_release = requests.get(f\"http://api.semanticscholar.org/datasets/v1/release/{dataset_ids[0]}\").json()"
   ]
  },
  {
   "cell_type": "markdown",
   "metadata": {},
   "source": [
    "# Download Files\n",
    "Create the file paths for the zipped and extracted"
   ]
  },
  {
   "cell_type": "code",
   "execution_count": 32,
   "metadata": {},
   "outputs": [],
   "source": [
    "download_flag = True\n",
    "extract_flag = False"
   ]
  },
  {
   "cell_type": "code",
   "execution_count": 28,
   "metadata": {},
   "outputs": [],
   "source": [
    "# create base file names\n",
    "file_names = [f\"papers-part{n}.jsonl.gz\" for n in range(len(papers['files']))]\n",
    "\n",
    "# create zipped file paths\n",
    "paper_zip = [os.path.join(mount_path, \"zipped\", f) for f in file_names]\n",
    "\n",
    "# create extracted file paths\n",
    "paper_fn = [os.path.join(mount_path, \"extracted\", f.strip(\"\\.gz\")) for f in file_names]"
   ]
  },
  {
   "cell_type": "code",
   "execution_count": 36,
   "metadata": {
    "scrolled": true
   },
   "outputs": [
    {
     "name": "stderr",
     "output_type": "stream",
     "text": [
      "0it [00:00, ?it/s]"
     ]
    },
    {
     "name": "stdout",
     "output_type": "stream",
     "text": [
      "0, File Exists\n",
      "1, File Exists\n",
      "2, File Exists\n",
      "3, File Exists\n",
      "4, File Exists\n",
      "5, File Exists\n",
      "6, File Exists\n",
      "7, File Exists\n",
      "8, File Exists\n",
      "9, File Exists\n",
      "10, File Exists\n",
      "11, File Exists\n",
      "12, File Exists\n",
      "13, File Exists\n",
      "14, File Exists\n",
      "15, File Exists\n",
      "16, File Exists\n",
      "17, File Exists\n",
      "18, File Exists\n",
      "19, File Exists\n",
      "20, File Exists\n",
      "21, File Exists\n",
      "22, File Exists\n",
      "23, File Exists\n",
      "24, File Exists\n",
      "25, File Exists\n",
      "26, File Exists\n"
     ]
    },
    {
     "name": "stderr",
     "output_type": "stream",
     "text": [
      "28it [00:00, 93.47it/s]"
     ]
    },
    {
     "name": "stdout",
     "output_type": "stream",
     "text": [
      "Error for /home/nick_lee_berkeley_edu/mount-folder/zipped/papers-part27.jsonl.gz\n",
      "Error for /home/nick_lee_berkeley_edu/mount-folder/zipped/papers-part28.jsonl.gz\n"
     ]
    },
    {
     "name": "stderr",
     "output_type": "stream",
     "text": [
      "30it [00:00, 32.07it/s]"
     ]
    },
    {
     "name": "stdout",
     "output_type": "stream",
     "text": [
      "Error for /home/nick_lee_berkeley_edu/mount-folder/zipped/papers-part29.jsonl.gz\n"
     ]
    },
    {
     "name": "stderr",
     "output_type": "stream",
     "text": [
      "\n"
     ]
    }
   ],
   "source": [
    "# Takes ~30 minutes\n",
    "if download_flag == True: \n",
    "    with multiprocessing.Pool() as pool:\n",
    "        pool.starmap(unzip_file, zip(papers['files'], paper_zip), chunksize=10)\n",
    "    # downloads the files directly into the google cloud bucket\n",
    "    for i, (url, file_path) in tqdm(enumerate(zip(papers['files'], paper_zip))): \n",
    "        if os.path.isfile(file_path) == False:\n",
    "            try: \n",
    "                get_paper(url, file_path)\n",
    "            except: \n",
    "                print(f\"Error for {file_path}\")\n",
    "        else: \n",
    "            print(f\"{i}, File Exists\")"
   ]
  },
  {
   "cell_type": "code",
   "execution_count": null,
   "metadata": {
    "scrolled": true
   },
   "outputs": [],
   "source": [
    "## Multiprocessing to extract multiple files at once\n",
    "# Takes ~FOREVER minutes\n",
    "with multiprocessing.Pool() as pool:\n",
    "    pool.starmap(unzip_file, zip(paper_zip, paper_fn), chunksize=3)"
   ]
  },
  {
   "cell_type": "code",
   "execution_count": null,
   "metadata": {},
   "outputs": [],
   "source": [
    "# Takes ~ FOREVER mins\n",
    "if extract_flag == True: \n",
    "    for tqdm(file_path) in paper_zip:\n",
    "        if os.path.isfile(file_path) == False:\n",
    "            unzip_file(file_path)\n",
    "        else: \n",
    "            print(f\"{i}, File Exists\")"
   ]
  },
  {
   "cell_type": "markdown",
   "metadata": {},
   "source": [
    "## Parse JSON file to upload into database"
   ]
  },
  {
   "cell_type": "code",
   "execution_count": 8,
   "metadata": {},
   "outputs": [],
   "source": [
    "# takes a long time to load\n",
    "with open('papers-part0.jsonl', 'r') as json_file:\n",
    "    json_list = list(json_file)"
   ]
  },
  {
   "cell_type": "code",
   "execution_count": 10,
   "metadata": {},
   "outputs": [
    {
     "data": {
      "text/plain": [
       "dict_keys(['corpusid', 'externalids', 'url', 'title', 'authors', 'venue', 'publicationvenueid', 'year', 'referencecount', 'citationcount', 'influentialcitationcount', 'isopenaccess', 's2fieldsofstudy', 'publicationtypes', 'publicationdate', 'journal', 'updated'])"
      ]
     },
     "execution_count": 10,
     "metadata": {},
     "output_type": "execute_result"
    }
   ],
   "source": [
    "# turn into json object\n",
    "test = json.loads(json_list[0])\n",
    "test2 = json.loads(json_list[1])\n",
    "\n",
    "test.keys()"
   ]
  },
  {
   "cell_type": "code",
   "execution_count": 11,
   "metadata": {
    "scrolled": true
   },
   "outputs": [
    {
     "data": {
      "text/html": [
       "<div>\n",
       "<style scoped>\n",
       "    .dataframe tbody tr th:only-of-type {\n",
       "        vertical-align: middle;\n",
       "    }\n",
       "\n",
       "    .dataframe tbody tr th {\n",
       "        vertical-align: top;\n",
       "    }\n",
       "\n",
       "    .dataframe thead th {\n",
       "        text-align: right;\n",
       "    }\n",
       "</style>\n",
       "<table border=\"1\" class=\"dataframe\">\n",
       "  <thead>\n",
       "    <tr style=\"text-align: right;\">\n",
       "      <th></th>\n",
       "      <th>corpusid</th>\n",
       "      <th>externalids</th>\n",
       "      <th>url</th>\n",
       "      <th>title</th>\n",
       "      <th>authors</th>\n",
       "      <th>venue</th>\n",
       "      <th>publicationvenueid</th>\n",
       "      <th>year</th>\n",
       "      <th>referencecount</th>\n",
       "      <th>citationcount</th>\n",
       "      <th>influentialcitationcount</th>\n",
       "      <th>isopenaccess</th>\n",
       "      <th>s2fieldsofstudy</th>\n",
       "      <th>publicationtypes</th>\n",
       "      <th>publicationdate</th>\n",
       "      <th>journal</th>\n",
       "      <th>updated</th>\n",
       "    </tr>\n",
       "  </thead>\n",
       "  <tbody>\n",
       "    <tr>\n",
       "      <th>0</th>\n",
       "      <td>158371356</td>\n",
       "      <td>{'ACL': None, 'DBLP': None, 'ArXiv': None, 'MA...</td>\n",
       "      <td>https://www.semanticscholar.org/paper/8100364c...</td>\n",
       "      <td>Education and the Non-financial Employment Com...</td>\n",
       "      <td>[{'authorId': '121045716', 'name': 'Simona Dem...</td>\n",
       "      <td></td>\n",
       "      <td>None</td>\n",
       "      <td>2018</td>\n",
       "      <td>21</td>\n",
       "      <td>2</td>\n",
       "      <td>0</td>\n",
       "      <td>False</td>\n",
       "      <td>[{'category': 'Economics', 'source': 's2-fos-m...</td>\n",
       "      <td>None</td>\n",
       "      <td>2018-11-01</td>\n",
       "      <td>{'name': 'Social Indicators Research', 'pages'...</td>\n",
       "      <td>2022-12-24T20:13:29.662Z</td>\n",
       "    </tr>\n",
       "  </tbody>\n",
       "</table>\n",
       "</div>"
      ],
      "text/plain": [
       "    corpusid                                        externalids  \\\n",
       "0  158371356  {'ACL': None, 'DBLP': None, 'ArXiv': None, 'MA...   \n",
       "\n",
       "                                                 url  \\\n",
       "0  https://www.semanticscholar.org/paper/8100364c...   \n",
       "\n",
       "                                               title  \\\n",
       "0  Education and the Non-financial Employment Com...   \n",
       "\n",
       "                                             authors venue publicationvenueid  \\\n",
       "0  [{'authorId': '121045716', 'name': 'Simona Dem...                     None   \n",
       "\n",
       "   year  referencecount  citationcount  influentialcitationcount  \\\n",
       "0  2018              21              2                         0   \n",
       "\n",
       "   isopenaccess                                    s2fieldsofstudy  \\\n",
       "0         False  [{'category': 'Economics', 'source': 's2-fos-m...   \n",
       "\n",
       "  publicationtypes publicationdate  \\\n",
       "0             None      2018-11-01   \n",
       "\n",
       "                                             journal                   updated  \n",
       "0  {'name': 'Social Indicators Research', 'pages'...  2022-12-24T20:13:29.662Z  "
      ]
     },
     "execution_count": 11,
     "metadata": {},
     "output_type": "execute_result"
    }
   ],
   "source": [
    "pd.DataFrame([test2])"
   ]
  },
  {
   "cell_type": "markdown",
   "metadata": {},
   "source": [
    "## Upload Data to Postgres DB"
   ]
  },
  {
   "cell_type": "code",
   "execution_count": 10,
   "metadata": {},
   "outputs": [],
   "source": [
    "# connection libraries\n",
    "from google.cloud.sql.connector import Connector\n",
    "import sqlalchemy\n",
    "import pg8000"
   ]
  },
  {
   "cell_type": "code",
   "execution_count": null,
   "metadata": {
    "scrolled": true
   },
   "outputs": [],
   "source": [
    "INSTANCE_CONNECTION_NAME = f\"{config['project_id']}:{config['instance']['region']}:{config['instance']['name']}\" # i.e demo-project:us-central1:demo-instance\n",
    "INSTANCE_CONNECTION_NAME"
   ]
  },
  {
   "cell_type": "code",
   "execution_count": 47,
   "metadata": {},
   "outputs": [],
   "source": [
    "# Add files to database\n",
    "# initialize Connector object\n",
    "connector = Connector()\n",
    "\n",
    "# function to return the database connection object\n",
    "# @hydra.main(config_path=\"../conf\", config_name=\"main\", version_base=None)\n",
    "def getconn():\n",
    "    INSTANCE_CONNECTION_NAME = f\"{config['project_id']}:{config['instance']['region']}:{config['instance']['name']}\" # i.e demo-project:us-central1:demo-instance\n",
    "    DB_USER = config['database']['user']\n",
    "    DB_PASS = config['database']['password']\n",
    "    DB_NAME = config['database']['name']\n",
    "    \n",
    "    conn = connector.connect(\n",
    "        INSTANCE_CONNECTION_NAME,\n",
    "        \"pg8000\",\n",
    "        user=DB_USER,\n",
    "        password=DB_PASS,\n",
    "        db=DB_NAME\n",
    "    )\n",
    "    return conn"
   ]
  },
  {
   "cell_type": "code",
   "execution_count": 52,
   "metadata": {
    "scrolled": true
   },
   "outputs": [
    {
     "ename": "ClientResponseError",
     "evalue": "404, message='Not Found', url=URL('https://sqladmin.googleapis.com/sql/v1beta4/projects/w210-capstone-ta/instances/w210-therapeutic-accelerator/connectSettings')",
     "output_type": "error",
     "traceback": [
      "\u001b[0;31m---------------------------------------------------------------------------\u001b[0m",
      "\u001b[0;31mClientResponseError\u001b[0m                       Traceback (most recent call last)",
      "Cell \u001b[0;32mIn[52], line 4\u001b[0m\n\u001b[1;32m      1\u001b[0m \u001b[38;5;66;03m# create connection pool with 'creator' argument to our connection object function\u001b[39;00m\n\u001b[1;32m      2\u001b[0m pool \u001b[38;5;241m=\u001b[39m sqlalchemy\u001b[38;5;241m.\u001b[39mcreate_engine(\n\u001b[1;32m      3\u001b[0m     \u001b[38;5;124m\"\u001b[39m\u001b[38;5;124mpostgresql+pg8000://\u001b[39m\u001b[38;5;124m\"\u001b[39m,\n\u001b[0;32m----> 4\u001b[0m     creator\u001b[38;5;241m=\u001b[39m\u001b[43mgetconn\u001b[49m\u001b[43m(\u001b[49m\u001b[43m)\u001b[49m,\n\u001b[1;32m      5\u001b[0m )\n",
      "Cell \u001b[0;32mIn[47], line 13\u001b[0m, in \u001b[0;36mgetconn\u001b[0;34m()\u001b[0m\n\u001b[1;32m     10\u001b[0m DB_PASS \u001b[38;5;241m=\u001b[39m config[\u001b[38;5;124m'\u001b[39m\u001b[38;5;124mdatabase\u001b[39m\u001b[38;5;124m'\u001b[39m][\u001b[38;5;124m'\u001b[39m\u001b[38;5;124mpassword\u001b[39m\u001b[38;5;124m'\u001b[39m]\n\u001b[1;32m     11\u001b[0m DB_NAME \u001b[38;5;241m=\u001b[39m config[\u001b[38;5;124m'\u001b[39m\u001b[38;5;124mdatabase\u001b[39m\u001b[38;5;124m'\u001b[39m][\u001b[38;5;124m'\u001b[39m\u001b[38;5;124mname\u001b[39m\u001b[38;5;124m'\u001b[39m]\n\u001b[0;32m---> 13\u001b[0m conn \u001b[38;5;241m=\u001b[39m \u001b[43mconnector\u001b[49m\u001b[38;5;241;43m.\u001b[39;49m\u001b[43mconnect\u001b[49m\u001b[43m(\u001b[49m\n\u001b[1;32m     14\u001b[0m \u001b[43m    \u001b[49m\u001b[43mINSTANCE_CONNECTION_NAME\u001b[49m\u001b[43m,\u001b[49m\n\u001b[1;32m     15\u001b[0m \u001b[43m    \u001b[49m\u001b[38;5;124;43m\"\u001b[39;49m\u001b[38;5;124;43mpg8000\u001b[39;49m\u001b[38;5;124;43m\"\u001b[39;49m\u001b[43m,\u001b[49m\n\u001b[1;32m     16\u001b[0m \u001b[43m    \u001b[49m\u001b[43muser\u001b[49m\u001b[38;5;241;43m=\u001b[39;49m\u001b[43mDB_USER\u001b[49m\u001b[43m,\u001b[49m\n\u001b[1;32m     17\u001b[0m \u001b[43m    \u001b[49m\u001b[43mpassword\u001b[49m\u001b[38;5;241;43m=\u001b[39;49m\u001b[43mDB_PASS\u001b[49m\u001b[43m,\u001b[49m\n\u001b[1;32m     18\u001b[0m \u001b[43m    \u001b[49m\u001b[43mdb\u001b[49m\u001b[38;5;241;43m=\u001b[39;49m\u001b[43mDB_NAME\u001b[49m\n\u001b[1;32m     19\u001b[0m \u001b[43m\u001b[49m\u001b[43m)\u001b[49m\n\u001b[1;32m     20\u001b[0m \u001b[38;5;28;01mreturn\u001b[39;00m conn\n",
      "File \u001b[0;32m~/anaconda3/lib/python3.10/site-packages/google/cloud/sql/connector/connector.py:154\u001b[0m, in \u001b[0;36mConnector.connect\u001b[0;34m(self, instance_connection_string, driver, **kwargs)\u001b[0m\n\u001b[1;32m    150\u001b[0m \u001b[38;5;66;03m# if event loop is not in current thread, proceed with connection\u001b[39;00m\n\u001b[1;32m    151\u001b[0m connect_task \u001b[38;5;241m=\u001b[39m asyncio\u001b[38;5;241m.\u001b[39mrun_coroutine_threadsafe(\n\u001b[1;32m    152\u001b[0m     \u001b[38;5;28mself\u001b[39m\u001b[38;5;241m.\u001b[39mconnect_async(instance_connection_string, driver, \u001b[38;5;241m*\u001b[39m\u001b[38;5;241m*\u001b[39mkwargs), \u001b[38;5;28mself\u001b[39m\u001b[38;5;241m.\u001b[39m_loop\n\u001b[1;32m    153\u001b[0m )\n\u001b[0;32m--> 154\u001b[0m \u001b[38;5;28;01mreturn\u001b[39;00m \u001b[43mconnect_task\u001b[49m\u001b[38;5;241;43m.\u001b[39;49m\u001b[43mresult\u001b[49m\u001b[43m(\u001b[49m\u001b[43m)\u001b[49m\n",
      "File \u001b[0;32m~/anaconda3/lib/python3.10/concurrent/futures/_base.py:458\u001b[0m, in \u001b[0;36mFuture.result\u001b[0;34m(self, timeout)\u001b[0m\n\u001b[1;32m    456\u001b[0m     \u001b[38;5;28;01mraise\u001b[39;00m CancelledError()\n\u001b[1;32m    457\u001b[0m \u001b[38;5;28;01melif\u001b[39;00m \u001b[38;5;28mself\u001b[39m\u001b[38;5;241m.\u001b[39m_state \u001b[38;5;241m==\u001b[39m FINISHED:\n\u001b[0;32m--> 458\u001b[0m     \u001b[38;5;28;01mreturn\u001b[39;00m \u001b[38;5;28;43mself\u001b[39;49m\u001b[38;5;241;43m.\u001b[39;49m\u001b[43m__get_result\u001b[49m\u001b[43m(\u001b[49m\u001b[43m)\u001b[49m\n\u001b[1;32m    459\u001b[0m \u001b[38;5;28;01melse\u001b[39;00m:\n\u001b[1;32m    460\u001b[0m     \u001b[38;5;28;01mraise\u001b[39;00m \u001b[38;5;167;01mTimeoutError\u001b[39;00m()\n",
      "File \u001b[0;32m~/anaconda3/lib/python3.10/concurrent/futures/_base.py:403\u001b[0m, in \u001b[0;36mFuture.__get_result\u001b[0;34m(self)\u001b[0m\n\u001b[1;32m    401\u001b[0m \u001b[38;5;28;01mif\u001b[39;00m \u001b[38;5;28mself\u001b[39m\u001b[38;5;241m.\u001b[39m_exception:\n\u001b[1;32m    402\u001b[0m     \u001b[38;5;28;01mtry\u001b[39;00m:\n\u001b[0;32m--> 403\u001b[0m         \u001b[38;5;28;01mraise\u001b[39;00m \u001b[38;5;28mself\u001b[39m\u001b[38;5;241m.\u001b[39m_exception\n\u001b[1;32m    404\u001b[0m     \u001b[38;5;28;01mfinally\u001b[39;00m:\n\u001b[1;32m    405\u001b[0m         \u001b[38;5;66;03m# Break a reference cycle with the exception in self._exception\u001b[39;00m\n\u001b[1;32m    406\u001b[0m         \u001b[38;5;28mself\u001b[39m \u001b[38;5;241m=\u001b[39m \u001b[38;5;28;01mNone\u001b[39;00m\n",
      "File \u001b[0;32m~/anaconda3/lib/python3.10/site-packages/google/cloud/sql/connector/connector.py:261\u001b[0m, in \u001b[0;36mConnector.connect_async\u001b[0;34m(self, instance_connection_string, driver, **kwargs)\u001b[0m\n\u001b[1;32m    259\u001b[0m \u001b[38;5;66;03m# attempt to make connection to Cloud SQL instance for given timeout\u001b[39;00m\n\u001b[1;32m    260\u001b[0m \u001b[38;5;28;01mtry\u001b[39;00m:\n\u001b[0;32m--> 261\u001b[0m     \u001b[38;5;28;01mreturn\u001b[39;00m \u001b[38;5;28;01mawait\u001b[39;00m asyncio\u001b[38;5;241m.\u001b[39mwait_for(get_connection(), timeout)\n\u001b[1;32m    262\u001b[0m \u001b[38;5;28;01mexcept\u001b[39;00m asyncio\u001b[38;5;241m.\u001b[39mTimeoutError:\n\u001b[1;32m    263\u001b[0m     \u001b[38;5;28;01mraise\u001b[39;00m \u001b[38;5;167;01mTimeoutError\u001b[39;00m(\u001b[38;5;124mf\u001b[39m\u001b[38;5;124m\"\u001b[39m\u001b[38;5;124mConnection timed out after \u001b[39m\u001b[38;5;132;01m{\u001b[39;00mtimeout\u001b[38;5;132;01m}\u001b[39;00m\u001b[38;5;124ms\u001b[39m\u001b[38;5;124m\"\u001b[39m)\n",
      "File \u001b[0;32m~/anaconda3/lib/python3.10/asyncio/tasks.py:445\u001b[0m, in \u001b[0;36mwait_for\u001b[0;34m(fut, timeout)\u001b[0m\n\u001b[1;32m    442\u001b[0m         \u001b[38;5;28;01mraise\u001b[39;00m\n\u001b[1;32m    444\u001b[0m \u001b[38;5;28;01mif\u001b[39;00m fut\u001b[38;5;241m.\u001b[39mdone():\n\u001b[0;32m--> 445\u001b[0m     \u001b[38;5;28;01mreturn\u001b[39;00m \u001b[43mfut\u001b[49m\u001b[38;5;241;43m.\u001b[39;49m\u001b[43mresult\u001b[49m\u001b[43m(\u001b[49m\u001b[43m)\u001b[49m\n\u001b[1;32m    446\u001b[0m \u001b[38;5;28;01melse\u001b[39;00m:\n\u001b[1;32m    447\u001b[0m     fut\u001b[38;5;241m.\u001b[39mremove_done_callback(cb)\n",
      "File \u001b[0;32m~/anaconda3/lib/python3.10/site-packages/google/cloud/sql/connector/connector.py:237\u001b[0m, in \u001b[0;36mConnector.connect_async.<locals>.get_connection\u001b[0;34m()\u001b[0m\n\u001b[1;32m    236\u001b[0m \u001b[38;5;28;01masync\u001b[39;00m \u001b[38;5;28;01mdef\u001b[39;00m \u001b[38;5;21mget_connection\u001b[39m() \u001b[38;5;241m-\u001b[39m\u001b[38;5;241m>\u001b[39m Any:\n\u001b[0;32m--> 237\u001b[0m     instance_data, ip_address \u001b[38;5;241m=\u001b[39m \u001b[38;5;28;01mawait\u001b[39;00m instance\u001b[38;5;241m.\u001b[39mconnect_info(ip_type)\n\u001b[1;32m    239\u001b[0m     \u001b[38;5;66;03m# format `user` param for automatic IAM database authn\u001b[39;00m\n\u001b[1;32m    240\u001b[0m     \u001b[38;5;28;01mif\u001b[39;00m enable_iam_auth:\n",
      "File \u001b[0;32m~/anaconda3/lib/python3.10/site-packages/google/cloud/sql/connector/instance.py:445\u001b[0m, in \u001b[0;36mInstance.connect_info\u001b[0;34m(self, ip_type)\u001b[0m\n\u001b[1;32m    439\u001b[0m logger\u001b[38;5;241m.\u001b[39mdebug(\n\u001b[1;32m    440\u001b[0m     \u001b[38;5;124mf\u001b[39m\u001b[38;5;124m\"\u001b[39m\u001b[38;5;124m[\u001b[39m\u001b[38;5;124m'\u001b[39m\u001b[38;5;132;01m{\u001b[39;00m\u001b[38;5;28mself\u001b[39m\u001b[38;5;241m.\u001b[39m_instance_connection_string\u001b[38;5;132;01m}\u001b[39;00m\u001b[38;5;124m'\u001b[39m\u001b[38;5;124m]: Entered connect_info method\u001b[39m\u001b[38;5;124m\"\u001b[39m\n\u001b[1;32m    441\u001b[0m )\n\u001b[1;32m    443\u001b[0m instance_data: InstanceMetadata\n\u001b[0;32m--> 445\u001b[0m instance_data \u001b[38;5;241m=\u001b[39m \u001b[38;5;28;01mawait\u001b[39;00m \u001b[38;5;28mself\u001b[39m\u001b[38;5;241m.\u001b[39m_current\n\u001b[1;32m    446\u001b[0m ip_address: \u001b[38;5;28mstr\u001b[39m \u001b[38;5;241m=\u001b[39m instance_data\u001b[38;5;241m.\u001b[39mget_preferred_ip(ip_type)\n\u001b[1;32m    447\u001b[0m \u001b[38;5;28;01mreturn\u001b[39;00m instance_data, ip_address\n",
      "\u001b[0;31mClientResponseError\u001b[0m: 404, message='Not Found', url=URL('https://sqladmin.googleapis.com/sql/v1beta4/projects/w210-capstone-ta/instances/w210-therapeutic-accelerator/connectSettings')"
     ]
    },
    {
     "name": "stderr",
     "output_type": "stream",
     "text": [
      "['w210-capstone-ta:us-central1:w210-therapeutic-accelerator']: An error occurred while performing refresh. Scheduling another refresh attempt immediately\n",
      "Traceback (most recent call last):\n",
      "  File \"/home/nick_lee_berkeley_edu/anaconda3/lib/python3.10/site-packages/google/cloud/sql/connector/instance.py\", line 388, in _refresh_task\n",
      "    refresh_data = await refresh_task\n",
      "  File \"/home/nick_lee_berkeley_edu/anaconda3/lib/python3.10/site-packages/google/cloud/sql/connector/instance.py\", line 312, in _perform_refresh\n",
      "    metadata = await metadata_task\n",
      "  File \"/home/nick_lee_berkeley_edu/anaconda3/lib/python3.10/site-packages/google/cloud/sql/connector/refresh_utils.py\", line 101, in _get_metadata\n",
      "    resp = await client_session.get(url, headers=headers, raise_for_status=True)\n",
      "  File \"/home/nick_lee_berkeley_edu/anaconda3/lib/python3.10/site-packages/aiohttp/client.py\", line 640, in _request\n",
      "    resp.raise_for_status()\n",
      "  File \"/home/nick_lee_berkeley_edu/anaconda3/lib/python3.10/site-packages/aiohttp/client_reqrep.py\", line 1004, in raise_for_status\n",
      "    raise ClientResponseError(\n",
      "aiohttp.client_exceptions.ClientResponseError: 404, message='Not Found', url=URL('https://sqladmin.googleapis.com/sql/v1beta4/projects/w210-capstone-ta/instances/w210-therapeutic-accelerator/connectSettings')\n",
      "Task exception was never retrieved\n",
      "future: <Task finished name='Task-57' coro=<Instance._schedule_refresh.<locals>._refresh_task() done, defined at /home/nick_lee_berkeley_edu/anaconda3/lib/python3.10/site-packages/google/cloud/sql/connector/instance.py:377> exception=ClientResponseError(RequestInfo(url=URL('https://sqladmin.googleapis.com/sql/v1beta4/projects/w210-capstone-ta/instances/w210-therapeutic-accelerator/connectSettings'), method='GET', headers=<CIMultiDictProxy('Host': 'sqladmin.googleapis.com', 'x-goog-api-client': 'cloud-sql-python-connector/1.2.3+pg8000', 'User-Agent': 'cloud-sql-python-connector/1.2.3+pg8000', 'Content-Type': 'application/json', 'Authorization': 'Bearer ya29.c.b0Aaekm1IY-VGbVQF2xAnFKLraacz4aWWINrWwumL0oEKATtsm27z8JAkL6smOHDDuVMEZcnyunbg_ECSPwUBg_x8Q_idoiNN1VENVTxHGMVrB-BHG9Bml0sqQl3Xq9xEnwVY9Jr4dtL8qOn9Aw-aUFXqI2LWxu-91iNrBEfRfF55dwCi6cBzZ6pigHoQuQptIU-ifSHd9P1H7O2o7k856XmTaioHiOJ6MWPf5a_wzdzq8UHfuGnp9a4P1Wcm-_4E-tRLWVDL5gSoeE1aqUAA96xZFUH2AdTTk49W8RnJqO5WhGwk72sfLLE6D5tCFxuxMAf8p2N6G7_rC-CYS1djxCSs7diTa89LF3e8hnLgH368PpbaY7Mzm08eQ-Xgef35d1QOrmcu_zrpxSBeBax3Sy_oc0slsobSlgJ91etzv4qbFJnF5p3oj6RQV9her5dmez1Ohgo2oY6IY4yIxgc01v_l0ls3tx3IFlXu-e_hhkFQcpR4ZyB_qWXVo45Q58sIhwshbnJuRqVBxyRRentplIfiu4YS_t_9y3Mcbdt_Vu-Fs_3UeaBp8fXhieO2uwclM0VYY2vwq7ZSqYXUZBnkd7FOq9x1YZzYtqbr9oORnrQ9ZZ2gOWWnJqkqtJnZ0ghXspRm3rYaWB6lfpeWgl9hhw1oJsu2kiYcIodjy4b22hvtZ7r9UnBq3ez-c9_SlYxrQpqSZs_yiIXqclzuqt6Byy9i73_z0nMruJJ1IBqlOS2ZbqkMVcb_4ean8tgntbkQ0VasxBQpxgSVgMOivokRIhBB9Q5F_ysiF71jRFQzXfcj9lXgOm_Q_V8iwjaVfFb4bqg7qJdSiOV2Wls8gXdOSSnBjOI2tufkex63wFQ4nU38I6FIt0Fgo5qsuOUgFyX4W68B9Zn_Xqeko5d711VBxyeVza0_mwx__dcfSk20jbIfzxRZOl5xzi2Iy1Vpm-9W9rJ2OsqZt2WWJf54Iuviiwr8e_9iBvJzYIcFcq_05ykruqxu0ri6rWOJ', 'Accept': '*/*', 'Accept-Encoding': 'gzip, deflate')>, real_url=URL('https://sqladmin.googleapis.com/sql/v1beta4/projects/w210-capstone-ta/instances/w210-therapeutic-accelerator/connectSettings')), (), status=404, message='Not Found', headers=<CIMultiDictProxy('Vary': 'Origin', 'Vary': 'X-Origin', 'Vary': 'Referer', 'Content-Type': 'application/json; charset=UTF-8', 'Content-Encoding': 'gzip', 'Date': 'Thu, 08 Jun 2023 00:24:42 GMT', 'Server': 'ESF', 'Cache-Control': 'private', 'X-XSS-Protection': '0', 'X-Frame-Options': 'SAMEORIGIN', 'X-Content-Type-Options': 'nosniff', 'Transfer-Encoding': 'chunked')>)>\n",
      "Traceback (most recent call last):\n",
      "  File \"/home/nick_lee_berkeley_edu/anaconda3/lib/python3.10/site-packages/google/cloud/sql/connector/instance.py\", line 388, in _refresh_task\n",
      "    refresh_data = await refresh_task\n",
      "  File \"/home/nick_lee_berkeley_edu/anaconda3/lib/python3.10/site-packages/google/cloud/sql/connector/instance.py\", line 312, in _perform_refresh\n",
      "    metadata = await metadata_task\n",
      "  File \"/home/nick_lee_berkeley_edu/anaconda3/lib/python3.10/site-packages/google/cloud/sql/connector/refresh_utils.py\", line 101, in _get_metadata\n",
      "    resp = await client_session.get(url, headers=headers, raise_for_status=True)\n",
      "  File \"/home/nick_lee_berkeley_edu/anaconda3/lib/python3.10/site-packages/aiohttp/client.py\", line 640, in _request\n",
      "    resp.raise_for_status()\n",
      "  File \"/home/nick_lee_berkeley_edu/anaconda3/lib/python3.10/site-packages/aiohttp/client_reqrep.py\", line 1004, in raise_for_status\n",
      "    raise ClientResponseError(\n",
      "aiohttp.client_exceptions.ClientResponseError: 404, message='Not Found', url=URL('https://sqladmin.googleapis.com/sql/v1beta4/projects/w210-capstone-ta/instances/w210-therapeutic-accelerator/connectSettings')\n",
      "['w210-capstone-ta:us-central1:w210-therapeutic-accelerator']: An error occurred while performing refresh. Scheduling another refresh attempt immediately\n",
      "Traceback (most recent call last):\n",
      "  File \"/home/nick_lee_berkeley_edu/anaconda3/lib/python3.10/site-packages/google/cloud/sql/connector/instance.py\", line 388, in _refresh_task\n",
      "    refresh_data = await refresh_task\n",
      "  File \"/home/nick_lee_berkeley_edu/anaconda3/lib/python3.10/site-packages/google/cloud/sql/connector/instance.py\", line 312, in _perform_refresh\n",
      "    metadata = await metadata_task\n",
      "  File \"/home/nick_lee_berkeley_edu/anaconda3/lib/python3.10/site-packages/google/cloud/sql/connector/refresh_utils.py\", line 101, in _get_metadata\n",
      "    resp = await client_session.get(url, headers=headers, raise_for_status=True)\n",
      "  File \"/home/nick_lee_berkeley_edu/anaconda3/lib/python3.10/site-packages/aiohttp/client.py\", line 640, in _request\n",
      "    resp.raise_for_status()\n",
      "  File \"/home/nick_lee_berkeley_edu/anaconda3/lib/python3.10/site-packages/aiohttp/client_reqrep.py\", line 1004, in raise_for_status\n",
      "    raise ClientResponseError(\n",
      "aiohttp.client_exceptions.ClientResponseError: 404, message='Not Found', url=URL('https://sqladmin.googleapis.com/sql/v1beta4/projects/w210-capstone-ta/instances/w210-therapeutic-accelerator/connectSettings')\n",
      "Task exception was never retrieved\n",
      "future: <Task finished name='Task-68' coro=<Instance._schedule_refresh.<locals>._refresh_task() done, defined at /home/nick_lee_berkeley_edu/anaconda3/lib/python3.10/site-packages/google/cloud/sql/connector/instance.py:377> exception=ClientResponseError(RequestInfo(url=URL('https://sqladmin.googleapis.com/sql/v1beta4/projects/w210-capstone-ta/instances/w210-therapeutic-accelerator/connectSettings'), method='GET', headers=<CIMultiDictProxy('Host': 'sqladmin.googleapis.com', 'x-goog-api-client': 'cloud-sql-python-connector/1.2.3+pg8000', 'User-Agent': 'cloud-sql-python-connector/1.2.3+pg8000', 'Content-Type': 'application/json', 'Authorization': 'Bearer ya29.c.b0Aaekm1IY-VGbVQF2xAnFKLraacz4aWWINrWwumL0oEKATtsm27z8JAkL6smOHDDuVMEZcnyunbg_ECSPwUBg_x8Q_idoiNN1VENVTxHGMVrB-BHG9Bml0sqQl3Xq9xEnwVY9Jr4dtL8qOn9Aw-aUFXqI2LWxu-91iNrBEfRfF55dwCi6cBzZ6pigHoQuQptIU-ifSHd9P1H7O2o7k856XmTaioHiOJ6MWPf5a_wzdzq8UHfuGnp9a4P1Wcm-_4E-tRLWVDL5gSoeE1aqUAA96xZFUH2AdTTk49W8RnJqO5WhGwk72sfLLE6D5tCFxuxMAf8p2N6G7_rC-CYS1djxCSs7diTa89LF3e8hnLgH368PpbaY7Mzm08eQ-Xgef35d1QOrmcu_zrpxSBeBax3Sy_oc0slsobSlgJ91etzv4qbFJnF5p3oj6RQV9her5dmez1Ohgo2oY6IY4yIxgc01v_l0ls3tx3IFlXu-e_hhkFQcpR4ZyB_qWXVo45Q58sIhwshbnJuRqVBxyRRentplIfiu4YS_t_9y3Mcbdt_Vu-Fs_3UeaBp8fXhieO2uwclM0VYY2vwq7ZSqYXUZBnkd7FOq9x1YZzYtqbr9oORnrQ9ZZ2gOWWnJqkqtJnZ0ghXspRm3rYaWB6lfpeWgl9hhw1oJsu2kiYcIodjy4b22hvtZ7r9UnBq3ez-c9_SlYxrQpqSZs_yiIXqclzuqt6Byy9i73_z0nMruJJ1IBqlOS2ZbqkMVcb_4ean8tgntbkQ0VasxBQpxgSVgMOivokRIhBB9Q5F_ysiF71jRFQzXfcj9lXgOm_Q_V8iwjaVfFb4bqg7qJdSiOV2Wls8gXdOSSnBjOI2tufkex63wFQ4nU38I6FIt0Fgo5qsuOUgFyX4W68B9Zn_Xqeko5d711VBxyeVza0_mwx__dcfSk20jbIfzxRZOl5xzi2Iy1Vpm-9W9rJ2OsqZt2WWJf54Iuviiwr8e_9iBvJzYIcFcq_05ykruqxu0ri6rWOJ', 'Accept': '*/*', 'Accept-Encoding': 'gzip, deflate')>, real_url=URL('https://sqladmin.googleapis.com/sql/v1beta4/projects/w210-capstone-ta/instances/w210-therapeutic-accelerator/connectSettings')), (), status=404, message='Not Found', headers=<CIMultiDictProxy('Vary': 'Origin', 'Vary': 'X-Origin', 'Vary': 'Referer', 'Content-Type': 'application/json; charset=UTF-8', 'Content-Encoding': 'gzip', 'Date': 'Thu, 08 Jun 2023 00:25:12 GMT', 'Server': 'ESF', 'Cache-Control': 'private', 'X-XSS-Protection': '0', 'X-Frame-Options': 'SAMEORIGIN', 'X-Content-Type-Options': 'nosniff', 'Transfer-Encoding': 'chunked')>)>\n",
      "Traceback (most recent call last):\n",
      "  File \"/home/nick_lee_berkeley_edu/anaconda3/lib/python3.10/site-packages/google/cloud/sql/connector/instance.py\", line 388, in _refresh_task\n",
      "    refresh_data = await refresh_task\n",
      "  File \"/home/nick_lee_berkeley_edu/anaconda3/lib/python3.10/site-packages/google/cloud/sql/connector/instance.py\", line 312, in _perform_refresh\n",
      "    metadata = await metadata_task\n",
      "  File \"/home/nick_lee_berkeley_edu/anaconda3/lib/python3.10/site-packages/google/cloud/sql/connector/refresh_utils.py\", line 101, in _get_metadata\n",
      "    resp = await client_session.get(url, headers=headers, raise_for_status=True)\n",
      "  File \"/home/nick_lee_berkeley_edu/anaconda3/lib/python3.10/site-packages/aiohttp/client.py\", line 640, in _request\n",
      "    resp.raise_for_status()\n",
      "  File \"/home/nick_lee_berkeley_edu/anaconda3/lib/python3.10/site-packages/aiohttp/client_reqrep.py\", line 1004, in raise_for_status\n",
      "    raise ClientResponseError(\n",
      "aiohttp.client_exceptions.ClientResponseError: 404, message='Not Found', url=URL('https://sqladmin.googleapis.com/sql/v1beta4/projects/w210-capstone-ta/instances/w210-therapeutic-accelerator/connectSettings')\n"
     ]
    }
   ],
   "source": [
    "# create connection pool with 'creator' argument to our connection object function\n",
    "pool = sqlalchemy.create_engine(\n",
    "    \"postgresql+pg8000://\",\n",
    "    creator=getconn(),\n",
    ")"
   ]
  },
  {
   "cell_type": "code",
   "execution_count": null,
   "metadata": {
    "jupyter": {
     "source_hidden": true
    }
   },
   "outputs": [],
   "source": [
    "# for context managment\n",
    "# build connection\n",
    "def getconn() -> pg8000.connections.Connection:\n",
    "    with Connector() as connector:\n",
    "        conn = connector.connect(\n",
    "            \"project:region:instance\",\n",
    "            \"pymysql\",\n",
    "            user=\"my-user\",\n",
    "            password=\"my-password\",\n",
    "            db=\"my-db-name\"\n",
    "        )\n",
    "    return conn\n",
    "\n",
    "# create connection pool\n",
    "pool = sqlalchemy.create_engine(\n",
    "    \"mysql+pymysql://\",\n",
    "    creator=getconn,\n",
    ")\n",
    "\n",
    "# insert statement\n",
    "insert_stmt = sqlalchemy.text(\n",
    "    \"INSERT INTO my_table (id, title) VALUES (:id, :title)\",\n",
    ")\n",
    "\n",
    "# interact with Cloud SQL database using connection pool\n",
    "with pool.connect() as db_conn:\n",
    "    # insert into database\n",
    "    db_conn.execute(insert_stmt, parameters={\"id\": \"book1\", \"title\": \"Book One\"})\n",
    "\n",
    "    # commit transaction (SQLAlchemy v2.X.X is commit as you go)\n",
    "    db_conn.commit()\n",
    "\n",
    "    # query database\n",
    "    result = db_conn.execute(sqlalchemy.text(\"SELECT * from my_table\")).fetchall()\n",
    "\n",
    "    # Do something with the results\n",
    "    for row in result:\n",
    "        print(row)"
   ]
  },
  {
   "cell_type": "code",
   "execution_count": null,
   "metadata": {
    "jupyter": {
     "source_hidden": true
    }
   },
   "outputs": [],
   "source": [
    "# import os\n",
    "\n",
    "# from google.cloud.sql.connector import Connector, IPTypes\n",
    "# import pg8000\n",
    "\n",
    "# import sqlalchemy\n",
    "\n",
    "\n",
    "# def connect_with_connector() -> sqlalchemy.engine.base.Engine:\n",
    "#     \"\"\"\n",
    "#     Initializes a connection pool for a Cloud SQL instance of Postgres.\n",
    "\n",
    "#     Uses the Cloud SQL Python Connector package.\n",
    "#     \"\"\"\n",
    "#     # Note: Saving credentials in environment variables is convenient, but not\n",
    "#     # secure - consider a more secure solution such as\n",
    "#     # Cloud Secret Manager (https://cloud.google.com/secret-manager) to help\n",
    "#     # keep secrets safe.\n",
    "\n",
    "#     instance_connection_name = os.environ[\"INSTANCE_CONNECTION_NAME\"]  # e.g. 'project:region:instance'\n",
    "#     db_user = os.environ[\"DB_USER\"]  # e.g. 'my-db-user'\n",
    "#     db_pass = os.environ[\"DB_PASS\"]  # e.g. 'my-db-password'\n",
    "#     db_name = os.environ[\"DB_NAME\"]  # e.g. 'my-database'\n",
    "\n",
    "#     ip_type = IPTypes.PRIVATE if os.environ.get(\"PRIVATE_IP\") else IPTypes.PUBLIC\n",
    "\n",
    "#     # initialize Cloud SQL Python Connector object\n",
    "#     connector = Connector()\n",
    "\n",
    "#     def getconn() -> pg8000.dbapi.Connection:\n",
    "#         conn: pg8000.dbapi.Connection = connector.connect(\n",
    "#             instance_connection_name,\n",
    "#             \"pg8000\",\n",
    "#             user=db_user,\n",
    "#             password=db_pass,\n",
    "#             db=db_name,\n",
    "#             ip_type=ip_type,\n",
    "#         )\n",
    "#         return conn\n",
    "\n",
    "#     # The Cloud SQL Python Connector can be used with SQLAlchemy\n",
    "#     # using the 'creator' argument to 'create_engine'\n",
    "#     pool = sqlalchemy.create_engine(\n",
    "#         \"postgresql+pg8000://\",\n",
    "#         creator=getconn,\n",
    "#         # ...\n",
    "#     )\n",
    "#     return pool"
   ]
  },
  {
   "cell_type": "code",
   "execution_count": 50,
   "metadata": {
    "scrolled": true
   },
   "outputs": [
    {
     "ename": "ClientResponseError",
     "evalue": "404, message='Not Found', url=URL('https://sqladmin.googleapis.com/sql/v1beta4/projects/w210-capstone-ta/instances/w210-therapeutic-accelerator/connectSettings')",
     "output_type": "error",
     "traceback": [
      "\u001b[0;31m---------------------------------------------------------------------------\u001b[0m",
      "\u001b[0;31mClientResponseError\u001b[0m                       Traceback (most recent call last)",
      "Cell \u001b[0;32mIn[50], line 5\u001b[0m\n\u001b[1;32m      2\u001b[0m \u001b[38;5;28;01mfrom\u001b[39;00m \u001b[38;5;21;01msqlalchemy\u001b[39;00m \u001b[38;5;28;01mimport\u001b[39;00m select\n\u001b[1;32m      3\u001b[0m session \u001b[38;5;241m=\u001b[39m Session(pool)\n\u001b[0;32m----> 5\u001b[0m \u001b[38;5;28;01mwith\u001b[39;00m \u001b[43mpool\u001b[49m\u001b[38;5;241;43m.\u001b[39;49m\u001b[43mconnect\u001b[49m\u001b[43m(\u001b[49m\u001b[43m)\u001b[49m \u001b[38;5;28;01mas\u001b[39;00m db_conn:\n\u001b[1;32m      6\u001b[0m     results \u001b[38;5;241m=\u001b[39m db_conn\u001b[38;5;241m.\u001b[39mexecute(sqlalchemy\u001b[38;5;241m.\u001b[39mtext(\u001b[38;5;124m\"\u001b[39m\u001b[38;5;124mSELECT * FROM semantic\u001b[39m\u001b[38;5;124m\"\u001b[39m))\u001b[38;5;241m.\u001b[39mfetchall()\n",
      "File \u001b[0;32m~/anaconda3/lib/python3.10/site-packages/sqlalchemy/engine/base.py:3234\u001b[0m, in \u001b[0;36mEngine.connect\u001b[0;34m(self, close_with_result)\u001b[0m\n\u001b[1;32m   3219\u001b[0m \u001b[38;5;28;01mdef\u001b[39;00m \u001b[38;5;21mconnect\u001b[39m(\u001b[38;5;28mself\u001b[39m, close_with_result\u001b[38;5;241m=\u001b[39m\u001b[38;5;28;01mFalse\u001b[39;00m):\n\u001b[1;32m   3220\u001b[0m \u001b[38;5;250m    \u001b[39m\u001b[38;5;124;03m\"\"\"Return a new :class:`_engine.Connection` object.\u001b[39;00m\n\u001b[1;32m   3221\u001b[0m \n\u001b[1;32m   3222\u001b[0m \u001b[38;5;124;03m    The :class:`_engine.Connection` object is a facade that uses a DBAPI\u001b[39;00m\n\u001b[0;32m   (...)\u001b[0m\n\u001b[1;32m   3231\u001b[0m \n\u001b[1;32m   3232\u001b[0m \u001b[38;5;124;03m    \"\"\"\u001b[39;00m\n\u001b[0;32m-> 3234\u001b[0m     \u001b[38;5;28;01mreturn\u001b[39;00m \u001b[38;5;28;43mself\u001b[39;49m\u001b[38;5;241;43m.\u001b[39;49m\u001b[43m_connection_cls\u001b[49m\u001b[43m(\u001b[49m\u001b[38;5;28;43mself\u001b[39;49m\u001b[43m,\u001b[49m\u001b[43m \u001b[49m\u001b[43mclose_with_result\u001b[49m\u001b[38;5;241;43m=\u001b[39;49m\u001b[43mclose_with_result\u001b[49m\u001b[43m)\u001b[49m\n",
      "File \u001b[0;32m~/anaconda3/lib/python3.10/site-packages/sqlalchemy/engine/base.py:96\u001b[0m, in \u001b[0;36mConnection.__init__\u001b[0;34m(self, engine, connection, close_with_result, _branch_from, _execution_options, _dispatch, _has_events, _allow_revalidate)\u001b[0m\n\u001b[1;32m     91\u001b[0m     \u001b[38;5;28mself\u001b[39m\u001b[38;5;241m.\u001b[39m_has_events \u001b[38;5;241m=\u001b[39m _branch_from\u001b[38;5;241m.\u001b[39m_has_events\n\u001b[1;32m     92\u001b[0m \u001b[38;5;28;01melse\u001b[39;00m:\n\u001b[1;32m     93\u001b[0m     \u001b[38;5;28mself\u001b[39m\u001b[38;5;241m.\u001b[39m_dbapi_connection \u001b[38;5;241m=\u001b[39m (\n\u001b[1;32m     94\u001b[0m         connection\n\u001b[1;32m     95\u001b[0m         \u001b[38;5;28;01mif\u001b[39;00m connection \u001b[38;5;129;01mis\u001b[39;00m \u001b[38;5;129;01mnot\u001b[39;00m \u001b[38;5;28;01mNone\u001b[39;00m\n\u001b[0;32m---> 96\u001b[0m         \u001b[38;5;28;01melse\u001b[39;00m \u001b[43mengine\u001b[49m\u001b[38;5;241;43m.\u001b[39;49m\u001b[43mraw_connection\u001b[49m\u001b[43m(\u001b[49m\u001b[43m)\u001b[49m\n\u001b[1;32m     97\u001b[0m     )\n\u001b[1;32m     99\u001b[0m     \u001b[38;5;28mself\u001b[39m\u001b[38;5;241m.\u001b[39m_transaction \u001b[38;5;241m=\u001b[39m \u001b[38;5;28mself\u001b[39m\u001b[38;5;241m.\u001b[39m_nested_transaction \u001b[38;5;241m=\u001b[39m \u001b[38;5;28;01mNone\u001b[39;00m\n\u001b[1;32m    100\u001b[0m     \u001b[38;5;28mself\u001b[39m\u001b[38;5;241m.\u001b[39m__savepoint_seq \u001b[38;5;241m=\u001b[39m \u001b[38;5;241m0\u001b[39m\n",
      "File \u001b[0;32m~/anaconda3/lib/python3.10/site-packages/sqlalchemy/engine/base.py:3313\u001b[0m, in \u001b[0;36mEngine.raw_connection\u001b[0;34m(self, _connection)\u001b[0m\n\u001b[1;32m   3291\u001b[0m \u001b[38;5;28;01mdef\u001b[39;00m \u001b[38;5;21mraw_connection\u001b[39m(\u001b[38;5;28mself\u001b[39m, _connection\u001b[38;5;241m=\u001b[39m\u001b[38;5;28;01mNone\u001b[39;00m):\n\u001b[1;32m   3292\u001b[0m \u001b[38;5;250m    \u001b[39m\u001b[38;5;124;03m\"\"\"Return a \"raw\" DBAPI connection from the connection pool.\u001b[39;00m\n\u001b[1;32m   3293\u001b[0m \n\u001b[1;32m   3294\u001b[0m \u001b[38;5;124;03m    The returned object is a proxied version of the DBAPI\u001b[39;00m\n\u001b[0;32m   (...)\u001b[0m\n\u001b[1;32m   3311\u001b[0m \n\u001b[1;32m   3312\u001b[0m \u001b[38;5;124;03m    \"\"\"\u001b[39;00m\n\u001b[0;32m-> 3313\u001b[0m     \u001b[38;5;28;01mreturn\u001b[39;00m \u001b[38;5;28;43mself\u001b[39;49m\u001b[38;5;241;43m.\u001b[39;49m\u001b[43m_wrap_pool_connect\u001b[49m\u001b[43m(\u001b[49m\u001b[38;5;28;43mself\u001b[39;49m\u001b[38;5;241;43m.\u001b[39;49m\u001b[43mpool\u001b[49m\u001b[38;5;241;43m.\u001b[39;49m\u001b[43mconnect\u001b[49m\u001b[43m,\u001b[49m\u001b[43m \u001b[49m\u001b[43m_connection\u001b[49m\u001b[43m)\u001b[49m\n",
      "File \u001b[0;32m~/anaconda3/lib/python3.10/site-packages/sqlalchemy/engine/base.py:3280\u001b[0m, in \u001b[0;36mEngine._wrap_pool_connect\u001b[0;34m(self, fn, connection)\u001b[0m\n\u001b[1;32m   3278\u001b[0m dialect \u001b[38;5;241m=\u001b[39m \u001b[38;5;28mself\u001b[39m\u001b[38;5;241m.\u001b[39mdialect\n\u001b[1;32m   3279\u001b[0m \u001b[38;5;28;01mtry\u001b[39;00m:\n\u001b[0;32m-> 3280\u001b[0m     \u001b[38;5;28;01mreturn\u001b[39;00m \u001b[43mfn\u001b[49m\u001b[43m(\u001b[49m\u001b[43m)\u001b[49m\n\u001b[1;32m   3281\u001b[0m \u001b[38;5;28;01mexcept\u001b[39;00m dialect\u001b[38;5;241m.\u001b[39mdbapi\u001b[38;5;241m.\u001b[39mError \u001b[38;5;28;01mas\u001b[39;00m e:\n\u001b[1;32m   3282\u001b[0m     \u001b[38;5;28;01mif\u001b[39;00m connection \u001b[38;5;129;01mis\u001b[39;00m \u001b[38;5;28;01mNone\u001b[39;00m:\n",
      "File \u001b[0;32m~/anaconda3/lib/python3.10/site-packages/sqlalchemy/pool/base.py:310\u001b[0m, in \u001b[0;36mPool.connect\u001b[0;34m(self)\u001b[0m\n\u001b[1;32m    302\u001b[0m \u001b[38;5;28;01mdef\u001b[39;00m \u001b[38;5;21mconnect\u001b[39m(\u001b[38;5;28mself\u001b[39m):\n\u001b[1;32m    303\u001b[0m \u001b[38;5;250m    \u001b[39m\u001b[38;5;124;03m\"\"\"Return a DBAPI connection from the pool.\u001b[39;00m\n\u001b[1;32m    304\u001b[0m \n\u001b[1;32m    305\u001b[0m \u001b[38;5;124;03m    The connection is instrumented such that when its\u001b[39;00m\n\u001b[0;32m   (...)\u001b[0m\n\u001b[1;32m    308\u001b[0m \n\u001b[1;32m    309\u001b[0m \u001b[38;5;124;03m    \"\"\"\u001b[39;00m\n\u001b[0;32m--> 310\u001b[0m     \u001b[38;5;28;01mreturn\u001b[39;00m \u001b[43m_ConnectionFairy\u001b[49m\u001b[38;5;241;43m.\u001b[39;49m\u001b[43m_checkout\u001b[49m\u001b[43m(\u001b[49m\u001b[38;5;28;43mself\u001b[39;49m\u001b[43m)\u001b[49m\n",
      "File \u001b[0;32m~/anaconda3/lib/python3.10/site-packages/sqlalchemy/pool/base.py:868\u001b[0m, in \u001b[0;36m_ConnectionFairy._checkout\u001b[0;34m(cls, pool, threadconns, fairy)\u001b[0m\n\u001b[1;32m    865\u001b[0m \u001b[38;5;129m@classmethod\u001b[39m\n\u001b[1;32m    866\u001b[0m \u001b[38;5;28;01mdef\u001b[39;00m \u001b[38;5;21m_checkout\u001b[39m(\u001b[38;5;28mcls\u001b[39m, pool, threadconns\u001b[38;5;241m=\u001b[39m\u001b[38;5;28;01mNone\u001b[39;00m, fairy\u001b[38;5;241m=\u001b[39m\u001b[38;5;28;01mNone\u001b[39;00m):\n\u001b[1;32m    867\u001b[0m     \u001b[38;5;28;01mif\u001b[39;00m \u001b[38;5;129;01mnot\u001b[39;00m fairy:\n\u001b[0;32m--> 868\u001b[0m         fairy \u001b[38;5;241m=\u001b[39m \u001b[43m_ConnectionRecord\u001b[49m\u001b[38;5;241;43m.\u001b[39;49m\u001b[43mcheckout\u001b[49m\u001b[43m(\u001b[49m\u001b[43mpool\u001b[49m\u001b[43m)\u001b[49m\n\u001b[1;32m    870\u001b[0m         fairy\u001b[38;5;241m.\u001b[39m_pool \u001b[38;5;241m=\u001b[39m pool\n\u001b[1;32m    871\u001b[0m         fairy\u001b[38;5;241m.\u001b[39m_counter \u001b[38;5;241m=\u001b[39m \u001b[38;5;241m0\u001b[39m\n",
      "File \u001b[0;32m~/anaconda3/lib/python3.10/site-packages/sqlalchemy/pool/base.py:476\u001b[0m, in \u001b[0;36m_ConnectionRecord.checkout\u001b[0;34m(cls, pool)\u001b[0m\n\u001b[1;32m    474\u001b[0m \u001b[38;5;129m@classmethod\u001b[39m\n\u001b[1;32m    475\u001b[0m \u001b[38;5;28;01mdef\u001b[39;00m \u001b[38;5;21mcheckout\u001b[39m(\u001b[38;5;28mcls\u001b[39m, pool):\n\u001b[0;32m--> 476\u001b[0m     rec \u001b[38;5;241m=\u001b[39m \u001b[43mpool\u001b[49m\u001b[38;5;241;43m.\u001b[39;49m\u001b[43m_do_get\u001b[49m\u001b[43m(\u001b[49m\u001b[43m)\u001b[49m\n\u001b[1;32m    477\u001b[0m     \u001b[38;5;28;01mtry\u001b[39;00m:\n\u001b[1;32m    478\u001b[0m         dbapi_connection \u001b[38;5;241m=\u001b[39m rec\u001b[38;5;241m.\u001b[39mget_connection()\n",
      "File \u001b[0;32m~/anaconda3/lib/python3.10/site-packages/sqlalchemy/pool/impl.py:145\u001b[0m, in \u001b[0;36mQueuePool._do_get\u001b[0;34m(self)\u001b[0m\n\u001b[1;32m    143\u001b[0m         \u001b[38;5;28;01mreturn\u001b[39;00m \u001b[38;5;28mself\u001b[39m\u001b[38;5;241m.\u001b[39m_create_connection()\n\u001b[1;32m    144\u001b[0m     \u001b[38;5;28;01mexcept\u001b[39;00m:\n\u001b[0;32m--> 145\u001b[0m         \u001b[38;5;28;01mwith\u001b[39;00m util\u001b[38;5;241m.\u001b[39msafe_reraise():\n\u001b[1;32m    146\u001b[0m             \u001b[38;5;28mself\u001b[39m\u001b[38;5;241m.\u001b[39m_dec_overflow()\n\u001b[1;32m    147\u001b[0m \u001b[38;5;28;01melse\u001b[39;00m:\n",
      "File \u001b[0;32m~/anaconda3/lib/python3.10/site-packages/sqlalchemy/util/langhelpers.py:70\u001b[0m, in \u001b[0;36msafe_reraise.__exit__\u001b[0;34m(self, type_, value, traceback)\u001b[0m\n\u001b[1;32m     68\u001b[0m     \u001b[38;5;28mself\u001b[39m\u001b[38;5;241m.\u001b[39m_exc_info \u001b[38;5;241m=\u001b[39m \u001b[38;5;28;01mNone\u001b[39;00m  \u001b[38;5;66;03m# remove potential circular references\u001b[39;00m\n\u001b[1;32m     69\u001b[0m     \u001b[38;5;28;01mif\u001b[39;00m \u001b[38;5;129;01mnot\u001b[39;00m \u001b[38;5;28mself\u001b[39m\u001b[38;5;241m.\u001b[39mwarn_only:\n\u001b[0;32m---> 70\u001b[0m         \u001b[43mcompat\u001b[49m\u001b[38;5;241;43m.\u001b[39;49m\u001b[43mraise_\u001b[49m\u001b[43m(\u001b[49m\n\u001b[1;32m     71\u001b[0m \u001b[43m            \u001b[49m\u001b[43mexc_value\u001b[49m\u001b[43m,\u001b[49m\n\u001b[1;32m     72\u001b[0m \u001b[43m            \u001b[49m\u001b[43mwith_traceback\u001b[49m\u001b[38;5;241;43m=\u001b[39;49m\u001b[43mexc_tb\u001b[49m\u001b[43m,\u001b[49m\n\u001b[1;32m     73\u001b[0m \u001b[43m        \u001b[49m\u001b[43m)\u001b[49m\n\u001b[1;32m     74\u001b[0m \u001b[38;5;28;01melse\u001b[39;00m:\n\u001b[1;32m     75\u001b[0m     \u001b[38;5;28;01mif\u001b[39;00m \u001b[38;5;129;01mnot\u001b[39;00m compat\u001b[38;5;241m.\u001b[39mpy3k \u001b[38;5;129;01mand\u001b[39;00m \u001b[38;5;28mself\u001b[39m\u001b[38;5;241m.\u001b[39m_exc_info \u001b[38;5;129;01mand\u001b[39;00m \u001b[38;5;28mself\u001b[39m\u001b[38;5;241m.\u001b[39m_exc_info[\u001b[38;5;241m1\u001b[39m]:\n\u001b[1;32m     76\u001b[0m         \u001b[38;5;66;03m# emulate Py3K's behavior of telling us when an exception\u001b[39;00m\n\u001b[1;32m     77\u001b[0m         \u001b[38;5;66;03m# occurs in an exception handler.\u001b[39;00m\n",
      "File \u001b[0;32m~/anaconda3/lib/python3.10/site-packages/sqlalchemy/util/compat.py:208\u001b[0m, in \u001b[0;36mraise_\u001b[0;34m(***failed resolving arguments***)\u001b[0m\n\u001b[1;32m    205\u001b[0m     exception\u001b[38;5;241m.\u001b[39m__cause__ \u001b[38;5;241m=\u001b[39m replace_context\n\u001b[1;32m    207\u001b[0m \u001b[38;5;28;01mtry\u001b[39;00m:\n\u001b[0;32m--> 208\u001b[0m     \u001b[38;5;28;01mraise\u001b[39;00m exception\n\u001b[1;32m    209\u001b[0m \u001b[38;5;28;01mfinally\u001b[39;00m:\n\u001b[1;32m    210\u001b[0m     \u001b[38;5;66;03m# credit to\u001b[39;00m\n\u001b[1;32m    211\u001b[0m     \u001b[38;5;66;03m# https://cosmicpercolator.com/2016/01/13/exception-leaks-in-python-2-and-3/\u001b[39;00m\n\u001b[1;32m    212\u001b[0m     \u001b[38;5;66;03m# as the __traceback__ object creates a cycle\u001b[39;00m\n\u001b[1;32m    213\u001b[0m     \u001b[38;5;28;01mdel\u001b[39;00m exception, replace_context, from_, with_traceback\n",
      "File \u001b[0;32m~/anaconda3/lib/python3.10/site-packages/sqlalchemy/pool/impl.py:143\u001b[0m, in \u001b[0;36mQueuePool._do_get\u001b[0;34m(self)\u001b[0m\n\u001b[1;32m    141\u001b[0m \u001b[38;5;28;01mif\u001b[39;00m \u001b[38;5;28mself\u001b[39m\u001b[38;5;241m.\u001b[39m_inc_overflow():\n\u001b[1;32m    142\u001b[0m     \u001b[38;5;28;01mtry\u001b[39;00m:\n\u001b[0;32m--> 143\u001b[0m         \u001b[38;5;28;01mreturn\u001b[39;00m \u001b[38;5;28;43mself\u001b[39;49m\u001b[38;5;241;43m.\u001b[39;49m\u001b[43m_create_connection\u001b[49m\u001b[43m(\u001b[49m\u001b[43m)\u001b[49m\n\u001b[1;32m    144\u001b[0m     \u001b[38;5;28;01mexcept\u001b[39;00m:\n\u001b[1;32m    145\u001b[0m         \u001b[38;5;28;01mwith\u001b[39;00m util\u001b[38;5;241m.\u001b[39msafe_reraise():\n",
      "File \u001b[0;32m~/anaconda3/lib/python3.10/site-packages/sqlalchemy/pool/base.py:256\u001b[0m, in \u001b[0;36mPool._create_connection\u001b[0;34m(self)\u001b[0m\n\u001b[1;32m    253\u001b[0m \u001b[38;5;28;01mdef\u001b[39;00m \u001b[38;5;21m_create_connection\u001b[39m(\u001b[38;5;28mself\u001b[39m):\n\u001b[1;32m    254\u001b[0m \u001b[38;5;250m    \u001b[39m\u001b[38;5;124;03m\"\"\"Called by subclasses to create a new ConnectionRecord.\"\"\"\u001b[39;00m\n\u001b[0;32m--> 256\u001b[0m     \u001b[38;5;28;01mreturn\u001b[39;00m \u001b[43m_ConnectionRecord\u001b[49m\u001b[43m(\u001b[49m\u001b[38;5;28;43mself\u001b[39;49m\u001b[43m)\u001b[49m\n",
      "File \u001b[0;32m~/anaconda3/lib/python3.10/site-packages/sqlalchemy/pool/base.py:371\u001b[0m, in \u001b[0;36m_ConnectionRecord.__init__\u001b[0;34m(self, pool, connect)\u001b[0m\n\u001b[1;32m    369\u001b[0m \u001b[38;5;28mself\u001b[39m\u001b[38;5;241m.\u001b[39m__pool \u001b[38;5;241m=\u001b[39m pool\n\u001b[1;32m    370\u001b[0m \u001b[38;5;28;01mif\u001b[39;00m connect:\n\u001b[0;32m--> 371\u001b[0m     \u001b[38;5;28;43mself\u001b[39;49m\u001b[38;5;241;43m.\u001b[39;49m\u001b[43m__connect\u001b[49m\u001b[43m(\u001b[49m\u001b[43m)\u001b[49m\n\u001b[1;32m    372\u001b[0m \u001b[38;5;28mself\u001b[39m\u001b[38;5;241m.\u001b[39mfinalize_callback \u001b[38;5;241m=\u001b[39m deque()\n",
      "File \u001b[0;32m~/anaconda3/lib/python3.10/site-packages/sqlalchemy/pool/base.py:665\u001b[0m, in \u001b[0;36m_ConnectionRecord.__connect\u001b[0;34m(self)\u001b[0m\n\u001b[1;32m    663\u001b[0m     \u001b[38;5;28mself\u001b[39m\u001b[38;5;241m.\u001b[39mfresh \u001b[38;5;241m=\u001b[39m \u001b[38;5;28;01mTrue\u001b[39;00m\n\u001b[1;32m    664\u001b[0m \u001b[38;5;28;01mexcept\u001b[39;00m \u001b[38;5;167;01mException\u001b[39;00m \u001b[38;5;28;01mas\u001b[39;00m e:\n\u001b[0;32m--> 665\u001b[0m     \u001b[38;5;28;01mwith\u001b[39;00m util\u001b[38;5;241m.\u001b[39msafe_reraise():\n\u001b[1;32m    666\u001b[0m         pool\u001b[38;5;241m.\u001b[39mlogger\u001b[38;5;241m.\u001b[39mdebug(\u001b[38;5;124m\"\u001b[39m\u001b[38;5;124mError on connect(): \u001b[39m\u001b[38;5;132;01m%s\u001b[39;00m\u001b[38;5;124m\"\u001b[39m, e)\n\u001b[1;32m    667\u001b[0m \u001b[38;5;28;01melse\u001b[39;00m:\n\u001b[1;32m    668\u001b[0m     \u001b[38;5;66;03m# in SQLAlchemy 1.4 the first_connect event is not used by\u001b[39;00m\n\u001b[1;32m    669\u001b[0m     \u001b[38;5;66;03m# the engine, so this will usually not be set\u001b[39;00m\n",
      "File \u001b[0;32m~/anaconda3/lib/python3.10/site-packages/sqlalchemy/util/langhelpers.py:70\u001b[0m, in \u001b[0;36msafe_reraise.__exit__\u001b[0;34m(self, type_, value, traceback)\u001b[0m\n\u001b[1;32m     68\u001b[0m     \u001b[38;5;28mself\u001b[39m\u001b[38;5;241m.\u001b[39m_exc_info \u001b[38;5;241m=\u001b[39m \u001b[38;5;28;01mNone\u001b[39;00m  \u001b[38;5;66;03m# remove potential circular references\u001b[39;00m\n\u001b[1;32m     69\u001b[0m     \u001b[38;5;28;01mif\u001b[39;00m \u001b[38;5;129;01mnot\u001b[39;00m \u001b[38;5;28mself\u001b[39m\u001b[38;5;241m.\u001b[39mwarn_only:\n\u001b[0;32m---> 70\u001b[0m         \u001b[43mcompat\u001b[49m\u001b[38;5;241;43m.\u001b[39;49m\u001b[43mraise_\u001b[49m\u001b[43m(\u001b[49m\n\u001b[1;32m     71\u001b[0m \u001b[43m            \u001b[49m\u001b[43mexc_value\u001b[49m\u001b[43m,\u001b[49m\n\u001b[1;32m     72\u001b[0m \u001b[43m            \u001b[49m\u001b[43mwith_traceback\u001b[49m\u001b[38;5;241;43m=\u001b[39;49m\u001b[43mexc_tb\u001b[49m\u001b[43m,\u001b[49m\n\u001b[1;32m     73\u001b[0m \u001b[43m        \u001b[49m\u001b[43m)\u001b[49m\n\u001b[1;32m     74\u001b[0m \u001b[38;5;28;01melse\u001b[39;00m:\n\u001b[1;32m     75\u001b[0m     \u001b[38;5;28;01mif\u001b[39;00m \u001b[38;5;129;01mnot\u001b[39;00m compat\u001b[38;5;241m.\u001b[39mpy3k \u001b[38;5;129;01mand\u001b[39;00m \u001b[38;5;28mself\u001b[39m\u001b[38;5;241m.\u001b[39m_exc_info \u001b[38;5;129;01mand\u001b[39;00m \u001b[38;5;28mself\u001b[39m\u001b[38;5;241m.\u001b[39m_exc_info[\u001b[38;5;241m1\u001b[39m]:\n\u001b[1;32m     76\u001b[0m         \u001b[38;5;66;03m# emulate Py3K's behavior of telling us when an exception\u001b[39;00m\n\u001b[1;32m     77\u001b[0m         \u001b[38;5;66;03m# occurs in an exception handler.\u001b[39;00m\n",
      "File \u001b[0;32m~/anaconda3/lib/python3.10/site-packages/sqlalchemy/util/compat.py:208\u001b[0m, in \u001b[0;36mraise_\u001b[0;34m(***failed resolving arguments***)\u001b[0m\n\u001b[1;32m    205\u001b[0m     exception\u001b[38;5;241m.\u001b[39m__cause__ \u001b[38;5;241m=\u001b[39m replace_context\n\u001b[1;32m    207\u001b[0m \u001b[38;5;28;01mtry\u001b[39;00m:\n\u001b[0;32m--> 208\u001b[0m     \u001b[38;5;28;01mraise\u001b[39;00m exception\n\u001b[1;32m    209\u001b[0m \u001b[38;5;28;01mfinally\u001b[39;00m:\n\u001b[1;32m    210\u001b[0m     \u001b[38;5;66;03m# credit to\u001b[39;00m\n\u001b[1;32m    211\u001b[0m     \u001b[38;5;66;03m# https://cosmicpercolator.com/2016/01/13/exception-leaks-in-python-2-and-3/\u001b[39;00m\n\u001b[1;32m    212\u001b[0m     \u001b[38;5;66;03m# as the __traceback__ object creates a cycle\u001b[39;00m\n\u001b[1;32m    213\u001b[0m     \u001b[38;5;28;01mdel\u001b[39;00m exception, replace_context, from_, with_traceback\n",
      "File \u001b[0;32m~/anaconda3/lib/python3.10/site-packages/sqlalchemy/pool/base.py:661\u001b[0m, in \u001b[0;36m_ConnectionRecord.__connect\u001b[0;34m(self)\u001b[0m\n\u001b[1;32m    659\u001b[0m \u001b[38;5;28;01mtry\u001b[39;00m:\n\u001b[1;32m    660\u001b[0m     \u001b[38;5;28mself\u001b[39m\u001b[38;5;241m.\u001b[39mstarttime \u001b[38;5;241m=\u001b[39m time\u001b[38;5;241m.\u001b[39mtime()\n\u001b[0;32m--> 661\u001b[0m     \u001b[38;5;28mself\u001b[39m\u001b[38;5;241m.\u001b[39mdbapi_connection \u001b[38;5;241m=\u001b[39m connection \u001b[38;5;241m=\u001b[39m \u001b[43mpool\u001b[49m\u001b[38;5;241;43m.\u001b[39;49m\u001b[43m_invoke_creator\u001b[49m\u001b[43m(\u001b[49m\u001b[38;5;28;43mself\u001b[39;49m\u001b[43m)\u001b[49m\n\u001b[1;32m    662\u001b[0m     pool\u001b[38;5;241m.\u001b[39mlogger\u001b[38;5;241m.\u001b[39mdebug(\u001b[38;5;124m\"\u001b[39m\u001b[38;5;124mCreated new connection \u001b[39m\u001b[38;5;132;01m%r\u001b[39;00m\u001b[38;5;124m\"\u001b[39m, connection)\n\u001b[1;32m    663\u001b[0m     \u001b[38;5;28mself\u001b[39m\u001b[38;5;241m.\u001b[39mfresh \u001b[38;5;241m=\u001b[39m \u001b[38;5;28;01mTrue\u001b[39;00m\n",
      "File \u001b[0;32m~/anaconda3/lib/python3.10/site-packages/sqlalchemy/pool/base.py:241\u001b[0m, in \u001b[0;36mPool._should_wrap_creator.<locals>.<lambda>\u001b[0;34m(crec)\u001b[0m\n\u001b[1;32m    237\u001b[0m     \u001b[38;5;28;01mreturn\u001b[39;00m creator\n\u001b[1;32m    238\u001b[0m \u001b[38;5;66;03m# all other cases, just wrap and assume legacy \"creator\" callable\u001b[39;00m\n\u001b[1;32m    239\u001b[0m \u001b[38;5;66;03m# thing\u001b[39;00m\n\u001b[1;32m    240\u001b[0m \u001b[38;5;28;01melse\u001b[39;00m:\n\u001b[0;32m--> 241\u001b[0m     \u001b[38;5;28;01mreturn\u001b[39;00m \u001b[38;5;28;01mlambda\u001b[39;00m crec: \u001b[43mcreator\u001b[49m\u001b[43m(\u001b[49m\u001b[43m)\u001b[49m\n",
      "Cell \u001b[0;32mIn[47], line 13\u001b[0m, in \u001b[0;36mgetconn\u001b[0;34m()\u001b[0m\n\u001b[1;32m     10\u001b[0m DB_PASS \u001b[38;5;241m=\u001b[39m config[\u001b[38;5;124m'\u001b[39m\u001b[38;5;124mdatabase\u001b[39m\u001b[38;5;124m'\u001b[39m][\u001b[38;5;124m'\u001b[39m\u001b[38;5;124mpassword\u001b[39m\u001b[38;5;124m'\u001b[39m]\n\u001b[1;32m     11\u001b[0m DB_NAME \u001b[38;5;241m=\u001b[39m config[\u001b[38;5;124m'\u001b[39m\u001b[38;5;124mdatabase\u001b[39m\u001b[38;5;124m'\u001b[39m][\u001b[38;5;124m'\u001b[39m\u001b[38;5;124mname\u001b[39m\u001b[38;5;124m'\u001b[39m]\n\u001b[0;32m---> 13\u001b[0m conn \u001b[38;5;241m=\u001b[39m \u001b[43mconnector\u001b[49m\u001b[38;5;241;43m.\u001b[39;49m\u001b[43mconnect\u001b[49m\u001b[43m(\u001b[49m\n\u001b[1;32m     14\u001b[0m \u001b[43m    \u001b[49m\u001b[43mINSTANCE_CONNECTION_NAME\u001b[49m\u001b[43m,\u001b[49m\n\u001b[1;32m     15\u001b[0m \u001b[43m    \u001b[49m\u001b[38;5;124;43m\"\u001b[39;49m\u001b[38;5;124;43mpg8000\u001b[39;49m\u001b[38;5;124;43m\"\u001b[39;49m\u001b[43m,\u001b[49m\n\u001b[1;32m     16\u001b[0m \u001b[43m    \u001b[49m\u001b[43muser\u001b[49m\u001b[38;5;241;43m=\u001b[39;49m\u001b[43mDB_USER\u001b[49m\u001b[43m,\u001b[49m\n\u001b[1;32m     17\u001b[0m \u001b[43m    \u001b[49m\u001b[43mpassword\u001b[49m\u001b[38;5;241;43m=\u001b[39;49m\u001b[43mDB_PASS\u001b[49m\u001b[43m,\u001b[49m\n\u001b[1;32m     18\u001b[0m \u001b[43m    \u001b[49m\u001b[43mdb\u001b[49m\u001b[38;5;241;43m=\u001b[39;49m\u001b[43mDB_NAME\u001b[49m\n\u001b[1;32m     19\u001b[0m \u001b[43m\u001b[49m\u001b[43m)\u001b[49m\n\u001b[1;32m     20\u001b[0m \u001b[38;5;28;01mreturn\u001b[39;00m conn\n",
      "File \u001b[0;32m~/anaconda3/lib/python3.10/site-packages/google/cloud/sql/connector/connector.py:154\u001b[0m, in \u001b[0;36mConnector.connect\u001b[0;34m(self, instance_connection_string, driver, **kwargs)\u001b[0m\n\u001b[1;32m    150\u001b[0m \u001b[38;5;66;03m# if event loop is not in current thread, proceed with connection\u001b[39;00m\n\u001b[1;32m    151\u001b[0m connect_task \u001b[38;5;241m=\u001b[39m asyncio\u001b[38;5;241m.\u001b[39mrun_coroutine_threadsafe(\n\u001b[1;32m    152\u001b[0m     \u001b[38;5;28mself\u001b[39m\u001b[38;5;241m.\u001b[39mconnect_async(instance_connection_string, driver, \u001b[38;5;241m*\u001b[39m\u001b[38;5;241m*\u001b[39mkwargs), \u001b[38;5;28mself\u001b[39m\u001b[38;5;241m.\u001b[39m_loop\n\u001b[1;32m    153\u001b[0m )\n\u001b[0;32m--> 154\u001b[0m \u001b[38;5;28;01mreturn\u001b[39;00m \u001b[43mconnect_task\u001b[49m\u001b[38;5;241;43m.\u001b[39;49m\u001b[43mresult\u001b[49m\u001b[43m(\u001b[49m\u001b[43m)\u001b[49m\n",
      "File \u001b[0;32m~/anaconda3/lib/python3.10/concurrent/futures/_base.py:458\u001b[0m, in \u001b[0;36mFuture.result\u001b[0;34m(self, timeout)\u001b[0m\n\u001b[1;32m    456\u001b[0m     \u001b[38;5;28;01mraise\u001b[39;00m CancelledError()\n\u001b[1;32m    457\u001b[0m \u001b[38;5;28;01melif\u001b[39;00m \u001b[38;5;28mself\u001b[39m\u001b[38;5;241m.\u001b[39m_state \u001b[38;5;241m==\u001b[39m FINISHED:\n\u001b[0;32m--> 458\u001b[0m     \u001b[38;5;28;01mreturn\u001b[39;00m \u001b[38;5;28;43mself\u001b[39;49m\u001b[38;5;241;43m.\u001b[39;49m\u001b[43m__get_result\u001b[49m\u001b[43m(\u001b[49m\u001b[43m)\u001b[49m\n\u001b[1;32m    459\u001b[0m \u001b[38;5;28;01melse\u001b[39;00m:\n\u001b[1;32m    460\u001b[0m     \u001b[38;5;28;01mraise\u001b[39;00m \u001b[38;5;167;01mTimeoutError\u001b[39;00m()\n",
      "File \u001b[0;32m~/anaconda3/lib/python3.10/concurrent/futures/_base.py:403\u001b[0m, in \u001b[0;36mFuture.__get_result\u001b[0;34m(self)\u001b[0m\n\u001b[1;32m    401\u001b[0m \u001b[38;5;28;01mif\u001b[39;00m \u001b[38;5;28mself\u001b[39m\u001b[38;5;241m.\u001b[39m_exception:\n\u001b[1;32m    402\u001b[0m     \u001b[38;5;28;01mtry\u001b[39;00m:\n\u001b[0;32m--> 403\u001b[0m         \u001b[38;5;28;01mraise\u001b[39;00m \u001b[38;5;28mself\u001b[39m\u001b[38;5;241m.\u001b[39m_exception\n\u001b[1;32m    404\u001b[0m     \u001b[38;5;28;01mfinally\u001b[39;00m:\n\u001b[1;32m    405\u001b[0m         \u001b[38;5;66;03m# Break a reference cycle with the exception in self._exception\u001b[39;00m\n\u001b[1;32m    406\u001b[0m         \u001b[38;5;28mself\u001b[39m \u001b[38;5;241m=\u001b[39m \u001b[38;5;28;01mNone\u001b[39;00m\n",
      "File \u001b[0;32m~/anaconda3/lib/python3.10/site-packages/google/cloud/sql/connector/connector.py:261\u001b[0m, in \u001b[0;36mConnector.connect_async\u001b[0;34m(self, instance_connection_string, driver, **kwargs)\u001b[0m\n\u001b[1;32m    259\u001b[0m \u001b[38;5;66;03m# attempt to make connection to Cloud SQL instance for given timeout\u001b[39;00m\n\u001b[1;32m    260\u001b[0m \u001b[38;5;28;01mtry\u001b[39;00m:\n\u001b[0;32m--> 261\u001b[0m     \u001b[38;5;28;01mreturn\u001b[39;00m \u001b[38;5;28;01mawait\u001b[39;00m asyncio\u001b[38;5;241m.\u001b[39mwait_for(get_connection(), timeout)\n\u001b[1;32m    262\u001b[0m \u001b[38;5;28;01mexcept\u001b[39;00m asyncio\u001b[38;5;241m.\u001b[39mTimeoutError:\n\u001b[1;32m    263\u001b[0m     \u001b[38;5;28;01mraise\u001b[39;00m \u001b[38;5;167;01mTimeoutError\u001b[39;00m(\u001b[38;5;124mf\u001b[39m\u001b[38;5;124m\"\u001b[39m\u001b[38;5;124mConnection timed out after \u001b[39m\u001b[38;5;132;01m{\u001b[39;00mtimeout\u001b[38;5;132;01m}\u001b[39;00m\u001b[38;5;124ms\u001b[39m\u001b[38;5;124m\"\u001b[39m)\n",
      "File \u001b[0;32m~/anaconda3/lib/python3.10/asyncio/tasks.py:445\u001b[0m, in \u001b[0;36mwait_for\u001b[0;34m(fut, timeout)\u001b[0m\n\u001b[1;32m    442\u001b[0m         \u001b[38;5;28;01mraise\u001b[39;00m\n\u001b[1;32m    444\u001b[0m \u001b[38;5;28;01mif\u001b[39;00m fut\u001b[38;5;241m.\u001b[39mdone():\n\u001b[0;32m--> 445\u001b[0m     \u001b[38;5;28;01mreturn\u001b[39;00m \u001b[43mfut\u001b[49m\u001b[38;5;241;43m.\u001b[39;49m\u001b[43mresult\u001b[49m\u001b[43m(\u001b[49m\u001b[43m)\u001b[49m\n\u001b[1;32m    446\u001b[0m \u001b[38;5;28;01melse\u001b[39;00m:\n\u001b[1;32m    447\u001b[0m     fut\u001b[38;5;241m.\u001b[39mremove_done_callback(cb)\n",
      "File \u001b[0;32m~/anaconda3/lib/python3.10/site-packages/google/cloud/sql/connector/connector.py:237\u001b[0m, in \u001b[0;36mConnector.connect_async.<locals>.get_connection\u001b[0;34m()\u001b[0m\n\u001b[1;32m    236\u001b[0m \u001b[38;5;28;01masync\u001b[39;00m \u001b[38;5;28;01mdef\u001b[39;00m \u001b[38;5;21mget_connection\u001b[39m() \u001b[38;5;241m-\u001b[39m\u001b[38;5;241m>\u001b[39m Any:\n\u001b[0;32m--> 237\u001b[0m     instance_data, ip_address \u001b[38;5;241m=\u001b[39m \u001b[38;5;28;01mawait\u001b[39;00m instance\u001b[38;5;241m.\u001b[39mconnect_info(ip_type)\n\u001b[1;32m    239\u001b[0m     \u001b[38;5;66;03m# format `user` param for automatic IAM database authn\u001b[39;00m\n\u001b[1;32m    240\u001b[0m     \u001b[38;5;28;01mif\u001b[39;00m enable_iam_auth:\n",
      "File \u001b[0;32m~/anaconda3/lib/python3.10/site-packages/google/cloud/sql/connector/instance.py:445\u001b[0m, in \u001b[0;36mInstance.connect_info\u001b[0;34m(self, ip_type)\u001b[0m\n\u001b[1;32m    439\u001b[0m logger\u001b[38;5;241m.\u001b[39mdebug(\n\u001b[1;32m    440\u001b[0m     \u001b[38;5;124mf\u001b[39m\u001b[38;5;124m\"\u001b[39m\u001b[38;5;124m[\u001b[39m\u001b[38;5;124m'\u001b[39m\u001b[38;5;132;01m{\u001b[39;00m\u001b[38;5;28mself\u001b[39m\u001b[38;5;241m.\u001b[39m_instance_connection_string\u001b[38;5;132;01m}\u001b[39;00m\u001b[38;5;124m'\u001b[39m\u001b[38;5;124m]: Entered connect_info method\u001b[39m\u001b[38;5;124m\"\u001b[39m\n\u001b[1;32m    441\u001b[0m )\n\u001b[1;32m    443\u001b[0m instance_data: InstanceMetadata\n\u001b[0;32m--> 445\u001b[0m instance_data \u001b[38;5;241m=\u001b[39m \u001b[38;5;28;01mawait\u001b[39;00m \u001b[38;5;28mself\u001b[39m\u001b[38;5;241m.\u001b[39m_current\n\u001b[1;32m    446\u001b[0m ip_address: \u001b[38;5;28mstr\u001b[39m \u001b[38;5;241m=\u001b[39m instance_data\u001b[38;5;241m.\u001b[39mget_preferred_ip(ip_type)\n\u001b[1;32m    447\u001b[0m \u001b[38;5;28;01mreturn\u001b[39;00m instance_data, ip_address\n",
      "\u001b[0;31mClientResponseError\u001b[0m: 404, message='Not Found', url=URL('https://sqladmin.googleapis.com/sql/v1beta4/projects/w210-capstone-ta/instances/w210-therapeutic-accelerator/connectSettings')"
     ]
    }
   ],
   "source": [
    "from sqlalchemy.orm import Session\n",
    "from sqlalchemy import select\n",
    "\n",
    "with pool.connect() as db_conn:\n",
    "    results = db_conn.execute(sqlalchemy.text(\"SELECT * FROM semantic\")).fetchall()"
   ]
  },
  {
   "cell_type": "code",
   "execution_count": 38,
   "metadata": {},
   "outputs": [
    {
     "data": {
      "text/plain": [
       "Engine(postgresql+pg8000://)"
      ]
     },
     "execution_count": 38,
     "metadata": {},
     "output_type": "execute_result"
    }
   ],
   "source": [
    "pool"
   ]
  },
  {
   "cell_type": "code",
   "execution_count": 28,
   "metadata": {},
   "outputs": [
    {
     "name": "stderr",
     "output_type": "stream",
     "text": [
      "usage: ipykernel_launcher.py [--help] [--hydra-help] [--version]\n",
      "                             [--cfg {job,hydra,all}] [--resolve]\n",
      "                             [--package PACKAGE] [--run] [--multirun]\n",
      "                             [--shell-completion] [--config-path CONFIG_PATH]\n",
      "                             [--config-name CONFIG_NAME]\n",
      "                             [--config-dir CONFIG_DIR]\n",
      "                             [--experimental-rerun EXPERIMENTAL_RERUN]\n",
      "                             [--info [{all,config,defaults,defaults-tree,plugins,searchpath}]]\n",
      "                             [overrides ...]\n",
      "ipykernel_launcher.py: error: unrecognized arguments: -f\n"
     ]
    },
    {
     "ename": "SystemExit",
     "evalue": "2",
     "output_type": "error",
     "traceback": [
      "An exception has occurred, use %tb to see the full traceback.\n",
      "\u001b[0;31mSystemExit\u001b[0m\u001b[0;31m:\u001b[0m 2\n"
     ]
    }
   ],
   "source": [
    "# test connection \n",
    "# connect to connection pool\n",
    "with pool.connect() as db_conn:\n",
    "    # create ratings table in our sandwiches database\n",
    "    results = db_conn.execute(sqlalchemy.text(\"SELECT * FROM semantic\")).fetchall()\n",
    "    \n",
    "    # show results\n",
    "    for row in results:\n",
    "        print(row)"
   ]
  },
  {
   "cell_type": "code",
   "execution_count": 55,
   "metadata": {
    "scrolled": true
   },
   "outputs": [
    {
     "ename": "ClientResponseError",
     "evalue": "404, message='Not Found', url=URL('https://sqladmin.googleapis.com/sql/v1beta4/projects/w210-capstone-ta/instances/w210-therapeutic-accelerator/connectSettings')",
     "output_type": "error",
     "traceback": [
      "\u001b[0;31m---------------------------------------------------------------------------\u001b[0m",
      "\u001b[0;31mClientResponseError\u001b[0m                       Traceback (most recent call last)",
      "Cell \u001b[0;32mIn[55], line 2\u001b[0m\n\u001b[1;32m      1\u001b[0m \u001b[38;5;66;03m# connect to connection pool\u001b[39;00m\n\u001b[0;32m----> 2\u001b[0m \u001b[38;5;28;01mwith\u001b[39;00m \u001b[43mpool\u001b[49m\u001b[38;5;241;43m.\u001b[39;49m\u001b[43mconnect\u001b[49m\u001b[43m(\u001b[49m\u001b[43m)\u001b[49m \u001b[38;5;28;01mas\u001b[39;00m db_conn:\n\u001b[1;32m      3\u001b[0m   \u001b[38;5;66;03m# create ratings table in our sandwiches database\u001b[39;00m\n\u001b[1;32m      4\u001b[0m   db_conn\u001b[38;5;241m.\u001b[39mexecute(\n\u001b[1;32m      5\u001b[0m     sqlalchemy\u001b[38;5;241m.\u001b[39mtext(\n\u001b[1;32m      6\u001b[0m       \u001b[38;5;124m\"\u001b[39m\u001b[38;5;124mCREATE TABLE IF NOT EXISTS semantic \u001b[39m\u001b[38;5;124m\"\u001b[39m\n\u001b[0;32m   (...)\u001b[0m\n\u001b[1;32m     14\u001b[0m     )\n\u001b[1;32m     15\u001b[0m   )\n\u001b[1;32m     17\u001b[0m   \u001b[38;5;66;03m# commit transaction (SQLAlchemy v2.X.X is commit as you go)\u001b[39;00m\n",
      "File \u001b[0;32m~/anaconda3/lib/python3.10/site-packages/sqlalchemy/engine/base.py:3234\u001b[0m, in \u001b[0;36mEngine.connect\u001b[0;34m(self, close_with_result)\u001b[0m\n\u001b[1;32m   3219\u001b[0m \u001b[38;5;28;01mdef\u001b[39;00m \u001b[38;5;21mconnect\u001b[39m(\u001b[38;5;28mself\u001b[39m, close_with_result\u001b[38;5;241m=\u001b[39m\u001b[38;5;28;01mFalse\u001b[39;00m):\n\u001b[1;32m   3220\u001b[0m \u001b[38;5;250m    \u001b[39m\u001b[38;5;124;03m\"\"\"Return a new :class:`_engine.Connection` object.\u001b[39;00m\n\u001b[1;32m   3221\u001b[0m \n\u001b[1;32m   3222\u001b[0m \u001b[38;5;124;03m    The :class:`_engine.Connection` object is a facade that uses a DBAPI\u001b[39;00m\n\u001b[0;32m   (...)\u001b[0m\n\u001b[1;32m   3231\u001b[0m \n\u001b[1;32m   3232\u001b[0m \u001b[38;5;124;03m    \"\"\"\u001b[39;00m\n\u001b[0;32m-> 3234\u001b[0m     \u001b[38;5;28;01mreturn\u001b[39;00m \u001b[38;5;28;43mself\u001b[39;49m\u001b[38;5;241;43m.\u001b[39;49m\u001b[43m_connection_cls\u001b[49m\u001b[43m(\u001b[49m\u001b[38;5;28;43mself\u001b[39;49m\u001b[43m,\u001b[49m\u001b[43m \u001b[49m\u001b[43mclose_with_result\u001b[49m\u001b[38;5;241;43m=\u001b[39;49m\u001b[43mclose_with_result\u001b[49m\u001b[43m)\u001b[49m\n",
      "File \u001b[0;32m~/anaconda3/lib/python3.10/site-packages/sqlalchemy/engine/base.py:96\u001b[0m, in \u001b[0;36mConnection.__init__\u001b[0;34m(self, engine, connection, close_with_result, _branch_from, _execution_options, _dispatch, _has_events, _allow_revalidate)\u001b[0m\n\u001b[1;32m     91\u001b[0m     \u001b[38;5;28mself\u001b[39m\u001b[38;5;241m.\u001b[39m_has_events \u001b[38;5;241m=\u001b[39m _branch_from\u001b[38;5;241m.\u001b[39m_has_events\n\u001b[1;32m     92\u001b[0m \u001b[38;5;28;01melse\u001b[39;00m:\n\u001b[1;32m     93\u001b[0m     \u001b[38;5;28mself\u001b[39m\u001b[38;5;241m.\u001b[39m_dbapi_connection \u001b[38;5;241m=\u001b[39m (\n\u001b[1;32m     94\u001b[0m         connection\n\u001b[1;32m     95\u001b[0m         \u001b[38;5;28;01mif\u001b[39;00m connection \u001b[38;5;129;01mis\u001b[39;00m \u001b[38;5;129;01mnot\u001b[39;00m \u001b[38;5;28;01mNone\u001b[39;00m\n\u001b[0;32m---> 96\u001b[0m         \u001b[38;5;28;01melse\u001b[39;00m \u001b[43mengine\u001b[49m\u001b[38;5;241;43m.\u001b[39;49m\u001b[43mraw_connection\u001b[49m\u001b[43m(\u001b[49m\u001b[43m)\u001b[49m\n\u001b[1;32m     97\u001b[0m     )\n\u001b[1;32m     99\u001b[0m     \u001b[38;5;28mself\u001b[39m\u001b[38;5;241m.\u001b[39m_transaction \u001b[38;5;241m=\u001b[39m \u001b[38;5;28mself\u001b[39m\u001b[38;5;241m.\u001b[39m_nested_transaction \u001b[38;5;241m=\u001b[39m \u001b[38;5;28;01mNone\u001b[39;00m\n\u001b[1;32m    100\u001b[0m     \u001b[38;5;28mself\u001b[39m\u001b[38;5;241m.\u001b[39m__savepoint_seq \u001b[38;5;241m=\u001b[39m \u001b[38;5;241m0\u001b[39m\n",
      "File \u001b[0;32m~/anaconda3/lib/python3.10/site-packages/sqlalchemy/engine/base.py:3313\u001b[0m, in \u001b[0;36mEngine.raw_connection\u001b[0;34m(self, _connection)\u001b[0m\n\u001b[1;32m   3291\u001b[0m \u001b[38;5;28;01mdef\u001b[39;00m \u001b[38;5;21mraw_connection\u001b[39m(\u001b[38;5;28mself\u001b[39m, _connection\u001b[38;5;241m=\u001b[39m\u001b[38;5;28;01mNone\u001b[39;00m):\n\u001b[1;32m   3292\u001b[0m \u001b[38;5;250m    \u001b[39m\u001b[38;5;124;03m\"\"\"Return a \"raw\" DBAPI connection from the connection pool.\u001b[39;00m\n\u001b[1;32m   3293\u001b[0m \n\u001b[1;32m   3294\u001b[0m \u001b[38;5;124;03m    The returned object is a proxied version of the DBAPI\u001b[39;00m\n\u001b[0;32m   (...)\u001b[0m\n\u001b[1;32m   3311\u001b[0m \n\u001b[1;32m   3312\u001b[0m \u001b[38;5;124;03m    \"\"\"\u001b[39;00m\n\u001b[0;32m-> 3313\u001b[0m     \u001b[38;5;28;01mreturn\u001b[39;00m \u001b[38;5;28;43mself\u001b[39;49m\u001b[38;5;241;43m.\u001b[39;49m\u001b[43m_wrap_pool_connect\u001b[49m\u001b[43m(\u001b[49m\u001b[38;5;28;43mself\u001b[39;49m\u001b[38;5;241;43m.\u001b[39;49m\u001b[43mpool\u001b[49m\u001b[38;5;241;43m.\u001b[39;49m\u001b[43mconnect\u001b[49m\u001b[43m,\u001b[49m\u001b[43m \u001b[49m\u001b[43m_connection\u001b[49m\u001b[43m)\u001b[49m\n",
      "File \u001b[0;32m~/anaconda3/lib/python3.10/site-packages/sqlalchemy/engine/base.py:3280\u001b[0m, in \u001b[0;36mEngine._wrap_pool_connect\u001b[0;34m(self, fn, connection)\u001b[0m\n\u001b[1;32m   3278\u001b[0m dialect \u001b[38;5;241m=\u001b[39m \u001b[38;5;28mself\u001b[39m\u001b[38;5;241m.\u001b[39mdialect\n\u001b[1;32m   3279\u001b[0m \u001b[38;5;28;01mtry\u001b[39;00m:\n\u001b[0;32m-> 3280\u001b[0m     \u001b[38;5;28;01mreturn\u001b[39;00m \u001b[43mfn\u001b[49m\u001b[43m(\u001b[49m\u001b[43m)\u001b[49m\n\u001b[1;32m   3281\u001b[0m \u001b[38;5;28;01mexcept\u001b[39;00m dialect\u001b[38;5;241m.\u001b[39mdbapi\u001b[38;5;241m.\u001b[39mError \u001b[38;5;28;01mas\u001b[39;00m e:\n\u001b[1;32m   3282\u001b[0m     \u001b[38;5;28;01mif\u001b[39;00m connection \u001b[38;5;129;01mis\u001b[39;00m \u001b[38;5;28;01mNone\u001b[39;00m:\n",
      "File \u001b[0;32m~/anaconda3/lib/python3.10/site-packages/sqlalchemy/pool/base.py:310\u001b[0m, in \u001b[0;36mPool.connect\u001b[0;34m(self)\u001b[0m\n\u001b[1;32m    302\u001b[0m \u001b[38;5;28;01mdef\u001b[39;00m \u001b[38;5;21mconnect\u001b[39m(\u001b[38;5;28mself\u001b[39m):\n\u001b[1;32m    303\u001b[0m \u001b[38;5;250m    \u001b[39m\u001b[38;5;124;03m\"\"\"Return a DBAPI connection from the pool.\u001b[39;00m\n\u001b[1;32m    304\u001b[0m \n\u001b[1;32m    305\u001b[0m \u001b[38;5;124;03m    The connection is instrumented such that when its\u001b[39;00m\n\u001b[0;32m   (...)\u001b[0m\n\u001b[1;32m    308\u001b[0m \n\u001b[1;32m    309\u001b[0m \u001b[38;5;124;03m    \"\"\"\u001b[39;00m\n\u001b[0;32m--> 310\u001b[0m     \u001b[38;5;28;01mreturn\u001b[39;00m \u001b[43m_ConnectionFairy\u001b[49m\u001b[38;5;241;43m.\u001b[39;49m\u001b[43m_checkout\u001b[49m\u001b[43m(\u001b[49m\u001b[38;5;28;43mself\u001b[39;49m\u001b[43m)\u001b[49m\n",
      "File \u001b[0;32m~/anaconda3/lib/python3.10/site-packages/sqlalchemy/pool/base.py:868\u001b[0m, in \u001b[0;36m_ConnectionFairy._checkout\u001b[0;34m(cls, pool, threadconns, fairy)\u001b[0m\n\u001b[1;32m    865\u001b[0m \u001b[38;5;129m@classmethod\u001b[39m\n\u001b[1;32m    866\u001b[0m \u001b[38;5;28;01mdef\u001b[39;00m \u001b[38;5;21m_checkout\u001b[39m(\u001b[38;5;28mcls\u001b[39m, pool, threadconns\u001b[38;5;241m=\u001b[39m\u001b[38;5;28;01mNone\u001b[39;00m, fairy\u001b[38;5;241m=\u001b[39m\u001b[38;5;28;01mNone\u001b[39;00m):\n\u001b[1;32m    867\u001b[0m     \u001b[38;5;28;01mif\u001b[39;00m \u001b[38;5;129;01mnot\u001b[39;00m fairy:\n\u001b[0;32m--> 868\u001b[0m         fairy \u001b[38;5;241m=\u001b[39m \u001b[43m_ConnectionRecord\u001b[49m\u001b[38;5;241;43m.\u001b[39;49m\u001b[43mcheckout\u001b[49m\u001b[43m(\u001b[49m\u001b[43mpool\u001b[49m\u001b[43m)\u001b[49m\n\u001b[1;32m    870\u001b[0m         fairy\u001b[38;5;241m.\u001b[39m_pool \u001b[38;5;241m=\u001b[39m pool\n\u001b[1;32m    871\u001b[0m         fairy\u001b[38;5;241m.\u001b[39m_counter \u001b[38;5;241m=\u001b[39m \u001b[38;5;241m0\u001b[39m\n",
      "File \u001b[0;32m~/anaconda3/lib/python3.10/site-packages/sqlalchemy/pool/base.py:476\u001b[0m, in \u001b[0;36m_ConnectionRecord.checkout\u001b[0;34m(cls, pool)\u001b[0m\n\u001b[1;32m    474\u001b[0m \u001b[38;5;129m@classmethod\u001b[39m\n\u001b[1;32m    475\u001b[0m \u001b[38;5;28;01mdef\u001b[39;00m \u001b[38;5;21mcheckout\u001b[39m(\u001b[38;5;28mcls\u001b[39m, pool):\n\u001b[0;32m--> 476\u001b[0m     rec \u001b[38;5;241m=\u001b[39m \u001b[43mpool\u001b[49m\u001b[38;5;241;43m.\u001b[39;49m\u001b[43m_do_get\u001b[49m\u001b[43m(\u001b[49m\u001b[43m)\u001b[49m\n\u001b[1;32m    477\u001b[0m     \u001b[38;5;28;01mtry\u001b[39;00m:\n\u001b[1;32m    478\u001b[0m         dbapi_connection \u001b[38;5;241m=\u001b[39m rec\u001b[38;5;241m.\u001b[39mget_connection()\n",
      "File \u001b[0;32m~/anaconda3/lib/python3.10/site-packages/sqlalchemy/pool/impl.py:145\u001b[0m, in \u001b[0;36mQueuePool._do_get\u001b[0;34m(self)\u001b[0m\n\u001b[1;32m    143\u001b[0m         \u001b[38;5;28;01mreturn\u001b[39;00m \u001b[38;5;28mself\u001b[39m\u001b[38;5;241m.\u001b[39m_create_connection()\n\u001b[1;32m    144\u001b[0m     \u001b[38;5;28;01mexcept\u001b[39;00m:\n\u001b[0;32m--> 145\u001b[0m         \u001b[38;5;28;01mwith\u001b[39;00m util\u001b[38;5;241m.\u001b[39msafe_reraise():\n\u001b[1;32m    146\u001b[0m             \u001b[38;5;28mself\u001b[39m\u001b[38;5;241m.\u001b[39m_dec_overflow()\n\u001b[1;32m    147\u001b[0m \u001b[38;5;28;01melse\u001b[39;00m:\n",
      "File \u001b[0;32m~/anaconda3/lib/python3.10/site-packages/sqlalchemy/util/langhelpers.py:70\u001b[0m, in \u001b[0;36msafe_reraise.__exit__\u001b[0;34m(self, type_, value, traceback)\u001b[0m\n\u001b[1;32m     68\u001b[0m     \u001b[38;5;28mself\u001b[39m\u001b[38;5;241m.\u001b[39m_exc_info \u001b[38;5;241m=\u001b[39m \u001b[38;5;28;01mNone\u001b[39;00m  \u001b[38;5;66;03m# remove potential circular references\u001b[39;00m\n\u001b[1;32m     69\u001b[0m     \u001b[38;5;28;01mif\u001b[39;00m \u001b[38;5;129;01mnot\u001b[39;00m \u001b[38;5;28mself\u001b[39m\u001b[38;5;241m.\u001b[39mwarn_only:\n\u001b[0;32m---> 70\u001b[0m         \u001b[43mcompat\u001b[49m\u001b[38;5;241;43m.\u001b[39;49m\u001b[43mraise_\u001b[49m\u001b[43m(\u001b[49m\n\u001b[1;32m     71\u001b[0m \u001b[43m            \u001b[49m\u001b[43mexc_value\u001b[49m\u001b[43m,\u001b[49m\n\u001b[1;32m     72\u001b[0m \u001b[43m            \u001b[49m\u001b[43mwith_traceback\u001b[49m\u001b[38;5;241;43m=\u001b[39;49m\u001b[43mexc_tb\u001b[49m\u001b[43m,\u001b[49m\n\u001b[1;32m     73\u001b[0m \u001b[43m        \u001b[49m\u001b[43m)\u001b[49m\n\u001b[1;32m     74\u001b[0m \u001b[38;5;28;01melse\u001b[39;00m:\n\u001b[1;32m     75\u001b[0m     \u001b[38;5;28;01mif\u001b[39;00m \u001b[38;5;129;01mnot\u001b[39;00m compat\u001b[38;5;241m.\u001b[39mpy3k \u001b[38;5;129;01mand\u001b[39;00m \u001b[38;5;28mself\u001b[39m\u001b[38;5;241m.\u001b[39m_exc_info \u001b[38;5;129;01mand\u001b[39;00m \u001b[38;5;28mself\u001b[39m\u001b[38;5;241m.\u001b[39m_exc_info[\u001b[38;5;241m1\u001b[39m]:\n\u001b[1;32m     76\u001b[0m         \u001b[38;5;66;03m# emulate Py3K's behavior of telling us when an exception\u001b[39;00m\n\u001b[1;32m     77\u001b[0m         \u001b[38;5;66;03m# occurs in an exception handler.\u001b[39;00m\n",
      "File \u001b[0;32m~/anaconda3/lib/python3.10/site-packages/sqlalchemy/util/compat.py:208\u001b[0m, in \u001b[0;36mraise_\u001b[0;34m(***failed resolving arguments***)\u001b[0m\n\u001b[1;32m    205\u001b[0m     exception\u001b[38;5;241m.\u001b[39m__cause__ \u001b[38;5;241m=\u001b[39m replace_context\n\u001b[1;32m    207\u001b[0m \u001b[38;5;28;01mtry\u001b[39;00m:\n\u001b[0;32m--> 208\u001b[0m     \u001b[38;5;28;01mraise\u001b[39;00m exception\n\u001b[1;32m    209\u001b[0m \u001b[38;5;28;01mfinally\u001b[39;00m:\n\u001b[1;32m    210\u001b[0m     \u001b[38;5;66;03m# credit to\u001b[39;00m\n\u001b[1;32m    211\u001b[0m     \u001b[38;5;66;03m# https://cosmicpercolator.com/2016/01/13/exception-leaks-in-python-2-and-3/\u001b[39;00m\n\u001b[1;32m    212\u001b[0m     \u001b[38;5;66;03m# as the __traceback__ object creates a cycle\u001b[39;00m\n\u001b[1;32m    213\u001b[0m     \u001b[38;5;28;01mdel\u001b[39;00m exception, replace_context, from_, with_traceback\n",
      "File \u001b[0;32m~/anaconda3/lib/python3.10/site-packages/sqlalchemy/pool/impl.py:143\u001b[0m, in \u001b[0;36mQueuePool._do_get\u001b[0;34m(self)\u001b[0m\n\u001b[1;32m    141\u001b[0m \u001b[38;5;28;01mif\u001b[39;00m \u001b[38;5;28mself\u001b[39m\u001b[38;5;241m.\u001b[39m_inc_overflow():\n\u001b[1;32m    142\u001b[0m     \u001b[38;5;28;01mtry\u001b[39;00m:\n\u001b[0;32m--> 143\u001b[0m         \u001b[38;5;28;01mreturn\u001b[39;00m \u001b[38;5;28;43mself\u001b[39;49m\u001b[38;5;241;43m.\u001b[39;49m\u001b[43m_create_connection\u001b[49m\u001b[43m(\u001b[49m\u001b[43m)\u001b[49m\n\u001b[1;32m    144\u001b[0m     \u001b[38;5;28;01mexcept\u001b[39;00m:\n\u001b[1;32m    145\u001b[0m         \u001b[38;5;28;01mwith\u001b[39;00m util\u001b[38;5;241m.\u001b[39msafe_reraise():\n",
      "File \u001b[0;32m~/anaconda3/lib/python3.10/site-packages/sqlalchemy/pool/base.py:256\u001b[0m, in \u001b[0;36mPool._create_connection\u001b[0;34m(self)\u001b[0m\n\u001b[1;32m    253\u001b[0m \u001b[38;5;28;01mdef\u001b[39;00m \u001b[38;5;21m_create_connection\u001b[39m(\u001b[38;5;28mself\u001b[39m):\n\u001b[1;32m    254\u001b[0m \u001b[38;5;250m    \u001b[39m\u001b[38;5;124;03m\"\"\"Called by subclasses to create a new ConnectionRecord.\"\"\"\u001b[39;00m\n\u001b[0;32m--> 256\u001b[0m     \u001b[38;5;28;01mreturn\u001b[39;00m \u001b[43m_ConnectionRecord\u001b[49m\u001b[43m(\u001b[49m\u001b[38;5;28;43mself\u001b[39;49m\u001b[43m)\u001b[49m\n",
      "File \u001b[0;32m~/anaconda3/lib/python3.10/site-packages/sqlalchemy/pool/base.py:371\u001b[0m, in \u001b[0;36m_ConnectionRecord.__init__\u001b[0;34m(self, pool, connect)\u001b[0m\n\u001b[1;32m    369\u001b[0m \u001b[38;5;28mself\u001b[39m\u001b[38;5;241m.\u001b[39m__pool \u001b[38;5;241m=\u001b[39m pool\n\u001b[1;32m    370\u001b[0m \u001b[38;5;28;01mif\u001b[39;00m connect:\n\u001b[0;32m--> 371\u001b[0m     \u001b[38;5;28;43mself\u001b[39;49m\u001b[38;5;241;43m.\u001b[39;49m\u001b[43m__connect\u001b[49m\u001b[43m(\u001b[49m\u001b[43m)\u001b[49m\n\u001b[1;32m    372\u001b[0m \u001b[38;5;28mself\u001b[39m\u001b[38;5;241m.\u001b[39mfinalize_callback \u001b[38;5;241m=\u001b[39m deque()\n",
      "File \u001b[0;32m~/anaconda3/lib/python3.10/site-packages/sqlalchemy/pool/base.py:665\u001b[0m, in \u001b[0;36m_ConnectionRecord.__connect\u001b[0;34m(self)\u001b[0m\n\u001b[1;32m    663\u001b[0m     \u001b[38;5;28mself\u001b[39m\u001b[38;5;241m.\u001b[39mfresh \u001b[38;5;241m=\u001b[39m \u001b[38;5;28;01mTrue\u001b[39;00m\n\u001b[1;32m    664\u001b[0m \u001b[38;5;28;01mexcept\u001b[39;00m \u001b[38;5;167;01mException\u001b[39;00m \u001b[38;5;28;01mas\u001b[39;00m e:\n\u001b[0;32m--> 665\u001b[0m     \u001b[38;5;28;01mwith\u001b[39;00m util\u001b[38;5;241m.\u001b[39msafe_reraise():\n\u001b[1;32m    666\u001b[0m         pool\u001b[38;5;241m.\u001b[39mlogger\u001b[38;5;241m.\u001b[39mdebug(\u001b[38;5;124m\"\u001b[39m\u001b[38;5;124mError on connect(): \u001b[39m\u001b[38;5;132;01m%s\u001b[39;00m\u001b[38;5;124m\"\u001b[39m, e)\n\u001b[1;32m    667\u001b[0m \u001b[38;5;28;01melse\u001b[39;00m:\n\u001b[1;32m    668\u001b[0m     \u001b[38;5;66;03m# in SQLAlchemy 1.4 the first_connect event is not used by\u001b[39;00m\n\u001b[1;32m    669\u001b[0m     \u001b[38;5;66;03m# the engine, so this will usually not be set\u001b[39;00m\n",
      "File \u001b[0;32m~/anaconda3/lib/python3.10/site-packages/sqlalchemy/util/langhelpers.py:70\u001b[0m, in \u001b[0;36msafe_reraise.__exit__\u001b[0;34m(self, type_, value, traceback)\u001b[0m\n\u001b[1;32m     68\u001b[0m     \u001b[38;5;28mself\u001b[39m\u001b[38;5;241m.\u001b[39m_exc_info \u001b[38;5;241m=\u001b[39m \u001b[38;5;28;01mNone\u001b[39;00m  \u001b[38;5;66;03m# remove potential circular references\u001b[39;00m\n\u001b[1;32m     69\u001b[0m     \u001b[38;5;28;01mif\u001b[39;00m \u001b[38;5;129;01mnot\u001b[39;00m \u001b[38;5;28mself\u001b[39m\u001b[38;5;241m.\u001b[39mwarn_only:\n\u001b[0;32m---> 70\u001b[0m         \u001b[43mcompat\u001b[49m\u001b[38;5;241;43m.\u001b[39;49m\u001b[43mraise_\u001b[49m\u001b[43m(\u001b[49m\n\u001b[1;32m     71\u001b[0m \u001b[43m            \u001b[49m\u001b[43mexc_value\u001b[49m\u001b[43m,\u001b[49m\n\u001b[1;32m     72\u001b[0m \u001b[43m            \u001b[49m\u001b[43mwith_traceback\u001b[49m\u001b[38;5;241;43m=\u001b[39;49m\u001b[43mexc_tb\u001b[49m\u001b[43m,\u001b[49m\n\u001b[1;32m     73\u001b[0m \u001b[43m        \u001b[49m\u001b[43m)\u001b[49m\n\u001b[1;32m     74\u001b[0m \u001b[38;5;28;01melse\u001b[39;00m:\n\u001b[1;32m     75\u001b[0m     \u001b[38;5;28;01mif\u001b[39;00m \u001b[38;5;129;01mnot\u001b[39;00m compat\u001b[38;5;241m.\u001b[39mpy3k \u001b[38;5;129;01mand\u001b[39;00m \u001b[38;5;28mself\u001b[39m\u001b[38;5;241m.\u001b[39m_exc_info \u001b[38;5;129;01mand\u001b[39;00m \u001b[38;5;28mself\u001b[39m\u001b[38;5;241m.\u001b[39m_exc_info[\u001b[38;5;241m1\u001b[39m]:\n\u001b[1;32m     76\u001b[0m         \u001b[38;5;66;03m# emulate Py3K's behavior of telling us when an exception\u001b[39;00m\n\u001b[1;32m     77\u001b[0m         \u001b[38;5;66;03m# occurs in an exception handler.\u001b[39;00m\n",
      "File \u001b[0;32m~/anaconda3/lib/python3.10/site-packages/sqlalchemy/util/compat.py:208\u001b[0m, in \u001b[0;36mraise_\u001b[0;34m(***failed resolving arguments***)\u001b[0m\n\u001b[1;32m    205\u001b[0m     exception\u001b[38;5;241m.\u001b[39m__cause__ \u001b[38;5;241m=\u001b[39m replace_context\n\u001b[1;32m    207\u001b[0m \u001b[38;5;28;01mtry\u001b[39;00m:\n\u001b[0;32m--> 208\u001b[0m     \u001b[38;5;28;01mraise\u001b[39;00m exception\n\u001b[1;32m    209\u001b[0m \u001b[38;5;28;01mfinally\u001b[39;00m:\n\u001b[1;32m    210\u001b[0m     \u001b[38;5;66;03m# credit to\u001b[39;00m\n\u001b[1;32m    211\u001b[0m     \u001b[38;5;66;03m# https://cosmicpercolator.com/2016/01/13/exception-leaks-in-python-2-and-3/\u001b[39;00m\n\u001b[1;32m    212\u001b[0m     \u001b[38;5;66;03m# as the __traceback__ object creates a cycle\u001b[39;00m\n\u001b[1;32m    213\u001b[0m     \u001b[38;5;28;01mdel\u001b[39;00m exception, replace_context, from_, with_traceback\n",
      "File \u001b[0;32m~/anaconda3/lib/python3.10/site-packages/sqlalchemy/pool/base.py:661\u001b[0m, in \u001b[0;36m_ConnectionRecord.__connect\u001b[0;34m(self)\u001b[0m\n\u001b[1;32m    659\u001b[0m \u001b[38;5;28;01mtry\u001b[39;00m:\n\u001b[1;32m    660\u001b[0m     \u001b[38;5;28mself\u001b[39m\u001b[38;5;241m.\u001b[39mstarttime \u001b[38;5;241m=\u001b[39m time\u001b[38;5;241m.\u001b[39mtime()\n\u001b[0;32m--> 661\u001b[0m     \u001b[38;5;28mself\u001b[39m\u001b[38;5;241m.\u001b[39mdbapi_connection \u001b[38;5;241m=\u001b[39m connection \u001b[38;5;241m=\u001b[39m \u001b[43mpool\u001b[49m\u001b[38;5;241;43m.\u001b[39;49m\u001b[43m_invoke_creator\u001b[49m\u001b[43m(\u001b[49m\u001b[38;5;28;43mself\u001b[39;49m\u001b[43m)\u001b[49m\n\u001b[1;32m    662\u001b[0m     pool\u001b[38;5;241m.\u001b[39mlogger\u001b[38;5;241m.\u001b[39mdebug(\u001b[38;5;124m\"\u001b[39m\u001b[38;5;124mCreated new connection \u001b[39m\u001b[38;5;132;01m%r\u001b[39;00m\u001b[38;5;124m\"\u001b[39m, connection)\n\u001b[1;32m    663\u001b[0m     \u001b[38;5;28mself\u001b[39m\u001b[38;5;241m.\u001b[39mfresh \u001b[38;5;241m=\u001b[39m \u001b[38;5;28;01mTrue\u001b[39;00m\n",
      "File \u001b[0;32m~/anaconda3/lib/python3.10/site-packages/sqlalchemy/pool/base.py:241\u001b[0m, in \u001b[0;36mPool._should_wrap_creator.<locals>.<lambda>\u001b[0;34m(crec)\u001b[0m\n\u001b[1;32m    237\u001b[0m     \u001b[38;5;28;01mreturn\u001b[39;00m creator\n\u001b[1;32m    238\u001b[0m \u001b[38;5;66;03m# all other cases, just wrap and assume legacy \"creator\" callable\u001b[39;00m\n\u001b[1;32m    239\u001b[0m \u001b[38;5;66;03m# thing\u001b[39;00m\n\u001b[1;32m    240\u001b[0m \u001b[38;5;28;01melse\u001b[39;00m:\n\u001b[0;32m--> 241\u001b[0m     \u001b[38;5;28;01mreturn\u001b[39;00m \u001b[38;5;28;01mlambda\u001b[39;00m crec: \u001b[43mcreator\u001b[49m\u001b[43m(\u001b[49m\u001b[43m)\u001b[49m\n",
      "Cell \u001b[0;32mIn[47], line 13\u001b[0m, in \u001b[0;36mgetconn\u001b[0;34m()\u001b[0m\n\u001b[1;32m     10\u001b[0m DB_PASS \u001b[38;5;241m=\u001b[39m config[\u001b[38;5;124m'\u001b[39m\u001b[38;5;124mdatabase\u001b[39m\u001b[38;5;124m'\u001b[39m][\u001b[38;5;124m'\u001b[39m\u001b[38;5;124mpassword\u001b[39m\u001b[38;5;124m'\u001b[39m]\n\u001b[1;32m     11\u001b[0m DB_NAME \u001b[38;5;241m=\u001b[39m config[\u001b[38;5;124m'\u001b[39m\u001b[38;5;124mdatabase\u001b[39m\u001b[38;5;124m'\u001b[39m][\u001b[38;5;124m'\u001b[39m\u001b[38;5;124mname\u001b[39m\u001b[38;5;124m'\u001b[39m]\n\u001b[0;32m---> 13\u001b[0m conn \u001b[38;5;241m=\u001b[39m \u001b[43mconnector\u001b[49m\u001b[38;5;241;43m.\u001b[39;49m\u001b[43mconnect\u001b[49m\u001b[43m(\u001b[49m\n\u001b[1;32m     14\u001b[0m \u001b[43m    \u001b[49m\u001b[43mINSTANCE_CONNECTION_NAME\u001b[49m\u001b[43m,\u001b[49m\n\u001b[1;32m     15\u001b[0m \u001b[43m    \u001b[49m\u001b[38;5;124;43m\"\u001b[39;49m\u001b[38;5;124;43mpg8000\u001b[39;49m\u001b[38;5;124;43m\"\u001b[39;49m\u001b[43m,\u001b[49m\n\u001b[1;32m     16\u001b[0m \u001b[43m    \u001b[49m\u001b[43muser\u001b[49m\u001b[38;5;241;43m=\u001b[39;49m\u001b[43mDB_USER\u001b[49m\u001b[43m,\u001b[49m\n\u001b[1;32m     17\u001b[0m \u001b[43m    \u001b[49m\u001b[43mpassword\u001b[49m\u001b[38;5;241;43m=\u001b[39;49m\u001b[43mDB_PASS\u001b[49m\u001b[43m,\u001b[49m\n\u001b[1;32m     18\u001b[0m \u001b[43m    \u001b[49m\u001b[43mdb\u001b[49m\u001b[38;5;241;43m=\u001b[39;49m\u001b[43mDB_NAME\u001b[49m\n\u001b[1;32m     19\u001b[0m \u001b[43m\u001b[49m\u001b[43m)\u001b[49m\n\u001b[1;32m     20\u001b[0m \u001b[38;5;28;01mreturn\u001b[39;00m conn\n",
      "File \u001b[0;32m~/anaconda3/lib/python3.10/site-packages/google/cloud/sql/connector/connector.py:154\u001b[0m, in \u001b[0;36mConnector.connect\u001b[0;34m(self, instance_connection_string, driver, **kwargs)\u001b[0m\n\u001b[1;32m    150\u001b[0m \u001b[38;5;66;03m# if event loop is not in current thread, proceed with connection\u001b[39;00m\n\u001b[1;32m    151\u001b[0m connect_task \u001b[38;5;241m=\u001b[39m asyncio\u001b[38;5;241m.\u001b[39mrun_coroutine_threadsafe(\n\u001b[1;32m    152\u001b[0m     \u001b[38;5;28mself\u001b[39m\u001b[38;5;241m.\u001b[39mconnect_async(instance_connection_string, driver, \u001b[38;5;241m*\u001b[39m\u001b[38;5;241m*\u001b[39mkwargs), \u001b[38;5;28mself\u001b[39m\u001b[38;5;241m.\u001b[39m_loop\n\u001b[1;32m    153\u001b[0m )\n\u001b[0;32m--> 154\u001b[0m \u001b[38;5;28;01mreturn\u001b[39;00m \u001b[43mconnect_task\u001b[49m\u001b[38;5;241;43m.\u001b[39;49m\u001b[43mresult\u001b[49m\u001b[43m(\u001b[49m\u001b[43m)\u001b[49m\n",
      "File \u001b[0;32m~/anaconda3/lib/python3.10/concurrent/futures/_base.py:458\u001b[0m, in \u001b[0;36mFuture.result\u001b[0;34m(self, timeout)\u001b[0m\n\u001b[1;32m    456\u001b[0m     \u001b[38;5;28;01mraise\u001b[39;00m CancelledError()\n\u001b[1;32m    457\u001b[0m \u001b[38;5;28;01melif\u001b[39;00m \u001b[38;5;28mself\u001b[39m\u001b[38;5;241m.\u001b[39m_state \u001b[38;5;241m==\u001b[39m FINISHED:\n\u001b[0;32m--> 458\u001b[0m     \u001b[38;5;28;01mreturn\u001b[39;00m \u001b[38;5;28;43mself\u001b[39;49m\u001b[38;5;241;43m.\u001b[39;49m\u001b[43m__get_result\u001b[49m\u001b[43m(\u001b[49m\u001b[43m)\u001b[49m\n\u001b[1;32m    459\u001b[0m \u001b[38;5;28;01melse\u001b[39;00m:\n\u001b[1;32m    460\u001b[0m     \u001b[38;5;28;01mraise\u001b[39;00m \u001b[38;5;167;01mTimeoutError\u001b[39;00m()\n",
      "File \u001b[0;32m~/anaconda3/lib/python3.10/concurrent/futures/_base.py:403\u001b[0m, in \u001b[0;36mFuture.__get_result\u001b[0;34m(self)\u001b[0m\n\u001b[1;32m    401\u001b[0m \u001b[38;5;28;01mif\u001b[39;00m \u001b[38;5;28mself\u001b[39m\u001b[38;5;241m.\u001b[39m_exception:\n\u001b[1;32m    402\u001b[0m     \u001b[38;5;28;01mtry\u001b[39;00m:\n\u001b[0;32m--> 403\u001b[0m         \u001b[38;5;28;01mraise\u001b[39;00m \u001b[38;5;28mself\u001b[39m\u001b[38;5;241m.\u001b[39m_exception\n\u001b[1;32m    404\u001b[0m     \u001b[38;5;28;01mfinally\u001b[39;00m:\n\u001b[1;32m    405\u001b[0m         \u001b[38;5;66;03m# Break a reference cycle with the exception in self._exception\u001b[39;00m\n\u001b[1;32m    406\u001b[0m         \u001b[38;5;28mself\u001b[39m \u001b[38;5;241m=\u001b[39m \u001b[38;5;28;01mNone\u001b[39;00m\n",
      "File \u001b[0;32m~/anaconda3/lib/python3.10/site-packages/google/cloud/sql/connector/connector.py:261\u001b[0m, in \u001b[0;36mConnector.connect_async\u001b[0;34m(self, instance_connection_string, driver, **kwargs)\u001b[0m\n\u001b[1;32m    259\u001b[0m \u001b[38;5;66;03m# attempt to make connection to Cloud SQL instance for given timeout\u001b[39;00m\n\u001b[1;32m    260\u001b[0m \u001b[38;5;28;01mtry\u001b[39;00m:\n\u001b[0;32m--> 261\u001b[0m     \u001b[38;5;28;01mreturn\u001b[39;00m \u001b[38;5;28;01mawait\u001b[39;00m asyncio\u001b[38;5;241m.\u001b[39mwait_for(get_connection(), timeout)\n\u001b[1;32m    262\u001b[0m \u001b[38;5;28;01mexcept\u001b[39;00m asyncio\u001b[38;5;241m.\u001b[39mTimeoutError:\n\u001b[1;32m    263\u001b[0m     \u001b[38;5;28;01mraise\u001b[39;00m \u001b[38;5;167;01mTimeoutError\u001b[39;00m(\u001b[38;5;124mf\u001b[39m\u001b[38;5;124m\"\u001b[39m\u001b[38;5;124mConnection timed out after \u001b[39m\u001b[38;5;132;01m{\u001b[39;00mtimeout\u001b[38;5;132;01m}\u001b[39;00m\u001b[38;5;124ms\u001b[39m\u001b[38;5;124m\"\u001b[39m)\n",
      "File \u001b[0;32m~/anaconda3/lib/python3.10/asyncio/tasks.py:445\u001b[0m, in \u001b[0;36mwait_for\u001b[0;34m(fut, timeout)\u001b[0m\n\u001b[1;32m    442\u001b[0m         \u001b[38;5;28;01mraise\u001b[39;00m\n\u001b[1;32m    444\u001b[0m \u001b[38;5;28;01mif\u001b[39;00m fut\u001b[38;5;241m.\u001b[39mdone():\n\u001b[0;32m--> 445\u001b[0m     \u001b[38;5;28;01mreturn\u001b[39;00m \u001b[43mfut\u001b[49m\u001b[38;5;241;43m.\u001b[39;49m\u001b[43mresult\u001b[49m\u001b[43m(\u001b[49m\u001b[43m)\u001b[49m\n\u001b[1;32m    446\u001b[0m \u001b[38;5;28;01melse\u001b[39;00m:\n\u001b[1;32m    447\u001b[0m     fut\u001b[38;5;241m.\u001b[39mremove_done_callback(cb)\n",
      "File \u001b[0;32m~/anaconda3/lib/python3.10/site-packages/google/cloud/sql/connector/connector.py:237\u001b[0m, in \u001b[0;36mConnector.connect_async.<locals>.get_connection\u001b[0;34m()\u001b[0m\n\u001b[1;32m    236\u001b[0m \u001b[38;5;28;01masync\u001b[39;00m \u001b[38;5;28;01mdef\u001b[39;00m \u001b[38;5;21mget_connection\u001b[39m() \u001b[38;5;241m-\u001b[39m\u001b[38;5;241m>\u001b[39m Any:\n\u001b[0;32m--> 237\u001b[0m     instance_data, ip_address \u001b[38;5;241m=\u001b[39m \u001b[38;5;28;01mawait\u001b[39;00m instance\u001b[38;5;241m.\u001b[39mconnect_info(ip_type)\n\u001b[1;32m    239\u001b[0m     \u001b[38;5;66;03m# format `user` param for automatic IAM database authn\u001b[39;00m\n\u001b[1;32m    240\u001b[0m     \u001b[38;5;28;01mif\u001b[39;00m enable_iam_auth:\n",
      "File \u001b[0;32m~/anaconda3/lib/python3.10/site-packages/google/cloud/sql/connector/instance.py:445\u001b[0m, in \u001b[0;36mInstance.connect_info\u001b[0;34m(self, ip_type)\u001b[0m\n\u001b[1;32m    439\u001b[0m logger\u001b[38;5;241m.\u001b[39mdebug(\n\u001b[1;32m    440\u001b[0m     \u001b[38;5;124mf\u001b[39m\u001b[38;5;124m\"\u001b[39m\u001b[38;5;124m[\u001b[39m\u001b[38;5;124m'\u001b[39m\u001b[38;5;132;01m{\u001b[39;00m\u001b[38;5;28mself\u001b[39m\u001b[38;5;241m.\u001b[39m_instance_connection_string\u001b[38;5;132;01m}\u001b[39;00m\u001b[38;5;124m'\u001b[39m\u001b[38;5;124m]: Entered connect_info method\u001b[39m\u001b[38;5;124m\"\u001b[39m\n\u001b[1;32m    441\u001b[0m )\n\u001b[1;32m    443\u001b[0m instance_data: InstanceMetadata\n\u001b[0;32m--> 445\u001b[0m instance_data \u001b[38;5;241m=\u001b[39m \u001b[38;5;28;01mawait\u001b[39;00m \u001b[38;5;28mself\u001b[39m\u001b[38;5;241m.\u001b[39m_current\n\u001b[1;32m    446\u001b[0m ip_address: \u001b[38;5;28mstr\u001b[39m \u001b[38;5;241m=\u001b[39m instance_data\u001b[38;5;241m.\u001b[39mget_preferred_ip(ip_type)\n\u001b[1;32m    447\u001b[0m \u001b[38;5;28;01mreturn\u001b[39;00m instance_data, ip_address\n",
      "\u001b[0;31mClientResponseError\u001b[0m: 404, message='Not Found', url=URL('https://sqladmin.googleapis.com/sql/v1beta4/projects/w210-capstone-ta/instances/w210-therapeutic-accelerator/connectSettings')"
     ]
    },
    {
     "name": "stderr",
     "output_type": "stream",
     "text": [
      "['w210-capstone-ta:us-central1:w210-therapeutic-accelerator']: An error occurred while performing refresh. Scheduling another refresh attempt immediately\n",
      "Traceback (most recent call last):\n",
      "  File \"/home/nick_lee_berkeley_edu/anaconda3/lib/python3.10/site-packages/google/cloud/sql/connector/instance.py\", line 388, in _refresh_task\n",
      "    refresh_data = await refresh_task\n",
      "  File \"/home/nick_lee_berkeley_edu/anaconda3/lib/python3.10/site-packages/google/cloud/sql/connector/instance.py\", line 312, in _perform_refresh\n",
      "    metadata = await metadata_task\n",
      "  File \"/home/nick_lee_berkeley_edu/anaconda3/lib/python3.10/site-packages/google/cloud/sql/connector/refresh_utils.py\", line 101, in _get_metadata\n",
      "    resp = await client_session.get(url, headers=headers, raise_for_status=True)\n",
      "  File \"/home/nick_lee_berkeley_edu/anaconda3/lib/python3.10/site-packages/aiohttp/client.py\", line 640, in _request\n",
      "    resp.raise_for_status()\n",
      "  File \"/home/nick_lee_berkeley_edu/anaconda3/lib/python3.10/site-packages/aiohttp/client_reqrep.py\", line 1004, in raise_for_status\n",
      "    raise ClientResponseError(\n",
      "aiohttp.client_exceptions.ClientResponseError: 404, message='Not Found', url=URL('https://sqladmin.googleapis.com/sql/v1beta4/projects/w210-capstone-ta/instances/w210-therapeutic-accelerator/connectSettings')\n",
      "Task exception was never retrieved\n",
      "future: <Task finished name='Task-158' coro=<Instance._schedule_refresh.<locals>._refresh_task() done, defined at /home/nick_lee_berkeley_edu/anaconda3/lib/python3.10/site-packages/google/cloud/sql/connector/instance.py:377> exception=ClientResponseError(RequestInfo(url=URL('https://sqladmin.googleapis.com/sql/v1beta4/projects/w210-capstone-ta/instances/w210-therapeutic-accelerator/connectSettings'), method='GET', headers=<CIMultiDictProxy('Host': 'sqladmin.googleapis.com', 'x-goog-api-client': 'cloud-sql-python-connector/1.2.3+pg8000', 'User-Agent': 'cloud-sql-python-connector/1.2.3+pg8000', 'Content-Type': 'application/json', 'Authorization': 'Bearer ya29.c.b0Aaekm1IY-VGbVQF2xAnFKLraacz4aWWINrWwumL0oEKATtsm27z8JAkL6smOHDDuVMEZcnyunbg_ECSPwUBg_x8Q_idoiNN1VENVTxHGMVrB-BHG9Bml0sqQl3Xq9xEnwVY9Jr4dtL8qOn9Aw-aUFXqI2LWxu-91iNrBEfRfF55dwCi6cBzZ6pigHoQuQptIU-ifSHd9P1H7O2o7k856XmTaioHiOJ6MWPf5a_wzdzq8UHfuGnp9a4P1Wcm-_4E-tRLWVDL5gSoeE1aqUAA96xZFUH2AdTTk49W8RnJqO5WhGwk72sfLLE6D5tCFxuxMAf8p2N6G7_rC-CYS1djxCSs7diTa89LF3e8hnLgH368PpbaY7Mzm08eQ-Xgef35d1QOrmcu_zrpxSBeBax3Sy_oc0slsobSlgJ91etzv4qbFJnF5p3oj6RQV9her5dmez1Ohgo2oY6IY4yIxgc01v_l0ls3tx3IFlXu-e_hhkFQcpR4ZyB_qWXVo45Q58sIhwshbnJuRqVBxyRRentplIfiu4YS_t_9y3Mcbdt_Vu-Fs_3UeaBp8fXhieO2uwclM0VYY2vwq7ZSqYXUZBnkd7FOq9x1YZzYtqbr9oORnrQ9ZZ2gOWWnJqkqtJnZ0ghXspRm3rYaWB6lfpeWgl9hhw1oJsu2kiYcIodjy4b22hvtZ7r9UnBq3ez-c9_SlYxrQpqSZs_yiIXqclzuqt6Byy9i73_z0nMruJJ1IBqlOS2ZbqkMVcb_4ean8tgntbkQ0VasxBQpxgSVgMOivokRIhBB9Q5F_ysiF71jRFQzXfcj9lXgOm_Q_V8iwjaVfFb4bqg7qJdSiOV2Wls8gXdOSSnBjOI2tufkex63wFQ4nU38I6FIt0Fgo5qsuOUgFyX4W68B9Zn_Xqeko5d711VBxyeVza0_mwx__dcfSk20jbIfzxRZOl5xzi2Iy1Vpm-9W9rJ2OsqZt2WWJf54Iuviiwr8e_9iBvJzYIcFcq_05ykruqxu0ri6rWOJ', 'Accept': '*/*', 'Accept-Encoding': 'gzip, deflate')>, real_url=URL('https://sqladmin.googleapis.com/sql/v1beta4/projects/w210-capstone-ta/instances/w210-therapeutic-accelerator/connectSettings')), (), status=404, message='Not Found', headers=<CIMultiDictProxy('Vary': 'Origin', 'Vary': 'X-Origin', 'Vary': 'Referer', 'Content-Type': 'application/json; charset=UTF-8', 'Content-Encoding': 'gzip', 'Date': 'Thu, 08 Jun 2023 00:30:12 GMT', 'Server': 'ESF', 'Cache-Control': 'private', 'X-XSS-Protection': '0', 'X-Frame-Options': 'SAMEORIGIN', 'X-Content-Type-Options': 'nosniff', 'Transfer-Encoding': 'chunked')>)>\n",
      "Traceback (most recent call last):\n",
      "  File \"/home/nick_lee_berkeley_edu/anaconda3/lib/python3.10/site-packages/google/cloud/sql/connector/instance.py\", line 388, in _refresh_task\n",
      "    refresh_data = await refresh_task\n",
      "  File \"/home/nick_lee_berkeley_edu/anaconda3/lib/python3.10/site-packages/google/cloud/sql/connector/instance.py\", line 312, in _perform_refresh\n",
      "    metadata = await metadata_task\n",
      "  File \"/home/nick_lee_berkeley_edu/anaconda3/lib/python3.10/site-packages/google/cloud/sql/connector/refresh_utils.py\", line 101, in _get_metadata\n",
      "    resp = await client_session.get(url, headers=headers, raise_for_status=True)\n",
      "  File \"/home/nick_lee_berkeley_edu/anaconda3/lib/python3.10/site-packages/aiohttp/client.py\", line 640, in _request\n",
      "    resp.raise_for_status()\n",
      "  File \"/home/nick_lee_berkeley_edu/anaconda3/lib/python3.10/site-packages/aiohttp/client_reqrep.py\", line 1004, in raise_for_status\n",
      "    raise ClientResponseError(\n",
      "aiohttp.client_exceptions.ClientResponseError: 404, message='Not Found', url=URL('https://sqladmin.googleapis.com/sql/v1beta4/projects/w210-capstone-ta/instances/w210-therapeutic-accelerator/connectSettings')\n",
      "['w210-capstone-ta:us-central1:w210-therapeutic-accelerator']: An error occurred while performing refresh. Scheduling another refresh attempt immediately\n",
      "Traceback (most recent call last):\n",
      "  File \"/home/nick_lee_berkeley_edu/anaconda3/lib/python3.10/site-packages/google/cloud/sql/connector/instance.py\", line 388, in _refresh_task\n",
      "    refresh_data = await refresh_task\n",
      "  File \"/home/nick_lee_berkeley_edu/anaconda3/lib/python3.10/site-packages/google/cloud/sql/connector/instance.py\", line 312, in _perform_refresh\n",
      "    metadata = await metadata_task\n",
      "  File \"/home/nick_lee_berkeley_edu/anaconda3/lib/python3.10/site-packages/google/cloud/sql/connector/refresh_utils.py\", line 101, in _get_metadata\n",
      "    resp = await client_session.get(url, headers=headers, raise_for_status=True)\n",
      "  File \"/home/nick_lee_berkeley_edu/anaconda3/lib/python3.10/site-packages/aiohttp/client.py\", line 640, in _request\n",
      "    resp.raise_for_status()\n",
      "  File \"/home/nick_lee_berkeley_edu/anaconda3/lib/python3.10/site-packages/aiohttp/client_reqrep.py\", line 1004, in raise_for_status\n",
      "    raise ClientResponseError(\n",
      "aiohttp.client_exceptions.ClientResponseError: 404, message='Not Found', url=URL('https://sqladmin.googleapis.com/sql/v1beta4/projects/w210-capstone-ta/instances/w210-therapeutic-accelerator/connectSettings')\n",
      "Task exception was never retrieved\n",
      "future: <Task finished name='Task-169' coro=<Instance._schedule_refresh.<locals>._refresh_task() done, defined at /home/nick_lee_berkeley_edu/anaconda3/lib/python3.10/site-packages/google/cloud/sql/connector/instance.py:377> exception=ClientResponseError(RequestInfo(url=URL('https://sqladmin.googleapis.com/sql/v1beta4/projects/w210-capstone-ta/instances/w210-therapeutic-accelerator/connectSettings'), method='GET', headers=<CIMultiDictProxy('Host': 'sqladmin.googleapis.com', 'x-goog-api-client': 'cloud-sql-python-connector/1.2.3+pg8000', 'User-Agent': 'cloud-sql-python-connector/1.2.3+pg8000', 'Content-Type': 'application/json', 'Authorization': 'Bearer ya29.c.b0Aaekm1IY-VGbVQF2xAnFKLraacz4aWWINrWwumL0oEKATtsm27z8JAkL6smOHDDuVMEZcnyunbg_ECSPwUBg_x8Q_idoiNN1VENVTxHGMVrB-BHG9Bml0sqQl3Xq9xEnwVY9Jr4dtL8qOn9Aw-aUFXqI2LWxu-91iNrBEfRfF55dwCi6cBzZ6pigHoQuQptIU-ifSHd9P1H7O2o7k856XmTaioHiOJ6MWPf5a_wzdzq8UHfuGnp9a4P1Wcm-_4E-tRLWVDL5gSoeE1aqUAA96xZFUH2AdTTk49W8RnJqO5WhGwk72sfLLE6D5tCFxuxMAf8p2N6G7_rC-CYS1djxCSs7diTa89LF3e8hnLgH368PpbaY7Mzm08eQ-Xgef35d1QOrmcu_zrpxSBeBax3Sy_oc0slsobSlgJ91etzv4qbFJnF5p3oj6RQV9her5dmez1Ohgo2oY6IY4yIxgc01v_l0ls3tx3IFlXu-e_hhkFQcpR4ZyB_qWXVo45Q58sIhwshbnJuRqVBxyRRentplIfiu4YS_t_9y3Mcbdt_Vu-Fs_3UeaBp8fXhieO2uwclM0VYY2vwq7ZSqYXUZBnkd7FOq9x1YZzYtqbr9oORnrQ9ZZ2gOWWnJqkqtJnZ0ghXspRm3rYaWB6lfpeWgl9hhw1oJsu2kiYcIodjy4b22hvtZ7r9UnBq3ez-c9_SlYxrQpqSZs_yiIXqclzuqt6Byy9i73_z0nMruJJ1IBqlOS2ZbqkMVcb_4ean8tgntbkQ0VasxBQpxgSVgMOivokRIhBB9Q5F_ysiF71jRFQzXfcj9lXgOm_Q_V8iwjaVfFb4bqg7qJdSiOV2Wls8gXdOSSnBjOI2tufkex63wFQ4nU38I6FIt0Fgo5qsuOUgFyX4W68B9Zn_Xqeko5d711VBxyeVza0_mwx__dcfSk20jbIfzxRZOl5xzi2Iy1Vpm-9W9rJ2OsqZt2WWJf54Iuviiwr8e_9iBvJzYIcFcq_05ykruqxu0ri6rWOJ', 'Accept': '*/*', 'Accept-Encoding': 'gzip, deflate')>, real_url=URL('https://sqladmin.googleapis.com/sql/v1beta4/projects/w210-capstone-ta/instances/w210-therapeutic-accelerator/connectSettings')), (), status=404, message='Not Found', headers=<CIMultiDictProxy('Vary': 'Origin', 'Vary': 'X-Origin', 'Vary': 'Referer', 'Content-Type': 'application/json; charset=UTF-8', 'Content-Encoding': 'gzip', 'Date': 'Thu, 08 Jun 2023 00:30:42 GMT', 'Server': 'ESF', 'Cache-Control': 'private', 'X-XSS-Protection': '0', 'X-Frame-Options': 'SAMEORIGIN', 'X-Content-Type-Options': 'nosniff', 'Transfer-Encoding': 'chunked')>)>\n",
      "Traceback (most recent call last):\n",
      "  File \"/home/nick_lee_berkeley_edu/anaconda3/lib/python3.10/site-packages/google/cloud/sql/connector/instance.py\", line 388, in _refresh_task\n",
      "    refresh_data = await refresh_task\n",
      "  File \"/home/nick_lee_berkeley_edu/anaconda3/lib/python3.10/site-packages/google/cloud/sql/connector/instance.py\", line 312, in _perform_refresh\n",
      "    metadata = await metadata_task\n",
      "  File \"/home/nick_lee_berkeley_edu/anaconda3/lib/python3.10/site-packages/google/cloud/sql/connector/refresh_utils.py\", line 101, in _get_metadata\n",
      "    resp = await client_session.get(url, headers=headers, raise_for_status=True)\n",
      "  File \"/home/nick_lee_berkeley_edu/anaconda3/lib/python3.10/site-packages/aiohttp/client.py\", line 640, in _request\n",
      "    resp.raise_for_status()\n",
      "  File \"/home/nick_lee_berkeley_edu/anaconda3/lib/python3.10/site-packages/aiohttp/client_reqrep.py\", line 1004, in raise_for_status\n",
      "    raise ClientResponseError(\n",
      "aiohttp.client_exceptions.ClientResponseError: 404, message='Not Found', url=URL('https://sqladmin.googleapis.com/sql/v1beta4/projects/w210-capstone-ta/instances/w210-therapeutic-accelerator/connectSettings')\n",
      "['w210-capstone-ta:us-central1:w210-therapeutic-accelerator']: An error occurred while performing refresh. Scheduling another refresh attempt immediately\n",
      "Traceback (most recent call last):\n",
      "  File \"/home/nick_lee_berkeley_edu/anaconda3/lib/python3.10/site-packages/google/cloud/sql/connector/instance.py\", line 388, in _refresh_task\n",
      "    refresh_data = await refresh_task\n",
      "  File \"/home/nick_lee_berkeley_edu/anaconda3/lib/python3.10/site-packages/google/cloud/sql/connector/instance.py\", line 312, in _perform_refresh\n",
      "    metadata = await metadata_task\n",
      "  File \"/home/nick_lee_berkeley_edu/anaconda3/lib/python3.10/site-packages/google/cloud/sql/connector/refresh_utils.py\", line 101, in _get_metadata\n",
      "    resp = await client_session.get(url, headers=headers, raise_for_status=True)\n",
      "  File \"/home/nick_lee_berkeley_edu/anaconda3/lib/python3.10/site-packages/aiohttp/client.py\", line 640, in _request\n",
      "    resp.raise_for_status()\n",
      "  File \"/home/nick_lee_berkeley_edu/anaconda3/lib/python3.10/site-packages/aiohttp/client_reqrep.py\", line 1004, in raise_for_status\n",
      "    raise ClientResponseError(\n",
      "aiohttp.client_exceptions.ClientResponseError: 404, message='Not Found', url=URL('https://sqladmin.googleapis.com/sql/v1beta4/projects/w210-capstone-ta/instances/w210-therapeutic-accelerator/connectSettings')\n",
      "Task exception was never retrieved\n",
      "future: <Task finished name='Task-178' coro=<Instance._schedule_refresh.<locals>._refresh_task() done, defined at /home/nick_lee_berkeley_edu/anaconda3/lib/python3.10/site-packages/google/cloud/sql/connector/instance.py:377> exception=ClientResponseError(RequestInfo(url=URL('https://sqladmin.googleapis.com/sql/v1beta4/projects/w210-capstone-ta/instances/w210-therapeutic-accelerator/connectSettings'), method='GET', headers=<CIMultiDictProxy('Host': 'sqladmin.googleapis.com', 'x-goog-api-client': 'cloud-sql-python-connector/1.2.3+pg8000', 'User-Agent': 'cloud-sql-python-connector/1.2.3+pg8000', 'Content-Type': 'application/json', 'Authorization': 'Bearer ya29.c.b0Aaekm1IY-VGbVQF2xAnFKLraacz4aWWINrWwumL0oEKATtsm27z8JAkL6smOHDDuVMEZcnyunbg_ECSPwUBg_x8Q_idoiNN1VENVTxHGMVrB-BHG9Bml0sqQl3Xq9xEnwVY9Jr4dtL8qOn9Aw-aUFXqI2LWxu-91iNrBEfRfF55dwCi6cBzZ6pigHoQuQptIU-ifSHd9P1H7O2o7k856XmTaioHiOJ6MWPf5a_wzdzq8UHfuGnp9a4P1Wcm-_4E-tRLWVDL5gSoeE1aqUAA96xZFUH2AdTTk49W8RnJqO5WhGwk72sfLLE6D5tCFxuxMAf8p2N6G7_rC-CYS1djxCSs7diTa89LF3e8hnLgH368PpbaY7Mzm08eQ-Xgef35d1QOrmcu_zrpxSBeBax3Sy_oc0slsobSlgJ91etzv4qbFJnF5p3oj6RQV9her5dmez1Ohgo2oY6IY4yIxgc01v_l0ls3tx3IFlXu-e_hhkFQcpR4ZyB_qWXVo45Q58sIhwshbnJuRqVBxyRRentplIfiu4YS_t_9y3Mcbdt_Vu-Fs_3UeaBp8fXhieO2uwclM0VYY2vwq7ZSqYXUZBnkd7FOq9x1YZzYtqbr9oORnrQ9ZZ2gOWWnJqkqtJnZ0ghXspRm3rYaWB6lfpeWgl9hhw1oJsu2kiYcIodjy4b22hvtZ7r9UnBq3ez-c9_SlYxrQpqSZs_yiIXqclzuqt6Byy9i73_z0nMruJJ1IBqlOS2ZbqkMVcb_4ean8tgntbkQ0VasxBQpxgSVgMOivokRIhBB9Q5F_ysiF71jRFQzXfcj9lXgOm_Q_V8iwjaVfFb4bqg7qJdSiOV2Wls8gXdOSSnBjOI2tufkex63wFQ4nU38I6FIt0Fgo5qsuOUgFyX4W68B9Zn_Xqeko5d711VBxyeVza0_mwx__dcfSk20jbIfzxRZOl5xzi2Iy1Vpm-9W9rJ2OsqZt2WWJf54Iuviiwr8e_9iBvJzYIcFcq_05ykruqxu0ri6rWOJ', 'Accept': '*/*', 'Accept-Encoding': 'gzip, deflate')>, real_url=URL('https://sqladmin.googleapis.com/sql/v1beta4/projects/w210-capstone-ta/instances/w210-therapeutic-accelerator/connectSettings')), (), status=404, message='Not Found', headers=<CIMultiDictProxy('Vary': 'Origin', 'Vary': 'X-Origin', 'Vary': 'Referer', 'Content-Type': 'application/json; charset=UTF-8', 'Content-Encoding': 'gzip', 'Date': 'Thu, 08 Jun 2023 00:31:12 GMT', 'Server': 'ESF', 'Cache-Control': 'private', 'X-XSS-Protection': '0', 'X-Frame-Options': 'SAMEORIGIN', 'X-Content-Type-Options': 'nosniff', 'Transfer-Encoding': 'chunked')>)>\n",
      "Traceback (most recent call last):\n",
      "  File \"/home/nick_lee_berkeley_edu/anaconda3/lib/python3.10/site-packages/google/cloud/sql/connector/instance.py\", line 388, in _refresh_task\n",
      "    refresh_data = await refresh_task\n",
      "  File \"/home/nick_lee_berkeley_edu/anaconda3/lib/python3.10/site-packages/google/cloud/sql/connector/instance.py\", line 312, in _perform_refresh\n",
      "    metadata = await metadata_task\n",
      "  File \"/home/nick_lee_berkeley_edu/anaconda3/lib/python3.10/site-packages/google/cloud/sql/connector/refresh_utils.py\", line 101, in _get_metadata\n",
      "    resp = await client_session.get(url, headers=headers, raise_for_status=True)\n",
      "  File \"/home/nick_lee_berkeley_edu/anaconda3/lib/python3.10/site-packages/aiohttp/client.py\", line 640, in _request\n",
      "    resp.raise_for_status()\n",
      "  File \"/home/nick_lee_berkeley_edu/anaconda3/lib/python3.10/site-packages/aiohttp/client_reqrep.py\", line 1004, in raise_for_status\n",
      "    raise ClientResponseError(\n",
      "aiohttp.client_exceptions.ClientResponseError: 404, message='Not Found', url=URL('https://sqladmin.googleapis.com/sql/v1beta4/projects/w210-capstone-ta/instances/w210-therapeutic-accelerator/connectSettings')\n",
      "['w210-capstone-ta:us-central1:w210-therapeutic-accelerator']: An error occurred while performing refresh. Scheduling another refresh attempt immediately\n",
      "Traceback (most recent call last):\n",
      "  File \"/home/nick_lee_berkeley_edu/anaconda3/lib/python3.10/site-packages/google/cloud/sql/connector/instance.py\", line 388, in _refresh_task\n",
      "    refresh_data = await refresh_task\n",
      "  File \"/home/nick_lee_berkeley_edu/anaconda3/lib/python3.10/site-packages/google/cloud/sql/connector/instance.py\", line 312, in _perform_refresh\n",
      "    metadata = await metadata_task\n",
      "  File \"/home/nick_lee_berkeley_edu/anaconda3/lib/python3.10/site-packages/google/cloud/sql/connector/refresh_utils.py\", line 101, in _get_metadata\n",
      "    resp = await client_session.get(url, headers=headers, raise_for_status=True)\n",
      "  File \"/home/nick_lee_berkeley_edu/anaconda3/lib/python3.10/site-packages/aiohttp/client.py\", line 640, in _request\n",
      "    resp.raise_for_status()\n",
      "  File \"/home/nick_lee_berkeley_edu/anaconda3/lib/python3.10/site-packages/aiohttp/client_reqrep.py\", line 1004, in raise_for_status\n",
      "    raise ClientResponseError(\n",
      "aiohttp.client_exceptions.ClientResponseError: 404, message='Not Found', url=URL('https://sqladmin.googleapis.com/sql/v1beta4/projects/w210-capstone-ta/instances/w210-therapeutic-accelerator/connectSettings')\n",
      "Task exception was never retrieved\n",
      "future: <Task finished name='Task-187' coro=<Instance._schedule_refresh.<locals>._refresh_task() done, defined at /home/nick_lee_berkeley_edu/anaconda3/lib/python3.10/site-packages/google/cloud/sql/connector/instance.py:377> exception=ClientResponseError(RequestInfo(url=URL('https://sqladmin.googleapis.com/sql/v1beta4/projects/w210-capstone-ta/instances/w210-therapeutic-accelerator/connectSettings'), method='GET', headers=<CIMultiDictProxy('Host': 'sqladmin.googleapis.com', 'x-goog-api-client': 'cloud-sql-python-connector/1.2.3+pg8000', 'User-Agent': 'cloud-sql-python-connector/1.2.3+pg8000', 'Content-Type': 'application/json', 'Authorization': 'Bearer ya29.c.b0Aaekm1IY-VGbVQF2xAnFKLraacz4aWWINrWwumL0oEKATtsm27z8JAkL6smOHDDuVMEZcnyunbg_ECSPwUBg_x8Q_idoiNN1VENVTxHGMVrB-BHG9Bml0sqQl3Xq9xEnwVY9Jr4dtL8qOn9Aw-aUFXqI2LWxu-91iNrBEfRfF55dwCi6cBzZ6pigHoQuQptIU-ifSHd9P1H7O2o7k856XmTaioHiOJ6MWPf5a_wzdzq8UHfuGnp9a4P1Wcm-_4E-tRLWVDL5gSoeE1aqUAA96xZFUH2AdTTk49W8RnJqO5WhGwk72sfLLE6D5tCFxuxMAf8p2N6G7_rC-CYS1djxCSs7diTa89LF3e8hnLgH368PpbaY7Mzm08eQ-Xgef35d1QOrmcu_zrpxSBeBax3Sy_oc0slsobSlgJ91etzv4qbFJnF5p3oj6RQV9her5dmez1Ohgo2oY6IY4yIxgc01v_l0ls3tx3IFlXu-e_hhkFQcpR4ZyB_qWXVo45Q58sIhwshbnJuRqVBxyRRentplIfiu4YS_t_9y3Mcbdt_Vu-Fs_3UeaBp8fXhieO2uwclM0VYY2vwq7ZSqYXUZBnkd7FOq9x1YZzYtqbr9oORnrQ9ZZ2gOWWnJqkqtJnZ0ghXspRm3rYaWB6lfpeWgl9hhw1oJsu2kiYcIodjy4b22hvtZ7r9UnBq3ez-c9_SlYxrQpqSZs_yiIXqclzuqt6Byy9i73_z0nMruJJ1IBqlOS2ZbqkMVcb_4ean8tgntbkQ0VasxBQpxgSVgMOivokRIhBB9Q5F_ysiF71jRFQzXfcj9lXgOm_Q_V8iwjaVfFb4bqg7qJdSiOV2Wls8gXdOSSnBjOI2tufkex63wFQ4nU38I6FIt0Fgo5qsuOUgFyX4W68B9Zn_Xqeko5d711VBxyeVza0_mwx__dcfSk20jbIfzxRZOl5xzi2Iy1Vpm-9W9rJ2OsqZt2WWJf54Iuviiwr8e_9iBvJzYIcFcq_05ykruqxu0ri6rWOJ', 'Accept': '*/*', 'Accept-Encoding': 'gzip, deflate')>, real_url=URL('https://sqladmin.googleapis.com/sql/v1beta4/projects/w210-capstone-ta/instances/w210-therapeutic-accelerator/connectSettings')), (), status=404, message='Not Found', headers=<CIMultiDictProxy('Vary': 'Origin', 'Vary': 'X-Origin', 'Vary': 'Referer', 'Content-Type': 'application/json; charset=UTF-8', 'Content-Encoding': 'gzip', 'Date': 'Thu, 08 Jun 2023 00:31:42 GMT', 'Server': 'ESF', 'Cache-Control': 'private', 'X-XSS-Protection': '0', 'X-Frame-Options': 'SAMEORIGIN', 'X-Content-Type-Options': 'nosniff', 'Transfer-Encoding': 'chunked')>)>\n",
      "Traceback (most recent call last):\n",
      "  File \"/home/nick_lee_berkeley_edu/anaconda3/lib/python3.10/site-packages/google/cloud/sql/connector/instance.py\", line 388, in _refresh_task\n",
      "    refresh_data = await refresh_task\n",
      "  File \"/home/nick_lee_berkeley_edu/anaconda3/lib/python3.10/site-packages/google/cloud/sql/connector/instance.py\", line 312, in _perform_refresh\n",
      "    metadata = await metadata_task\n",
      "  File \"/home/nick_lee_berkeley_edu/anaconda3/lib/python3.10/site-packages/google/cloud/sql/connector/refresh_utils.py\", line 101, in _get_metadata\n",
      "    resp = await client_session.get(url, headers=headers, raise_for_status=True)\n",
      "  File \"/home/nick_lee_berkeley_edu/anaconda3/lib/python3.10/site-packages/aiohttp/client.py\", line 640, in _request\n",
      "    resp.raise_for_status()\n",
      "  File \"/home/nick_lee_berkeley_edu/anaconda3/lib/python3.10/site-packages/aiohttp/client_reqrep.py\", line 1004, in raise_for_status\n",
      "    raise ClientResponseError(\n",
      "aiohttp.client_exceptions.ClientResponseError: 404, message='Not Found', url=URL('https://sqladmin.googleapis.com/sql/v1beta4/projects/w210-capstone-ta/instances/w210-therapeutic-accelerator/connectSettings')\n",
      "['w210-capstone-ta:us-central1:w210-therapeutic-accelerator']: An error occurred while performing refresh. Scheduling another refresh attempt immediately\n",
      "Traceback (most recent call last):\n",
      "  File \"/home/nick_lee_berkeley_edu/anaconda3/lib/python3.10/site-packages/google/cloud/sql/connector/instance.py\", line 388, in _refresh_task\n",
      "    refresh_data = await refresh_task\n",
      "  File \"/home/nick_lee_berkeley_edu/anaconda3/lib/python3.10/site-packages/google/cloud/sql/connector/instance.py\", line 312, in _perform_refresh\n",
      "    metadata = await metadata_task\n",
      "  File \"/home/nick_lee_berkeley_edu/anaconda3/lib/python3.10/site-packages/google/cloud/sql/connector/refresh_utils.py\", line 101, in _get_metadata\n",
      "    resp = await client_session.get(url, headers=headers, raise_for_status=True)\n",
      "  File \"/home/nick_lee_berkeley_edu/anaconda3/lib/python3.10/site-packages/aiohttp/client.py\", line 640, in _request\n",
      "    resp.raise_for_status()\n",
      "  File \"/home/nick_lee_berkeley_edu/anaconda3/lib/python3.10/site-packages/aiohttp/client_reqrep.py\", line 1004, in raise_for_status\n",
      "    raise ClientResponseError(\n",
      "aiohttp.client_exceptions.ClientResponseError: 404, message='Not Found', url=URL('https://sqladmin.googleapis.com/sql/v1beta4/projects/w210-capstone-ta/instances/w210-therapeutic-accelerator/connectSettings')\n",
      "Task exception was never retrieved\n",
      "future: <Task finished name='Task-196' coro=<Instance._schedule_refresh.<locals>._refresh_task() done, defined at /home/nick_lee_berkeley_edu/anaconda3/lib/python3.10/site-packages/google/cloud/sql/connector/instance.py:377> exception=ClientResponseError(RequestInfo(url=URL('https://sqladmin.googleapis.com/sql/v1beta4/projects/w210-capstone-ta/instances/w210-therapeutic-accelerator/connectSettings'), method='GET', headers=<CIMultiDictProxy('Host': 'sqladmin.googleapis.com', 'x-goog-api-client': 'cloud-sql-python-connector/1.2.3+pg8000', 'User-Agent': 'cloud-sql-python-connector/1.2.3+pg8000', 'Content-Type': 'application/json', 'Authorization': 'Bearer ya29.c.b0Aaekm1IY-VGbVQF2xAnFKLraacz4aWWINrWwumL0oEKATtsm27z8JAkL6smOHDDuVMEZcnyunbg_ECSPwUBg_x8Q_idoiNN1VENVTxHGMVrB-BHG9Bml0sqQl3Xq9xEnwVY9Jr4dtL8qOn9Aw-aUFXqI2LWxu-91iNrBEfRfF55dwCi6cBzZ6pigHoQuQptIU-ifSHd9P1H7O2o7k856XmTaioHiOJ6MWPf5a_wzdzq8UHfuGnp9a4P1Wcm-_4E-tRLWVDL5gSoeE1aqUAA96xZFUH2AdTTk49W8RnJqO5WhGwk72sfLLE6D5tCFxuxMAf8p2N6G7_rC-CYS1djxCSs7diTa89LF3e8hnLgH368PpbaY7Mzm08eQ-Xgef35d1QOrmcu_zrpxSBeBax3Sy_oc0slsobSlgJ91etzv4qbFJnF5p3oj6RQV9her5dmez1Ohgo2oY6IY4yIxgc01v_l0ls3tx3IFlXu-e_hhkFQcpR4ZyB_qWXVo45Q58sIhwshbnJuRqVBxyRRentplIfiu4YS_t_9y3Mcbdt_Vu-Fs_3UeaBp8fXhieO2uwclM0VYY2vwq7ZSqYXUZBnkd7FOq9x1YZzYtqbr9oORnrQ9ZZ2gOWWnJqkqtJnZ0ghXspRm3rYaWB6lfpeWgl9hhw1oJsu2kiYcIodjy4b22hvtZ7r9UnBq3ez-c9_SlYxrQpqSZs_yiIXqclzuqt6Byy9i73_z0nMruJJ1IBqlOS2ZbqkMVcb_4ean8tgntbkQ0VasxBQpxgSVgMOivokRIhBB9Q5F_ysiF71jRFQzXfcj9lXgOm_Q_V8iwjaVfFb4bqg7qJdSiOV2Wls8gXdOSSnBjOI2tufkex63wFQ4nU38I6FIt0Fgo5qsuOUgFyX4W68B9Zn_Xqeko5d711VBxyeVza0_mwx__dcfSk20jbIfzxRZOl5xzi2Iy1Vpm-9W9rJ2OsqZt2WWJf54Iuviiwr8e_9iBvJzYIcFcq_05ykruqxu0ri6rWOJ', 'Accept': '*/*', 'Accept-Encoding': 'gzip, deflate')>, real_url=URL('https://sqladmin.googleapis.com/sql/v1beta4/projects/w210-capstone-ta/instances/w210-therapeutic-accelerator/connectSettings')), (), status=404, message='Not Found', headers=<CIMultiDictProxy('Vary': 'Origin', 'Vary': 'X-Origin', 'Vary': 'Referer', 'Content-Type': 'application/json; charset=UTF-8', 'Content-Encoding': 'gzip', 'Date': 'Thu, 08 Jun 2023 00:32:12 GMT', 'Server': 'ESF', 'Cache-Control': 'private', 'X-XSS-Protection': '0', 'X-Frame-Options': 'SAMEORIGIN', 'X-Content-Type-Options': 'nosniff', 'Transfer-Encoding': 'chunked')>)>\n",
      "Traceback (most recent call last):\n",
      "  File \"/home/nick_lee_berkeley_edu/anaconda3/lib/python3.10/site-packages/google/cloud/sql/connector/instance.py\", line 388, in _refresh_task\n",
      "    refresh_data = await refresh_task\n",
      "  File \"/home/nick_lee_berkeley_edu/anaconda3/lib/python3.10/site-packages/google/cloud/sql/connector/instance.py\", line 312, in _perform_refresh\n",
      "    metadata = await metadata_task\n",
      "  File \"/home/nick_lee_berkeley_edu/anaconda3/lib/python3.10/site-packages/google/cloud/sql/connector/refresh_utils.py\", line 101, in _get_metadata\n",
      "    resp = await client_session.get(url, headers=headers, raise_for_status=True)\n",
      "  File \"/home/nick_lee_berkeley_edu/anaconda3/lib/python3.10/site-packages/aiohttp/client.py\", line 640, in _request\n",
      "    resp.raise_for_status()\n",
      "  File \"/home/nick_lee_berkeley_edu/anaconda3/lib/python3.10/site-packages/aiohttp/client_reqrep.py\", line 1004, in raise_for_status\n",
      "    raise ClientResponseError(\n",
      "aiohttp.client_exceptions.ClientResponseError: 404, message='Not Found', url=URL('https://sqladmin.googleapis.com/sql/v1beta4/projects/w210-capstone-ta/instances/w210-therapeutic-accelerator/connectSettings')\n",
      "['w210-capstone-ta:us-central1:w210-therapeutic-accelerator']: An error occurred while performing refresh. Scheduling another refresh attempt immediately\n",
      "Traceback (most recent call last):\n",
      "  File \"/home/nick_lee_berkeley_edu/anaconda3/lib/python3.10/site-packages/google/cloud/sql/connector/instance.py\", line 388, in _refresh_task\n",
      "    refresh_data = await refresh_task\n",
      "  File \"/home/nick_lee_berkeley_edu/anaconda3/lib/python3.10/site-packages/google/cloud/sql/connector/instance.py\", line 312, in _perform_refresh\n",
      "    metadata = await metadata_task\n",
      "  File \"/home/nick_lee_berkeley_edu/anaconda3/lib/python3.10/site-packages/google/cloud/sql/connector/refresh_utils.py\", line 101, in _get_metadata\n",
      "    resp = await client_session.get(url, headers=headers, raise_for_status=True)\n",
      "  File \"/home/nick_lee_berkeley_edu/anaconda3/lib/python3.10/site-packages/aiohttp/client.py\", line 640, in _request\n",
      "    resp.raise_for_status()\n",
      "  File \"/home/nick_lee_berkeley_edu/anaconda3/lib/python3.10/site-packages/aiohttp/client_reqrep.py\", line 1004, in raise_for_status\n",
      "    raise ClientResponseError(\n",
      "aiohttp.client_exceptions.ClientResponseError: 404, message='Not Found', url=URL('https://sqladmin.googleapis.com/sql/v1beta4/projects/w210-capstone-ta/instances/w210-therapeutic-accelerator/connectSettings')\n",
      "Task exception was never retrieved\n",
      "future: <Task finished name='Task-205' coro=<Instance._schedule_refresh.<locals>._refresh_task() done, defined at /home/nick_lee_berkeley_edu/anaconda3/lib/python3.10/site-packages/google/cloud/sql/connector/instance.py:377> exception=ClientResponseError(RequestInfo(url=URL('https://sqladmin.googleapis.com/sql/v1beta4/projects/w210-capstone-ta/instances/w210-therapeutic-accelerator/connectSettings'), method='GET', headers=<CIMultiDictProxy('Host': 'sqladmin.googleapis.com', 'x-goog-api-client': 'cloud-sql-python-connector/1.2.3+pg8000', 'User-Agent': 'cloud-sql-python-connector/1.2.3+pg8000', 'Content-Type': 'application/json', 'Authorization': 'Bearer ya29.c.b0Aaekm1IY-VGbVQF2xAnFKLraacz4aWWINrWwumL0oEKATtsm27z8JAkL6smOHDDuVMEZcnyunbg_ECSPwUBg_x8Q_idoiNN1VENVTxHGMVrB-BHG9Bml0sqQl3Xq9xEnwVY9Jr4dtL8qOn9Aw-aUFXqI2LWxu-91iNrBEfRfF55dwCi6cBzZ6pigHoQuQptIU-ifSHd9P1H7O2o7k856XmTaioHiOJ6MWPf5a_wzdzq8UHfuGnp9a4P1Wcm-_4E-tRLWVDL5gSoeE1aqUAA96xZFUH2AdTTk49W8RnJqO5WhGwk72sfLLE6D5tCFxuxMAf8p2N6G7_rC-CYS1djxCSs7diTa89LF3e8hnLgH368PpbaY7Mzm08eQ-Xgef35d1QOrmcu_zrpxSBeBax3Sy_oc0slsobSlgJ91etzv4qbFJnF5p3oj6RQV9her5dmez1Ohgo2oY6IY4yIxgc01v_l0ls3tx3IFlXu-e_hhkFQcpR4ZyB_qWXVo45Q58sIhwshbnJuRqVBxyRRentplIfiu4YS_t_9y3Mcbdt_Vu-Fs_3UeaBp8fXhieO2uwclM0VYY2vwq7ZSqYXUZBnkd7FOq9x1YZzYtqbr9oORnrQ9ZZ2gOWWnJqkqtJnZ0ghXspRm3rYaWB6lfpeWgl9hhw1oJsu2kiYcIodjy4b22hvtZ7r9UnBq3ez-c9_SlYxrQpqSZs_yiIXqclzuqt6Byy9i73_z0nMruJJ1IBqlOS2ZbqkMVcb_4ean8tgntbkQ0VasxBQpxgSVgMOivokRIhBB9Q5F_ysiF71jRFQzXfcj9lXgOm_Q_V8iwjaVfFb4bqg7qJdSiOV2Wls8gXdOSSnBjOI2tufkex63wFQ4nU38I6FIt0Fgo5qsuOUgFyX4W68B9Zn_Xqeko5d711VBxyeVza0_mwx__dcfSk20jbIfzxRZOl5xzi2Iy1Vpm-9W9rJ2OsqZt2WWJf54Iuviiwr8e_9iBvJzYIcFcq_05ykruqxu0ri6rWOJ', 'Accept': '*/*', 'Accept-Encoding': 'gzip, deflate')>, real_url=URL('https://sqladmin.googleapis.com/sql/v1beta4/projects/w210-capstone-ta/instances/w210-therapeutic-accelerator/connectSettings')), (), status=404, message='Not Found', headers=<CIMultiDictProxy('Vary': 'Origin', 'Vary': 'X-Origin', 'Vary': 'Referer', 'Content-Type': 'application/json; charset=UTF-8', 'Content-Encoding': 'gzip', 'Date': 'Thu, 08 Jun 2023 00:32:42 GMT', 'Server': 'ESF', 'Cache-Control': 'private', 'X-XSS-Protection': '0', 'X-Frame-Options': 'SAMEORIGIN', 'X-Content-Type-Options': 'nosniff', 'Transfer-Encoding': 'chunked')>)>\n",
      "Traceback (most recent call last):\n",
      "  File \"/home/nick_lee_berkeley_edu/anaconda3/lib/python3.10/site-packages/google/cloud/sql/connector/instance.py\", line 388, in _refresh_task\n",
      "    refresh_data = await refresh_task\n",
      "  File \"/home/nick_lee_berkeley_edu/anaconda3/lib/python3.10/site-packages/google/cloud/sql/connector/instance.py\", line 312, in _perform_refresh\n",
      "    metadata = await metadata_task\n",
      "  File \"/home/nick_lee_berkeley_edu/anaconda3/lib/python3.10/site-packages/google/cloud/sql/connector/refresh_utils.py\", line 101, in _get_metadata\n",
      "    resp = await client_session.get(url, headers=headers, raise_for_status=True)\n",
      "  File \"/home/nick_lee_berkeley_edu/anaconda3/lib/python3.10/site-packages/aiohttp/client.py\", line 640, in _request\n",
      "    resp.raise_for_status()\n",
      "  File \"/home/nick_lee_berkeley_edu/anaconda3/lib/python3.10/site-packages/aiohttp/client_reqrep.py\", line 1004, in raise_for_status\n",
      "    raise ClientResponseError(\n",
      "aiohttp.client_exceptions.ClientResponseError: 404, message='Not Found', url=URL('https://sqladmin.googleapis.com/sql/v1beta4/projects/w210-capstone-ta/instances/w210-therapeutic-accelerator/connectSettings')\n",
      "['w210-capstone-ta:us-central1:w210-therapeutic-accelerator']: An error occurred while performing refresh. Scheduling another refresh attempt immediately\n",
      "Traceback (most recent call last):\n",
      "  File \"/home/nick_lee_berkeley_edu/anaconda3/lib/python3.10/site-packages/google/cloud/sql/connector/instance.py\", line 388, in _refresh_task\n",
      "    refresh_data = await refresh_task\n",
      "  File \"/home/nick_lee_berkeley_edu/anaconda3/lib/python3.10/site-packages/google/cloud/sql/connector/instance.py\", line 312, in _perform_refresh\n",
      "    metadata = await metadata_task\n",
      "  File \"/home/nick_lee_berkeley_edu/anaconda3/lib/python3.10/site-packages/google/cloud/sql/connector/refresh_utils.py\", line 101, in _get_metadata\n",
      "    resp = await client_session.get(url, headers=headers, raise_for_status=True)\n",
      "  File \"/home/nick_lee_berkeley_edu/anaconda3/lib/python3.10/site-packages/aiohttp/client.py\", line 640, in _request\n",
      "    resp.raise_for_status()\n",
      "  File \"/home/nick_lee_berkeley_edu/anaconda3/lib/python3.10/site-packages/aiohttp/client_reqrep.py\", line 1004, in raise_for_status\n",
      "    raise ClientResponseError(\n",
      "aiohttp.client_exceptions.ClientResponseError: 404, message='Not Found', url=URL('https://sqladmin.googleapis.com/sql/v1beta4/projects/w210-capstone-ta/instances/w210-therapeutic-accelerator/connectSettings')\n",
      "Task exception was never retrieved\n",
      "future: <Task finished name='Task-214' coro=<Instance._schedule_refresh.<locals>._refresh_task() done, defined at /home/nick_lee_berkeley_edu/anaconda3/lib/python3.10/site-packages/google/cloud/sql/connector/instance.py:377> exception=ClientResponseError(RequestInfo(url=URL('https://sqladmin.googleapis.com/sql/v1beta4/projects/w210-capstone-ta/instances/w210-therapeutic-accelerator/connectSettings'), method='GET', headers=<CIMultiDictProxy('Host': 'sqladmin.googleapis.com', 'x-goog-api-client': 'cloud-sql-python-connector/1.2.3+pg8000', 'User-Agent': 'cloud-sql-python-connector/1.2.3+pg8000', 'Content-Type': 'application/json', 'Authorization': 'Bearer ya29.c.b0Aaekm1IY-VGbVQF2xAnFKLraacz4aWWINrWwumL0oEKATtsm27z8JAkL6smOHDDuVMEZcnyunbg_ECSPwUBg_x8Q_idoiNN1VENVTxHGMVrB-BHG9Bml0sqQl3Xq9xEnwVY9Jr4dtL8qOn9Aw-aUFXqI2LWxu-91iNrBEfRfF55dwCi6cBzZ6pigHoQuQptIU-ifSHd9P1H7O2o7k856XmTaioHiOJ6MWPf5a_wzdzq8UHfuGnp9a4P1Wcm-_4E-tRLWVDL5gSoeE1aqUAA96xZFUH2AdTTk49W8RnJqO5WhGwk72sfLLE6D5tCFxuxMAf8p2N6G7_rC-CYS1djxCSs7diTa89LF3e8hnLgH368PpbaY7Mzm08eQ-Xgef35d1QOrmcu_zrpxSBeBax3Sy_oc0slsobSlgJ91etzv4qbFJnF5p3oj6RQV9her5dmez1Ohgo2oY6IY4yIxgc01v_l0ls3tx3IFlXu-e_hhkFQcpR4ZyB_qWXVo45Q58sIhwshbnJuRqVBxyRRentplIfiu4YS_t_9y3Mcbdt_Vu-Fs_3UeaBp8fXhieO2uwclM0VYY2vwq7ZSqYXUZBnkd7FOq9x1YZzYtqbr9oORnrQ9ZZ2gOWWnJqkqtJnZ0ghXspRm3rYaWB6lfpeWgl9hhw1oJsu2kiYcIodjy4b22hvtZ7r9UnBq3ez-c9_SlYxrQpqSZs_yiIXqclzuqt6Byy9i73_z0nMruJJ1IBqlOS2ZbqkMVcb_4ean8tgntbkQ0VasxBQpxgSVgMOivokRIhBB9Q5F_ysiF71jRFQzXfcj9lXgOm_Q_V8iwjaVfFb4bqg7qJdSiOV2Wls8gXdOSSnBjOI2tufkex63wFQ4nU38I6FIt0Fgo5qsuOUgFyX4W68B9Zn_Xqeko5d711VBxyeVza0_mwx__dcfSk20jbIfzxRZOl5xzi2Iy1Vpm-9W9rJ2OsqZt2WWJf54Iuviiwr8e_9iBvJzYIcFcq_05ykruqxu0ri6rWOJ', 'Accept': '*/*', 'Accept-Encoding': 'gzip, deflate')>, real_url=URL('https://sqladmin.googleapis.com/sql/v1beta4/projects/w210-capstone-ta/instances/w210-therapeutic-accelerator/connectSettings')), (), status=404, message='Not Found', headers=<CIMultiDictProxy('Vary': 'Origin', 'Vary': 'X-Origin', 'Vary': 'Referer', 'Content-Type': 'application/json; charset=UTF-8', 'Content-Encoding': 'gzip', 'Date': 'Thu, 08 Jun 2023 00:33:12 GMT', 'Server': 'ESF', 'Cache-Control': 'private', 'X-XSS-Protection': '0', 'X-Frame-Options': 'SAMEORIGIN', 'X-Content-Type-Options': 'nosniff', 'Transfer-Encoding': 'chunked')>)>\n",
      "Traceback (most recent call last):\n",
      "  File \"/home/nick_lee_berkeley_edu/anaconda3/lib/python3.10/site-packages/google/cloud/sql/connector/instance.py\", line 388, in _refresh_task\n",
      "    refresh_data = await refresh_task\n",
      "  File \"/home/nick_lee_berkeley_edu/anaconda3/lib/python3.10/site-packages/google/cloud/sql/connector/instance.py\", line 312, in _perform_refresh\n",
      "    metadata = await metadata_task\n",
      "  File \"/home/nick_lee_berkeley_edu/anaconda3/lib/python3.10/site-packages/google/cloud/sql/connector/refresh_utils.py\", line 101, in _get_metadata\n",
      "    resp = await client_session.get(url, headers=headers, raise_for_status=True)\n",
      "  File \"/home/nick_lee_berkeley_edu/anaconda3/lib/python3.10/site-packages/aiohttp/client.py\", line 640, in _request\n",
      "    resp.raise_for_status()\n",
      "  File \"/home/nick_lee_berkeley_edu/anaconda3/lib/python3.10/site-packages/aiohttp/client_reqrep.py\", line 1004, in raise_for_status\n",
      "    raise ClientResponseError(\n",
      "aiohttp.client_exceptions.ClientResponseError: 404, message='Not Found', url=URL('https://sqladmin.googleapis.com/sql/v1beta4/projects/w210-capstone-ta/instances/w210-therapeutic-accelerator/connectSettings')\n",
      "['w210-capstone-ta:us-central1:w210-therapeutic-accelerator']: An error occurred while performing refresh. Scheduling another refresh attempt immediately\n",
      "Traceback (most recent call last):\n",
      "  File \"/home/nick_lee_berkeley_edu/anaconda3/lib/python3.10/site-packages/google/cloud/sql/connector/instance.py\", line 388, in _refresh_task\n",
      "    refresh_data = await refresh_task\n",
      "  File \"/home/nick_lee_berkeley_edu/anaconda3/lib/python3.10/site-packages/google/cloud/sql/connector/instance.py\", line 312, in _perform_refresh\n",
      "    metadata = await metadata_task\n",
      "  File \"/home/nick_lee_berkeley_edu/anaconda3/lib/python3.10/site-packages/google/cloud/sql/connector/refresh_utils.py\", line 101, in _get_metadata\n",
      "    resp = await client_session.get(url, headers=headers, raise_for_status=True)\n",
      "  File \"/home/nick_lee_berkeley_edu/anaconda3/lib/python3.10/site-packages/aiohttp/client.py\", line 640, in _request\n",
      "    resp.raise_for_status()\n",
      "  File \"/home/nick_lee_berkeley_edu/anaconda3/lib/python3.10/site-packages/aiohttp/client_reqrep.py\", line 1004, in raise_for_status\n",
      "    raise ClientResponseError(\n",
      "aiohttp.client_exceptions.ClientResponseError: 404, message='Not Found', url=URL('https://sqladmin.googleapis.com/sql/v1beta4/projects/w210-capstone-ta/instances/w210-therapeutic-accelerator/connectSettings')\n",
      "Task exception was never retrieved\n",
      "future: <Task finished name='Task-223' coro=<Instance._schedule_refresh.<locals>._refresh_task() done, defined at /home/nick_lee_berkeley_edu/anaconda3/lib/python3.10/site-packages/google/cloud/sql/connector/instance.py:377> exception=ClientResponseError(RequestInfo(url=URL('https://sqladmin.googleapis.com/sql/v1beta4/projects/w210-capstone-ta/instances/w210-therapeutic-accelerator/connectSettings'), method='GET', headers=<CIMultiDictProxy('Host': 'sqladmin.googleapis.com', 'x-goog-api-client': 'cloud-sql-python-connector/1.2.3+pg8000', 'User-Agent': 'cloud-sql-python-connector/1.2.3+pg8000', 'Content-Type': 'application/json', 'Authorization': 'Bearer ya29.c.b0Aaekm1IY-VGbVQF2xAnFKLraacz4aWWINrWwumL0oEKATtsm27z8JAkL6smOHDDuVMEZcnyunbg_ECSPwUBg_x8Q_idoiNN1VENVTxHGMVrB-BHG9Bml0sqQl3Xq9xEnwVY9Jr4dtL8qOn9Aw-aUFXqI2LWxu-91iNrBEfRfF55dwCi6cBzZ6pigHoQuQptIU-ifSHd9P1H7O2o7k856XmTaioHiOJ6MWPf5a_wzdzq8UHfuGnp9a4P1Wcm-_4E-tRLWVDL5gSoeE1aqUAA96xZFUH2AdTTk49W8RnJqO5WhGwk72sfLLE6D5tCFxuxMAf8p2N6G7_rC-CYS1djxCSs7diTa89LF3e8hnLgH368PpbaY7Mzm08eQ-Xgef35d1QOrmcu_zrpxSBeBax3Sy_oc0slsobSlgJ91etzv4qbFJnF5p3oj6RQV9her5dmez1Ohgo2oY6IY4yIxgc01v_l0ls3tx3IFlXu-e_hhkFQcpR4ZyB_qWXVo45Q58sIhwshbnJuRqVBxyRRentplIfiu4YS_t_9y3Mcbdt_Vu-Fs_3UeaBp8fXhieO2uwclM0VYY2vwq7ZSqYXUZBnkd7FOq9x1YZzYtqbr9oORnrQ9ZZ2gOWWnJqkqtJnZ0ghXspRm3rYaWB6lfpeWgl9hhw1oJsu2kiYcIodjy4b22hvtZ7r9UnBq3ez-c9_SlYxrQpqSZs_yiIXqclzuqt6Byy9i73_z0nMruJJ1IBqlOS2ZbqkMVcb_4ean8tgntbkQ0VasxBQpxgSVgMOivokRIhBB9Q5F_ysiF71jRFQzXfcj9lXgOm_Q_V8iwjaVfFb4bqg7qJdSiOV2Wls8gXdOSSnBjOI2tufkex63wFQ4nU38I6FIt0Fgo5qsuOUgFyX4W68B9Zn_Xqeko5d711VBxyeVza0_mwx__dcfSk20jbIfzxRZOl5xzi2Iy1Vpm-9W9rJ2OsqZt2WWJf54Iuviiwr8e_9iBvJzYIcFcq_05ykruqxu0ri6rWOJ', 'Accept': '*/*', 'Accept-Encoding': 'gzip, deflate')>, real_url=URL('https://sqladmin.googleapis.com/sql/v1beta4/projects/w210-capstone-ta/instances/w210-therapeutic-accelerator/connectSettings')), (), status=404, message='Not Found', headers=<CIMultiDictProxy('Vary': 'Origin', 'Vary': 'X-Origin', 'Vary': 'Referer', 'Content-Type': 'application/json; charset=UTF-8', 'Content-Encoding': 'gzip', 'Date': 'Thu, 08 Jun 2023 00:33:42 GMT', 'Server': 'ESF', 'Cache-Control': 'private', 'X-XSS-Protection': '0', 'X-Frame-Options': 'SAMEORIGIN', 'X-Content-Type-Options': 'nosniff', 'Transfer-Encoding': 'chunked')>)>\n",
      "Traceback (most recent call last):\n",
      "  File \"/home/nick_lee_berkeley_edu/anaconda3/lib/python3.10/site-packages/google/cloud/sql/connector/instance.py\", line 388, in _refresh_task\n",
      "    refresh_data = await refresh_task\n",
      "  File \"/home/nick_lee_berkeley_edu/anaconda3/lib/python3.10/site-packages/google/cloud/sql/connector/instance.py\", line 312, in _perform_refresh\n",
      "    metadata = await metadata_task\n",
      "  File \"/home/nick_lee_berkeley_edu/anaconda3/lib/python3.10/site-packages/google/cloud/sql/connector/refresh_utils.py\", line 101, in _get_metadata\n",
      "    resp = await client_session.get(url, headers=headers, raise_for_status=True)\n",
      "  File \"/home/nick_lee_berkeley_edu/anaconda3/lib/python3.10/site-packages/aiohttp/client.py\", line 640, in _request\n",
      "    resp.raise_for_status()\n",
      "  File \"/home/nick_lee_berkeley_edu/anaconda3/lib/python3.10/site-packages/aiohttp/client_reqrep.py\", line 1004, in raise_for_status\n",
      "    raise ClientResponseError(\n",
      "aiohttp.client_exceptions.ClientResponseError: 404, message='Not Found', url=URL('https://sqladmin.googleapis.com/sql/v1beta4/projects/w210-capstone-ta/instances/w210-therapeutic-accelerator/connectSettings')\n",
      "['w210-capstone-ta:us-central1:w210-therapeutic-accelerator']: An error occurred while performing refresh. Scheduling another refresh attempt immediately\n",
      "Traceback (most recent call last):\n",
      "  File \"/home/nick_lee_berkeley_edu/anaconda3/lib/python3.10/site-packages/google/cloud/sql/connector/instance.py\", line 388, in _refresh_task\n",
      "    refresh_data = await refresh_task\n",
      "  File \"/home/nick_lee_berkeley_edu/anaconda3/lib/python3.10/site-packages/google/cloud/sql/connector/instance.py\", line 312, in _perform_refresh\n",
      "    metadata = await metadata_task\n",
      "  File \"/home/nick_lee_berkeley_edu/anaconda3/lib/python3.10/site-packages/google/cloud/sql/connector/refresh_utils.py\", line 101, in _get_metadata\n",
      "    resp = await client_session.get(url, headers=headers, raise_for_status=True)\n",
      "  File \"/home/nick_lee_berkeley_edu/anaconda3/lib/python3.10/site-packages/aiohttp/client.py\", line 640, in _request\n",
      "    resp.raise_for_status()\n",
      "  File \"/home/nick_lee_berkeley_edu/anaconda3/lib/python3.10/site-packages/aiohttp/client_reqrep.py\", line 1004, in raise_for_status\n",
      "    raise ClientResponseError(\n",
      "aiohttp.client_exceptions.ClientResponseError: 404, message='Not Found', url=URL('https://sqladmin.googleapis.com/sql/v1beta4/projects/w210-capstone-ta/instances/w210-therapeutic-accelerator/connectSettings')\n",
      "Task exception was never retrieved\n",
      "future: <Task finished name='Task-232' coro=<Instance._schedule_refresh.<locals>._refresh_task() done, defined at /home/nick_lee_berkeley_edu/anaconda3/lib/python3.10/site-packages/google/cloud/sql/connector/instance.py:377> exception=ClientResponseError(RequestInfo(url=URL('https://sqladmin.googleapis.com/sql/v1beta4/projects/w210-capstone-ta/instances/w210-therapeutic-accelerator/connectSettings'), method='GET', headers=<CIMultiDictProxy('Host': 'sqladmin.googleapis.com', 'x-goog-api-client': 'cloud-sql-python-connector/1.2.3+pg8000', 'User-Agent': 'cloud-sql-python-connector/1.2.3+pg8000', 'Content-Type': 'application/json', 'Authorization': 'Bearer ya29.c.b0Aaekm1IY-VGbVQF2xAnFKLraacz4aWWINrWwumL0oEKATtsm27z8JAkL6smOHDDuVMEZcnyunbg_ECSPwUBg_x8Q_idoiNN1VENVTxHGMVrB-BHG9Bml0sqQl3Xq9xEnwVY9Jr4dtL8qOn9Aw-aUFXqI2LWxu-91iNrBEfRfF55dwCi6cBzZ6pigHoQuQptIU-ifSHd9P1H7O2o7k856XmTaioHiOJ6MWPf5a_wzdzq8UHfuGnp9a4P1Wcm-_4E-tRLWVDL5gSoeE1aqUAA96xZFUH2AdTTk49W8RnJqO5WhGwk72sfLLE6D5tCFxuxMAf8p2N6G7_rC-CYS1djxCSs7diTa89LF3e8hnLgH368PpbaY7Mzm08eQ-Xgef35d1QOrmcu_zrpxSBeBax3Sy_oc0slsobSlgJ91etzv4qbFJnF5p3oj6RQV9her5dmez1Ohgo2oY6IY4yIxgc01v_l0ls3tx3IFlXu-e_hhkFQcpR4ZyB_qWXVo45Q58sIhwshbnJuRqVBxyRRentplIfiu4YS_t_9y3Mcbdt_Vu-Fs_3UeaBp8fXhieO2uwclM0VYY2vwq7ZSqYXUZBnkd7FOq9x1YZzYtqbr9oORnrQ9ZZ2gOWWnJqkqtJnZ0ghXspRm3rYaWB6lfpeWgl9hhw1oJsu2kiYcIodjy4b22hvtZ7r9UnBq3ez-c9_SlYxrQpqSZs_yiIXqclzuqt6Byy9i73_z0nMruJJ1IBqlOS2ZbqkMVcb_4ean8tgntbkQ0VasxBQpxgSVgMOivokRIhBB9Q5F_ysiF71jRFQzXfcj9lXgOm_Q_V8iwjaVfFb4bqg7qJdSiOV2Wls8gXdOSSnBjOI2tufkex63wFQ4nU38I6FIt0Fgo5qsuOUgFyX4W68B9Zn_Xqeko5d711VBxyeVza0_mwx__dcfSk20jbIfzxRZOl5xzi2Iy1Vpm-9W9rJ2OsqZt2WWJf54Iuviiwr8e_9iBvJzYIcFcq_05ykruqxu0ri6rWOJ', 'Accept': '*/*', 'Accept-Encoding': 'gzip, deflate')>, real_url=URL('https://sqladmin.googleapis.com/sql/v1beta4/projects/w210-capstone-ta/instances/w210-therapeutic-accelerator/connectSettings')), (), status=404, message='Not Found', headers=<CIMultiDictProxy('Vary': 'Origin', 'Vary': 'X-Origin', 'Vary': 'Referer', 'Content-Type': 'application/json; charset=UTF-8', 'Content-Encoding': 'gzip', 'Date': 'Thu, 08 Jun 2023 00:34:12 GMT', 'Server': 'ESF', 'Cache-Control': 'private', 'X-XSS-Protection': '0', 'X-Frame-Options': 'SAMEORIGIN', 'X-Content-Type-Options': 'nosniff', 'Transfer-Encoding': 'chunked')>)>\n",
      "Traceback (most recent call last):\n",
      "  File \"/home/nick_lee_berkeley_edu/anaconda3/lib/python3.10/site-packages/google/cloud/sql/connector/instance.py\", line 388, in _refresh_task\n",
      "    refresh_data = await refresh_task\n",
      "  File \"/home/nick_lee_berkeley_edu/anaconda3/lib/python3.10/site-packages/google/cloud/sql/connector/instance.py\", line 312, in _perform_refresh\n",
      "    metadata = await metadata_task\n",
      "  File \"/home/nick_lee_berkeley_edu/anaconda3/lib/python3.10/site-packages/google/cloud/sql/connector/refresh_utils.py\", line 101, in _get_metadata\n",
      "    resp = await client_session.get(url, headers=headers, raise_for_status=True)\n",
      "  File \"/home/nick_lee_berkeley_edu/anaconda3/lib/python3.10/site-packages/aiohttp/client.py\", line 640, in _request\n",
      "    resp.raise_for_status()\n",
      "  File \"/home/nick_lee_berkeley_edu/anaconda3/lib/python3.10/site-packages/aiohttp/client_reqrep.py\", line 1004, in raise_for_status\n",
      "    raise ClientResponseError(\n",
      "aiohttp.client_exceptions.ClientResponseError: 404, message='Not Found', url=URL('https://sqladmin.googleapis.com/sql/v1beta4/projects/w210-capstone-ta/instances/w210-therapeutic-accelerator/connectSettings')\n",
      "['w210-capstone-ta:us-central1:w210-therapeutic-accelerator']: An error occurred while performing refresh. Scheduling another refresh attempt immediately\n",
      "Traceback (most recent call last):\n",
      "  File \"/home/nick_lee_berkeley_edu/anaconda3/lib/python3.10/site-packages/google/cloud/sql/connector/instance.py\", line 388, in _refresh_task\n",
      "    refresh_data = await refresh_task\n",
      "  File \"/home/nick_lee_berkeley_edu/anaconda3/lib/python3.10/site-packages/google/cloud/sql/connector/instance.py\", line 312, in _perform_refresh\n",
      "    metadata = await metadata_task\n",
      "  File \"/home/nick_lee_berkeley_edu/anaconda3/lib/python3.10/site-packages/google/cloud/sql/connector/refresh_utils.py\", line 101, in _get_metadata\n",
      "    resp = await client_session.get(url, headers=headers, raise_for_status=True)\n",
      "  File \"/home/nick_lee_berkeley_edu/anaconda3/lib/python3.10/site-packages/aiohttp/client.py\", line 640, in _request\n",
      "    resp.raise_for_status()\n",
      "  File \"/home/nick_lee_berkeley_edu/anaconda3/lib/python3.10/site-packages/aiohttp/client_reqrep.py\", line 1004, in raise_for_status\n",
      "    raise ClientResponseError(\n",
      "aiohttp.client_exceptions.ClientResponseError: 404, message='Not Found', url=URL('https://sqladmin.googleapis.com/sql/v1beta4/projects/w210-capstone-ta/instances/w210-therapeutic-accelerator/connectSettings')\n",
      "Task exception was never retrieved\n",
      "future: <Task finished name='Task-241' coro=<Instance._schedule_refresh.<locals>._refresh_task() done, defined at /home/nick_lee_berkeley_edu/anaconda3/lib/python3.10/site-packages/google/cloud/sql/connector/instance.py:377> exception=ClientResponseError(RequestInfo(url=URL('https://sqladmin.googleapis.com/sql/v1beta4/projects/w210-capstone-ta/instances/w210-therapeutic-accelerator/connectSettings'), method='GET', headers=<CIMultiDictProxy('Host': 'sqladmin.googleapis.com', 'x-goog-api-client': 'cloud-sql-python-connector/1.2.3+pg8000', 'User-Agent': 'cloud-sql-python-connector/1.2.3+pg8000', 'Content-Type': 'application/json', 'Authorization': 'Bearer ya29.c.b0Aaekm1IY-VGbVQF2xAnFKLraacz4aWWINrWwumL0oEKATtsm27z8JAkL6smOHDDuVMEZcnyunbg_ECSPwUBg_x8Q_idoiNN1VENVTxHGMVrB-BHG9Bml0sqQl3Xq9xEnwVY9Jr4dtL8qOn9Aw-aUFXqI2LWxu-91iNrBEfRfF55dwCi6cBzZ6pigHoQuQptIU-ifSHd9P1H7O2o7k856XmTaioHiOJ6MWPf5a_wzdzq8UHfuGnp9a4P1Wcm-_4E-tRLWVDL5gSoeE1aqUAA96xZFUH2AdTTk49W8RnJqO5WhGwk72sfLLE6D5tCFxuxMAf8p2N6G7_rC-CYS1djxCSs7diTa89LF3e8hnLgH368PpbaY7Mzm08eQ-Xgef35d1QOrmcu_zrpxSBeBax3Sy_oc0slsobSlgJ91etzv4qbFJnF5p3oj6RQV9her5dmez1Ohgo2oY6IY4yIxgc01v_l0ls3tx3IFlXu-e_hhkFQcpR4ZyB_qWXVo45Q58sIhwshbnJuRqVBxyRRentplIfiu4YS_t_9y3Mcbdt_Vu-Fs_3UeaBp8fXhieO2uwclM0VYY2vwq7ZSqYXUZBnkd7FOq9x1YZzYtqbr9oORnrQ9ZZ2gOWWnJqkqtJnZ0ghXspRm3rYaWB6lfpeWgl9hhw1oJsu2kiYcIodjy4b22hvtZ7r9UnBq3ez-c9_SlYxrQpqSZs_yiIXqclzuqt6Byy9i73_z0nMruJJ1IBqlOS2ZbqkMVcb_4ean8tgntbkQ0VasxBQpxgSVgMOivokRIhBB9Q5F_ysiF71jRFQzXfcj9lXgOm_Q_V8iwjaVfFb4bqg7qJdSiOV2Wls8gXdOSSnBjOI2tufkex63wFQ4nU38I6FIt0Fgo5qsuOUgFyX4W68B9Zn_Xqeko5d711VBxyeVza0_mwx__dcfSk20jbIfzxRZOl5xzi2Iy1Vpm-9W9rJ2OsqZt2WWJf54Iuviiwr8e_9iBvJzYIcFcq_05ykruqxu0ri6rWOJ', 'Accept': '*/*', 'Accept-Encoding': 'gzip, deflate')>, real_url=URL('https://sqladmin.googleapis.com/sql/v1beta4/projects/w210-capstone-ta/instances/w210-therapeutic-accelerator/connectSettings')), (), status=404, message='Not Found', headers=<CIMultiDictProxy('Vary': 'Origin', 'Vary': 'X-Origin', 'Vary': 'Referer', 'Content-Type': 'application/json; charset=UTF-8', 'Content-Encoding': 'gzip', 'Date': 'Thu, 08 Jun 2023 00:34:42 GMT', 'Server': 'ESF', 'Cache-Control': 'private', 'X-XSS-Protection': '0', 'X-Frame-Options': 'SAMEORIGIN', 'X-Content-Type-Options': 'nosniff', 'Transfer-Encoding': 'chunked')>)>\n",
      "Traceback (most recent call last):\n",
      "  File \"/home/nick_lee_berkeley_edu/anaconda3/lib/python3.10/site-packages/google/cloud/sql/connector/instance.py\", line 388, in _refresh_task\n",
      "    refresh_data = await refresh_task\n",
      "  File \"/home/nick_lee_berkeley_edu/anaconda3/lib/python3.10/site-packages/google/cloud/sql/connector/instance.py\", line 312, in _perform_refresh\n",
      "    metadata = await metadata_task\n",
      "  File \"/home/nick_lee_berkeley_edu/anaconda3/lib/python3.10/site-packages/google/cloud/sql/connector/refresh_utils.py\", line 101, in _get_metadata\n",
      "    resp = await client_session.get(url, headers=headers, raise_for_status=True)\n",
      "  File \"/home/nick_lee_berkeley_edu/anaconda3/lib/python3.10/site-packages/aiohttp/client.py\", line 640, in _request\n",
      "    resp.raise_for_status()\n",
      "  File \"/home/nick_lee_berkeley_edu/anaconda3/lib/python3.10/site-packages/aiohttp/client_reqrep.py\", line 1004, in raise_for_status\n",
      "    raise ClientResponseError(\n",
      "aiohttp.client_exceptions.ClientResponseError: 404, message='Not Found', url=URL('https://sqladmin.googleapis.com/sql/v1beta4/projects/w210-capstone-ta/instances/w210-therapeutic-accelerator/connectSettings')\n",
      "['w210-capstone-ta:us-central1:w210-therapeutic-accelerator']: An error occurred while performing refresh. Scheduling another refresh attempt immediately\n",
      "Traceback (most recent call last):\n",
      "  File \"/home/nick_lee_berkeley_edu/anaconda3/lib/python3.10/site-packages/google/cloud/sql/connector/instance.py\", line 388, in _refresh_task\n",
      "    refresh_data = await refresh_task\n",
      "  File \"/home/nick_lee_berkeley_edu/anaconda3/lib/python3.10/site-packages/google/cloud/sql/connector/instance.py\", line 312, in _perform_refresh\n",
      "    metadata = await metadata_task\n",
      "  File \"/home/nick_lee_berkeley_edu/anaconda3/lib/python3.10/site-packages/google/cloud/sql/connector/refresh_utils.py\", line 101, in _get_metadata\n",
      "    resp = await client_session.get(url, headers=headers, raise_for_status=True)\n",
      "  File \"/home/nick_lee_berkeley_edu/anaconda3/lib/python3.10/site-packages/aiohttp/client.py\", line 640, in _request\n",
      "    resp.raise_for_status()\n",
      "  File \"/home/nick_lee_berkeley_edu/anaconda3/lib/python3.10/site-packages/aiohttp/client_reqrep.py\", line 1004, in raise_for_status\n",
      "    raise ClientResponseError(\n",
      "aiohttp.client_exceptions.ClientResponseError: 404, message='Not Found', url=URL('https://sqladmin.googleapis.com/sql/v1beta4/projects/w210-capstone-ta/instances/w210-therapeutic-accelerator/connectSettings')\n",
      "Task exception was never retrieved\n",
      "future: <Task finished name='Task-250' coro=<Instance._schedule_refresh.<locals>._refresh_task() done, defined at /home/nick_lee_berkeley_edu/anaconda3/lib/python3.10/site-packages/google/cloud/sql/connector/instance.py:377> exception=ClientResponseError(RequestInfo(url=URL('https://sqladmin.googleapis.com/sql/v1beta4/projects/w210-capstone-ta/instances/w210-therapeutic-accelerator/connectSettings'), method='GET', headers=<CIMultiDictProxy('Host': 'sqladmin.googleapis.com', 'x-goog-api-client': 'cloud-sql-python-connector/1.2.3+pg8000', 'User-Agent': 'cloud-sql-python-connector/1.2.3+pg8000', 'Content-Type': 'application/json', 'Authorization': 'Bearer ya29.c.b0Aaekm1IY-VGbVQF2xAnFKLraacz4aWWINrWwumL0oEKATtsm27z8JAkL6smOHDDuVMEZcnyunbg_ECSPwUBg_x8Q_idoiNN1VENVTxHGMVrB-BHG9Bml0sqQl3Xq9xEnwVY9Jr4dtL8qOn9Aw-aUFXqI2LWxu-91iNrBEfRfF55dwCi6cBzZ6pigHoQuQptIU-ifSHd9P1H7O2o7k856XmTaioHiOJ6MWPf5a_wzdzq8UHfuGnp9a4P1Wcm-_4E-tRLWVDL5gSoeE1aqUAA96xZFUH2AdTTk49W8RnJqO5WhGwk72sfLLE6D5tCFxuxMAf8p2N6G7_rC-CYS1djxCSs7diTa89LF3e8hnLgH368PpbaY7Mzm08eQ-Xgef35d1QOrmcu_zrpxSBeBax3Sy_oc0slsobSlgJ91etzv4qbFJnF5p3oj6RQV9her5dmez1Ohgo2oY6IY4yIxgc01v_l0ls3tx3IFlXu-e_hhkFQcpR4ZyB_qWXVo45Q58sIhwshbnJuRqVBxyRRentplIfiu4YS_t_9y3Mcbdt_Vu-Fs_3UeaBp8fXhieO2uwclM0VYY2vwq7ZSqYXUZBnkd7FOq9x1YZzYtqbr9oORnrQ9ZZ2gOWWnJqkqtJnZ0ghXspRm3rYaWB6lfpeWgl9hhw1oJsu2kiYcIodjy4b22hvtZ7r9UnBq3ez-c9_SlYxrQpqSZs_yiIXqclzuqt6Byy9i73_z0nMruJJ1IBqlOS2ZbqkMVcb_4ean8tgntbkQ0VasxBQpxgSVgMOivokRIhBB9Q5F_ysiF71jRFQzXfcj9lXgOm_Q_V8iwjaVfFb4bqg7qJdSiOV2Wls8gXdOSSnBjOI2tufkex63wFQ4nU38I6FIt0Fgo5qsuOUgFyX4W68B9Zn_Xqeko5d711VBxyeVza0_mwx__dcfSk20jbIfzxRZOl5xzi2Iy1Vpm-9W9rJ2OsqZt2WWJf54Iuviiwr8e_9iBvJzYIcFcq_05ykruqxu0ri6rWOJ', 'Accept': '*/*', 'Accept-Encoding': 'gzip, deflate')>, real_url=URL('https://sqladmin.googleapis.com/sql/v1beta4/projects/w210-capstone-ta/instances/w210-therapeutic-accelerator/connectSettings')), (), status=404, message='Not Found', headers=<CIMultiDictProxy('Vary': 'Origin', 'Vary': 'X-Origin', 'Vary': 'Referer', 'Content-Type': 'application/json; charset=UTF-8', 'Content-Encoding': 'gzip', 'Date': 'Thu, 08 Jun 2023 00:35:12 GMT', 'Server': 'ESF', 'Cache-Control': 'private', 'X-XSS-Protection': '0', 'X-Frame-Options': 'SAMEORIGIN', 'X-Content-Type-Options': 'nosniff', 'Transfer-Encoding': 'chunked')>)>\n",
      "Traceback (most recent call last):\n",
      "  File \"/home/nick_lee_berkeley_edu/anaconda3/lib/python3.10/site-packages/google/cloud/sql/connector/instance.py\", line 388, in _refresh_task\n",
      "    refresh_data = await refresh_task\n",
      "  File \"/home/nick_lee_berkeley_edu/anaconda3/lib/python3.10/site-packages/google/cloud/sql/connector/instance.py\", line 312, in _perform_refresh\n",
      "    metadata = await metadata_task\n",
      "  File \"/home/nick_lee_berkeley_edu/anaconda3/lib/python3.10/site-packages/google/cloud/sql/connector/refresh_utils.py\", line 101, in _get_metadata\n",
      "    resp = await client_session.get(url, headers=headers, raise_for_status=True)\n",
      "  File \"/home/nick_lee_berkeley_edu/anaconda3/lib/python3.10/site-packages/aiohttp/client.py\", line 640, in _request\n",
      "    resp.raise_for_status()\n",
      "  File \"/home/nick_lee_berkeley_edu/anaconda3/lib/python3.10/site-packages/aiohttp/client_reqrep.py\", line 1004, in raise_for_status\n",
      "    raise ClientResponseError(\n",
      "aiohttp.client_exceptions.ClientResponseError: 404, message='Not Found', url=URL('https://sqladmin.googleapis.com/sql/v1beta4/projects/w210-capstone-ta/instances/w210-therapeutic-accelerator/connectSettings')\n",
      "['w210-capstone-ta:us-central1:w210-therapeutic-accelerator']: An error occurred while performing refresh. Scheduling another refresh attempt immediately\n",
      "Traceback (most recent call last):\n",
      "  File \"/home/nick_lee_berkeley_edu/anaconda3/lib/python3.10/site-packages/google/cloud/sql/connector/instance.py\", line 388, in _refresh_task\n",
      "    refresh_data = await refresh_task\n",
      "  File \"/home/nick_lee_berkeley_edu/anaconda3/lib/python3.10/site-packages/google/cloud/sql/connector/instance.py\", line 312, in _perform_refresh\n",
      "    metadata = await metadata_task\n",
      "  File \"/home/nick_lee_berkeley_edu/anaconda3/lib/python3.10/site-packages/google/cloud/sql/connector/refresh_utils.py\", line 101, in _get_metadata\n",
      "    resp = await client_session.get(url, headers=headers, raise_for_status=True)\n",
      "  File \"/home/nick_lee_berkeley_edu/anaconda3/lib/python3.10/site-packages/aiohttp/client.py\", line 640, in _request\n",
      "    resp.raise_for_status()\n",
      "  File \"/home/nick_lee_berkeley_edu/anaconda3/lib/python3.10/site-packages/aiohttp/client_reqrep.py\", line 1004, in raise_for_status\n",
      "    raise ClientResponseError(\n",
      "aiohttp.client_exceptions.ClientResponseError: 404, message='Not Found', url=URL('https://sqladmin.googleapis.com/sql/v1beta4/projects/w210-capstone-ta/instances/w210-therapeutic-accelerator/connectSettings')\n",
      "Task exception was never retrieved\n",
      "future: <Task finished name='Task-259' coro=<Instance._schedule_refresh.<locals>._refresh_task() done, defined at /home/nick_lee_berkeley_edu/anaconda3/lib/python3.10/site-packages/google/cloud/sql/connector/instance.py:377> exception=ClientResponseError(RequestInfo(url=URL('https://sqladmin.googleapis.com/sql/v1beta4/projects/w210-capstone-ta/instances/w210-therapeutic-accelerator/connectSettings'), method='GET', headers=<CIMultiDictProxy('Host': 'sqladmin.googleapis.com', 'x-goog-api-client': 'cloud-sql-python-connector/1.2.3+pg8000', 'User-Agent': 'cloud-sql-python-connector/1.2.3+pg8000', 'Content-Type': 'application/json', 'Authorization': 'Bearer ya29.c.b0Aaekm1IY-VGbVQF2xAnFKLraacz4aWWINrWwumL0oEKATtsm27z8JAkL6smOHDDuVMEZcnyunbg_ECSPwUBg_x8Q_idoiNN1VENVTxHGMVrB-BHG9Bml0sqQl3Xq9xEnwVY9Jr4dtL8qOn9Aw-aUFXqI2LWxu-91iNrBEfRfF55dwCi6cBzZ6pigHoQuQptIU-ifSHd9P1H7O2o7k856XmTaioHiOJ6MWPf5a_wzdzq8UHfuGnp9a4P1Wcm-_4E-tRLWVDL5gSoeE1aqUAA96xZFUH2AdTTk49W8RnJqO5WhGwk72sfLLE6D5tCFxuxMAf8p2N6G7_rC-CYS1djxCSs7diTa89LF3e8hnLgH368PpbaY7Mzm08eQ-Xgef35d1QOrmcu_zrpxSBeBax3Sy_oc0slsobSlgJ91etzv4qbFJnF5p3oj6RQV9her5dmez1Ohgo2oY6IY4yIxgc01v_l0ls3tx3IFlXu-e_hhkFQcpR4ZyB_qWXVo45Q58sIhwshbnJuRqVBxyRRentplIfiu4YS_t_9y3Mcbdt_Vu-Fs_3UeaBp8fXhieO2uwclM0VYY2vwq7ZSqYXUZBnkd7FOq9x1YZzYtqbr9oORnrQ9ZZ2gOWWnJqkqtJnZ0ghXspRm3rYaWB6lfpeWgl9hhw1oJsu2kiYcIodjy4b22hvtZ7r9UnBq3ez-c9_SlYxrQpqSZs_yiIXqclzuqt6Byy9i73_z0nMruJJ1IBqlOS2ZbqkMVcb_4ean8tgntbkQ0VasxBQpxgSVgMOivokRIhBB9Q5F_ysiF71jRFQzXfcj9lXgOm_Q_V8iwjaVfFb4bqg7qJdSiOV2Wls8gXdOSSnBjOI2tufkex63wFQ4nU38I6FIt0Fgo5qsuOUgFyX4W68B9Zn_Xqeko5d711VBxyeVza0_mwx__dcfSk20jbIfzxRZOl5xzi2Iy1Vpm-9W9rJ2OsqZt2WWJf54Iuviiwr8e_9iBvJzYIcFcq_05ykruqxu0ri6rWOJ', 'Accept': '*/*', 'Accept-Encoding': 'gzip, deflate')>, real_url=URL('https://sqladmin.googleapis.com/sql/v1beta4/projects/w210-capstone-ta/instances/w210-therapeutic-accelerator/connectSettings')), (), status=404, message='Not Found', headers=<CIMultiDictProxy('Vary': 'Origin', 'Vary': 'X-Origin', 'Vary': 'Referer', 'Content-Type': 'application/json; charset=UTF-8', 'Content-Encoding': 'gzip', 'Date': 'Thu, 08 Jun 2023 00:35:42 GMT', 'Server': 'ESF', 'Cache-Control': 'private', 'X-XSS-Protection': '0', 'X-Frame-Options': 'SAMEORIGIN', 'X-Content-Type-Options': 'nosniff', 'Transfer-Encoding': 'chunked')>)>\n",
      "Traceback (most recent call last):\n",
      "  File \"/home/nick_lee_berkeley_edu/anaconda3/lib/python3.10/site-packages/google/cloud/sql/connector/instance.py\", line 388, in _refresh_task\n",
      "    refresh_data = await refresh_task\n",
      "  File \"/home/nick_lee_berkeley_edu/anaconda3/lib/python3.10/site-packages/google/cloud/sql/connector/instance.py\", line 312, in _perform_refresh\n",
      "    metadata = await metadata_task\n",
      "  File \"/home/nick_lee_berkeley_edu/anaconda3/lib/python3.10/site-packages/google/cloud/sql/connector/refresh_utils.py\", line 101, in _get_metadata\n",
      "    resp = await client_session.get(url, headers=headers, raise_for_status=True)\n",
      "  File \"/home/nick_lee_berkeley_edu/anaconda3/lib/python3.10/site-packages/aiohttp/client.py\", line 640, in _request\n",
      "    resp.raise_for_status()\n",
      "  File \"/home/nick_lee_berkeley_edu/anaconda3/lib/python3.10/site-packages/aiohttp/client_reqrep.py\", line 1004, in raise_for_status\n",
      "    raise ClientResponseError(\n",
      "aiohttp.client_exceptions.ClientResponseError: 404, message='Not Found', url=URL('https://sqladmin.googleapis.com/sql/v1beta4/projects/w210-capstone-ta/instances/w210-therapeutic-accelerator/connectSettings')\n",
      "['w210-capstone-ta:us-central1:w210-therapeutic-accelerator']: An error occurred while performing refresh. Scheduling another refresh attempt immediately\n",
      "Traceback (most recent call last):\n",
      "  File \"/home/nick_lee_berkeley_edu/anaconda3/lib/python3.10/site-packages/google/cloud/sql/connector/instance.py\", line 388, in _refresh_task\n",
      "    refresh_data = await refresh_task\n",
      "  File \"/home/nick_lee_berkeley_edu/anaconda3/lib/python3.10/site-packages/google/cloud/sql/connector/instance.py\", line 312, in _perform_refresh\n",
      "    metadata = await metadata_task\n",
      "  File \"/home/nick_lee_berkeley_edu/anaconda3/lib/python3.10/site-packages/google/cloud/sql/connector/refresh_utils.py\", line 101, in _get_metadata\n",
      "    resp = await client_session.get(url, headers=headers, raise_for_status=True)\n",
      "  File \"/home/nick_lee_berkeley_edu/anaconda3/lib/python3.10/site-packages/aiohttp/client.py\", line 640, in _request\n",
      "    resp.raise_for_status()\n",
      "  File \"/home/nick_lee_berkeley_edu/anaconda3/lib/python3.10/site-packages/aiohttp/client_reqrep.py\", line 1004, in raise_for_status\n",
      "    raise ClientResponseError(\n",
      "aiohttp.client_exceptions.ClientResponseError: 404, message='Not Found', url=URL('https://sqladmin.googleapis.com/sql/v1beta4/projects/w210-capstone-ta/instances/w210-therapeutic-accelerator/connectSettings')\n",
      "Task exception was never retrieved\n",
      "future: <Task finished name='Task-268' coro=<Instance._schedule_refresh.<locals>._refresh_task() done, defined at /home/nick_lee_berkeley_edu/anaconda3/lib/python3.10/site-packages/google/cloud/sql/connector/instance.py:377> exception=ClientResponseError(RequestInfo(url=URL('https://sqladmin.googleapis.com/sql/v1beta4/projects/w210-capstone-ta/instances/w210-therapeutic-accelerator/connectSettings'), method='GET', headers=<CIMultiDictProxy('Host': 'sqladmin.googleapis.com', 'x-goog-api-client': 'cloud-sql-python-connector/1.2.3+pg8000', 'User-Agent': 'cloud-sql-python-connector/1.2.3+pg8000', 'Content-Type': 'application/json', 'Authorization': 'Bearer ya29.c.b0Aaekm1IY-VGbVQF2xAnFKLraacz4aWWINrWwumL0oEKATtsm27z8JAkL6smOHDDuVMEZcnyunbg_ECSPwUBg_x8Q_idoiNN1VENVTxHGMVrB-BHG9Bml0sqQl3Xq9xEnwVY9Jr4dtL8qOn9Aw-aUFXqI2LWxu-91iNrBEfRfF55dwCi6cBzZ6pigHoQuQptIU-ifSHd9P1H7O2o7k856XmTaioHiOJ6MWPf5a_wzdzq8UHfuGnp9a4P1Wcm-_4E-tRLWVDL5gSoeE1aqUAA96xZFUH2AdTTk49W8RnJqO5WhGwk72sfLLE6D5tCFxuxMAf8p2N6G7_rC-CYS1djxCSs7diTa89LF3e8hnLgH368PpbaY7Mzm08eQ-Xgef35d1QOrmcu_zrpxSBeBax3Sy_oc0slsobSlgJ91etzv4qbFJnF5p3oj6RQV9her5dmez1Ohgo2oY6IY4yIxgc01v_l0ls3tx3IFlXu-e_hhkFQcpR4ZyB_qWXVo45Q58sIhwshbnJuRqVBxyRRentplIfiu4YS_t_9y3Mcbdt_Vu-Fs_3UeaBp8fXhieO2uwclM0VYY2vwq7ZSqYXUZBnkd7FOq9x1YZzYtqbr9oORnrQ9ZZ2gOWWnJqkqtJnZ0ghXspRm3rYaWB6lfpeWgl9hhw1oJsu2kiYcIodjy4b22hvtZ7r9UnBq3ez-c9_SlYxrQpqSZs_yiIXqclzuqt6Byy9i73_z0nMruJJ1IBqlOS2ZbqkMVcb_4ean8tgntbkQ0VasxBQpxgSVgMOivokRIhBB9Q5F_ysiF71jRFQzXfcj9lXgOm_Q_V8iwjaVfFb4bqg7qJdSiOV2Wls8gXdOSSnBjOI2tufkex63wFQ4nU38I6FIt0Fgo5qsuOUgFyX4W68B9Zn_Xqeko5d711VBxyeVza0_mwx__dcfSk20jbIfzxRZOl5xzi2Iy1Vpm-9W9rJ2OsqZt2WWJf54Iuviiwr8e_9iBvJzYIcFcq_05ykruqxu0ri6rWOJ', 'Accept': '*/*', 'Accept-Encoding': 'gzip, deflate')>, real_url=URL('https://sqladmin.googleapis.com/sql/v1beta4/projects/w210-capstone-ta/instances/w210-therapeutic-accelerator/connectSettings')), (), status=404, message='Not Found', headers=<CIMultiDictProxy('Vary': 'Origin', 'Vary': 'X-Origin', 'Vary': 'Referer', 'Content-Type': 'application/json; charset=UTF-8', 'Content-Encoding': 'gzip', 'Date': 'Thu, 08 Jun 2023 00:36:12 GMT', 'Server': 'ESF', 'Cache-Control': 'private', 'X-XSS-Protection': '0', 'X-Frame-Options': 'SAMEORIGIN', 'X-Content-Type-Options': 'nosniff', 'Transfer-Encoding': 'chunked')>)>\n",
      "Traceback (most recent call last):\n",
      "  File \"/home/nick_lee_berkeley_edu/anaconda3/lib/python3.10/site-packages/google/cloud/sql/connector/instance.py\", line 388, in _refresh_task\n",
      "    refresh_data = await refresh_task\n",
      "  File \"/home/nick_lee_berkeley_edu/anaconda3/lib/python3.10/site-packages/google/cloud/sql/connector/instance.py\", line 312, in _perform_refresh\n",
      "    metadata = await metadata_task\n",
      "  File \"/home/nick_lee_berkeley_edu/anaconda3/lib/python3.10/site-packages/google/cloud/sql/connector/refresh_utils.py\", line 101, in _get_metadata\n",
      "    resp = await client_session.get(url, headers=headers, raise_for_status=True)\n",
      "  File \"/home/nick_lee_berkeley_edu/anaconda3/lib/python3.10/site-packages/aiohttp/client.py\", line 640, in _request\n",
      "    resp.raise_for_status()\n",
      "  File \"/home/nick_lee_berkeley_edu/anaconda3/lib/python3.10/site-packages/aiohttp/client_reqrep.py\", line 1004, in raise_for_status\n",
      "    raise ClientResponseError(\n",
      "aiohttp.client_exceptions.ClientResponseError: 404, message='Not Found', url=URL('https://sqladmin.googleapis.com/sql/v1beta4/projects/w210-capstone-ta/instances/w210-therapeutic-accelerator/connectSettings')\n",
      "['w210-capstone-ta:us-central1:w210-therapeutic-accelerator']: An error occurred while performing refresh. Scheduling another refresh attempt immediately\n",
      "Traceback (most recent call last):\n",
      "  File \"/home/nick_lee_berkeley_edu/anaconda3/lib/python3.10/site-packages/google/cloud/sql/connector/instance.py\", line 388, in _refresh_task\n",
      "    refresh_data = await refresh_task\n",
      "  File \"/home/nick_lee_berkeley_edu/anaconda3/lib/python3.10/site-packages/google/cloud/sql/connector/instance.py\", line 312, in _perform_refresh\n",
      "    metadata = await metadata_task\n",
      "  File \"/home/nick_lee_berkeley_edu/anaconda3/lib/python3.10/site-packages/google/cloud/sql/connector/refresh_utils.py\", line 101, in _get_metadata\n",
      "    resp = await client_session.get(url, headers=headers, raise_for_status=True)\n",
      "  File \"/home/nick_lee_berkeley_edu/anaconda3/lib/python3.10/site-packages/aiohttp/client.py\", line 640, in _request\n",
      "    resp.raise_for_status()\n",
      "  File \"/home/nick_lee_berkeley_edu/anaconda3/lib/python3.10/site-packages/aiohttp/client_reqrep.py\", line 1004, in raise_for_status\n",
      "    raise ClientResponseError(\n",
      "aiohttp.client_exceptions.ClientResponseError: 404, message='Not Found', url=URL('https://sqladmin.googleapis.com/sql/v1beta4/projects/w210-capstone-ta/instances/w210-therapeutic-accelerator/connectSettings')\n",
      "Task exception was never retrieved\n",
      "future: <Task finished name='Task-277' coro=<Instance._schedule_refresh.<locals>._refresh_task() done, defined at /home/nick_lee_berkeley_edu/anaconda3/lib/python3.10/site-packages/google/cloud/sql/connector/instance.py:377> exception=ClientResponseError(RequestInfo(url=URL('https://sqladmin.googleapis.com/sql/v1beta4/projects/w210-capstone-ta/instances/w210-therapeutic-accelerator/connectSettings'), method='GET', headers=<CIMultiDictProxy('Host': 'sqladmin.googleapis.com', 'x-goog-api-client': 'cloud-sql-python-connector/1.2.3+pg8000', 'User-Agent': 'cloud-sql-python-connector/1.2.3+pg8000', 'Content-Type': 'application/json', 'Authorization': 'Bearer ya29.c.b0Aaekm1IY-VGbVQF2xAnFKLraacz4aWWINrWwumL0oEKATtsm27z8JAkL6smOHDDuVMEZcnyunbg_ECSPwUBg_x8Q_idoiNN1VENVTxHGMVrB-BHG9Bml0sqQl3Xq9xEnwVY9Jr4dtL8qOn9Aw-aUFXqI2LWxu-91iNrBEfRfF55dwCi6cBzZ6pigHoQuQptIU-ifSHd9P1H7O2o7k856XmTaioHiOJ6MWPf5a_wzdzq8UHfuGnp9a4P1Wcm-_4E-tRLWVDL5gSoeE1aqUAA96xZFUH2AdTTk49W8RnJqO5WhGwk72sfLLE6D5tCFxuxMAf8p2N6G7_rC-CYS1djxCSs7diTa89LF3e8hnLgH368PpbaY7Mzm08eQ-Xgef35d1QOrmcu_zrpxSBeBax3Sy_oc0slsobSlgJ91etzv4qbFJnF5p3oj6RQV9her5dmez1Ohgo2oY6IY4yIxgc01v_l0ls3tx3IFlXu-e_hhkFQcpR4ZyB_qWXVo45Q58sIhwshbnJuRqVBxyRRentplIfiu4YS_t_9y3Mcbdt_Vu-Fs_3UeaBp8fXhieO2uwclM0VYY2vwq7ZSqYXUZBnkd7FOq9x1YZzYtqbr9oORnrQ9ZZ2gOWWnJqkqtJnZ0ghXspRm3rYaWB6lfpeWgl9hhw1oJsu2kiYcIodjy4b22hvtZ7r9UnBq3ez-c9_SlYxrQpqSZs_yiIXqclzuqt6Byy9i73_z0nMruJJ1IBqlOS2ZbqkMVcb_4ean8tgntbkQ0VasxBQpxgSVgMOivokRIhBB9Q5F_ysiF71jRFQzXfcj9lXgOm_Q_V8iwjaVfFb4bqg7qJdSiOV2Wls8gXdOSSnBjOI2tufkex63wFQ4nU38I6FIt0Fgo5qsuOUgFyX4W68B9Zn_Xqeko5d711VBxyeVza0_mwx__dcfSk20jbIfzxRZOl5xzi2Iy1Vpm-9W9rJ2OsqZt2WWJf54Iuviiwr8e_9iBvJzYIcFcq_05ykruqxu0ri6rWOJ', 'Accept': '*/*', 'Accept-Encoding': 'gzip, deflate')>, real_url=URL('https://sqladmin.googleapis.com/sql/v1beta4/projects/w210-capstone-ta/instances/w210-therapeutic-accelerator/connectSettings')), (), status=404, message='Not Found', headers=<CIMultiDictProxy('Vary': 'Origin', 'Vary': 'X-Origin', 'Vary': 'Referer', 'Content-Type': 'application/json; charset=UTF-8', 'Content-Encoding': 'gzip', 'Date': 'Thu, 08 Jun 2023 00:36:42 GMT', 'Server': 'ESF', 'Cache-Control': 'private', 'X-XSS-Protection': '0', 'X-Frame-Options': 'SAMEORIGIN', 'X-Content-Type-Options': 'nosniff', 'Transfer-Encoding': 'chunked')>)>\n",
      "Traceback (most recent call last):\n",
      "  File \"/home/nick_lee_berkeley_edu/anaconda3/lib/python3.10/site-packages/google/cloud/sql/connector/instance.py\", line 388, in _refresh_task\n",
      "    refresh_data = await refresh_task\n",
      "  File \"/home/nick_lee_berkeley_edu/anaconda3/lib/python3.10/site-packages/google/cloud/sql/connector/instance.py\", line 312, in _perform_refresh\n",
      "    metadata = await metadata_task\n",
      "  File \"/home/nick_lee_berkeley_edu/anaconda3/lib/python3.10/site-packages/google/cloud/sql/connector/refresh_utils.py\", line 101, in _get_metadata\n",
      "    resp = await client_session.get(url, headers=headers, raise_for_status=True)\n",
      "  File \"/home/nick_lee_berkeley_edu/anaconda3/lib/python3.10/site-packages/aiohttp/client.py\", line 640, in _request\n",
      "    resp.raise_for_status()\n",
      "  File \"/home/nick_lee_berkeley_edu/anaconda3/lib/python3.10/site-packages/aiohttp/client_reqrep.py\", line 1004, in raise_for_status\n",
      "    raise ClientResponseError(\n",
      "aiohttp.client_exceptions.ClientResponseError: 404, message='Not Found', url=URL('https://sqladmin.googleapis.com/sql/v1beta4/projects/w210-capstone-ta/instances/w210-therapeutic-accelerator/connectSettings')\n",
      "['w210-capstone-ta:us-central1:w210-therapeutic-accelerator']: An error occurred while performing refresh. Scheduling another refresh attempt immediately\n",
      "Traceback (most recent call last):\n",
      "  File \"/home/nick_lee_berkeley_edu/anaconda3/lib/python3.10/site-packages/google/cloud/sql/connector/instance.py\", line 388, in _refresh_task\n",
      "    refresh_data = await refresh_task\n",
      "  File \"/home/nick_lee_berkeley_edu/anaconda3/lib/python3.10/site-packages/google/cloud/sql/connector/instance.py\", line 312, in _perform_refresh\n",
      "    metadata = await metadata_task\n",
      "  File \"/home/nick_lee_berkeley_edu/anaconda3/lib/python3.10/site-packages/google/cloud/sql/connector/refresh_utils.py\", line 101, in _get_metadata\n",
      "    resp = await client_session.get(url, headers=headers, raise_for_status=True)\n",
      "  File \"/home/nick_lee_berkeley_edu/anaconda3/lib/python3.10/site-packages/aiohttp/client.py\", line 640, in _request\n",
      "    resp.raise_for_status()\n",
      "  File \"/home/nick_lee_berkeley_edu/anaconda3/lib/python3.10/site-packages/aiohttp/client_reqrep.py\", line 1004, in raise_for_status\n",
      "    raise ClientResponseError(\n",
      "aiohttp.client_exceptions.ClientResponseError: 404, message='Not Found', url=URL('https://sqladmin.googleapis.com/sql/v1beta4/projects/w210-capstone-ta/instances/w210-therapeutic-accelerator/connectSettings')\n",
      "Task exception was never retrieved\n",
      "future: <Task finished name='Task-286' coro=<Instance._schedule_refresh.<locals>._refresh_task() done, defined at /home/nick_lee_berkeley_edu/anaconda3/lib/python3.10/site-packages/google/cloud/sql/connector/instance.py:377> exception=ClientResponseError(RequestInfo(url=URL('https://sqladmin.googleapis.com/sql/v1beta4/projects/w210-capstone-ta/instances/w210-therapeutic-accelerator/connectSettings'), method='GET', headers=<CIMultiDictProxy('Host': 'sqladmin.googleapis.com', 'x-goog-api-client': 'cloud-sql-python-connector/1.2.3+pg8000', 'User-Agent': 'cloud-sql-python-connector/1.2.3+pg8000', 'Content-Type': 'application/json', 'Authorization': 'Bearer ya29.c.b0Aaekm1IY-VGbVQF2xAnFKLraacz4aWWINrWwumL0oEKATtsm27z8JAkL6smOHDDuVMEZcnyunbg_ECSPwUBg_x8Q_idoiNN1VENVTxHGMVrB-BHG9Bml0sqQl3Xq9xEnwVY9Jr4dtL8qOn9Aw-aUFXqI2LWxu-91iNrBEfRfF55dwCi6cBzZ6pigHoQuQptIU-ifSHd9P1H7O2o7k856XmTaioHiOJ6MWPf5a_wzdzq8UHfuGnp9a4P1Wcm-_4E-tRLWVDL5gSoeE1aqUAA96xZFUH2AdTTk49W8RnJqO5WhGwk72sfLLE6D5tCFxuxMAf8p2N6G7_rC-CYS1djxCSs7diTa89LF3e8hnLgH368PpbaY7Mzm08eQ-Xgef35d1QOrmcu_zrpxSBeBax3Sy_oc0slsobSlgJ91etzv4qbFJnF5p3oj6RQV9her5dmez1Ohgo2oY6IY4yIxgc01v_l0ls3tx3IFlXu-e_hhkFQcpR4ZyB_qWXVo45Q58sIhwshbnJuRqVBxyRRentplIfiu4YS_t_9y3Mcbdt_Vu-Fs_3UeaBp8fXhieO2uwclM0VYY2vwq7ZSqYXUZBnkd7FOq9x1YZzYtqbr9oORnrQ9ZZ2gOWWnJqkqtJnZ0ghXspRm3rYaWB6lfpeWgl9hhw1oJsu2kiYcIodjy4b22hvtZ7r9UnBq3ez-c9_SlYxrQpqSZs_yiIXqclzuqt6Byy9i73_z0nMruJJ1IBqlOS2ZbqkMVcb_4ean8tgntbkQ0VasxBQpxgSVgMOivokRIhBB9Q5F_ysiF71jRFQzXfcj9lXgOm_Q_V8iwjaVfFb4bqg7qJdSiOV2Wls8gXdOSSnBjOI2tufkex63wFQ4nU38I6FIt0Fgo5qsuOUgFyX4W68B9Zn_Xqeko5d711VBxyeVza0_mwx__dcfSk20jbIfzxRZOl5xzi2Iy1Vpm-9W9rJ2OsqZt2WWJf54Iuviiwr8e_9iBvJzYIcFcq_05ykruqxu0ri6rWOJ', 'Accept': '*/*', 'Accept-Encoding': 'gzip, deflate')>, real_url=URL('https://sqladmin.googleapis.com/sql/v1beta4/projects/w210-capstone-ta/instances/w210-therapeutic-accelerator/connectSettings')), (), status=404, message='Not Found', headers=<CIMultiDictProxy('Vary': 'Origin', 'Vary': 'X-Origin', 'Vary': 'Referer', 'Content-Type': 'application/json; charset=UTF-8', 'Content-Encoding': 'gzip', 'Date': 'Thu, 08 Jun 2023 00:37:12 GMT', 'Server': 'ESF', 'Cache-Control': 'private', 'X-XSS-Protection': '0', 'X-Frame-Options': 'SAMEORIGIN', 'X-Content-Type-Options': 'nosniff', 'Transfer-Encoding': 'chunked')>)>\n",
      "Traceback (most recent call last):\n",
      "  File \"/home/nick_lee_berkeley_edu/anaconda3/lib/python3.10/site-packages/google/cloud/sql/connector/instance.py\", line 388, in _refresh_task\n",
      "    refresh_data = await refresh_task\n",
      "  File \"/home/nick_lee_berkeley_edu/anaconda3/lib/python3.10/site-packages/google/cloud/sql/connector/instance.py\", line 312, in _perform_refresh\n",
      "    metadata = await metadata_task\n",
      "  File \"/home/nick_lee_berkeley_edu/anaconda3/lib/python3.10/site-packages/google/cloud/sql/connector/refresh_utils.py\", line 101, in _get_metadata\n",
      "    resp = await client_session.get(url, headers=headers, raise_for_status=True)\n",
      "  File \"/home/nick_lee_berkeley_edu/anaconda3/lib/python3.10/site-packages/aiohttp/client.py\", line 640, in _request\n",
      "    resp.raise_for_status()\n",
      "  File \"/home/nick_lee_berkeley_edu/anaconda3/lib/python3.10/site-packages/aiohttp/client_reqrep.py\", line 1004, in raise_for_status\n",
      "    raise ClientResponseError(\n",
      "aiohttp.client_exceptions.ClientResponseError: 404, message='Not Found', url=URL('https://sqladmin.googleapis.com/sql/v1beta4/projects/w210-capstone-ta/instances/w210-therapeutic-accelerator/connectSettings')\n",
      "['w210-capstone-ta:us-central1:w210-therapeutic-accelerator']: An error occurred while performing refresh. Scheduling another refresh attempt immediately\n",
      "Traceback (most recent call last):\n",
      "  File \"/home/nick_lee_berkeley_edu/anaconda3/lib/python3.10/site-packages/google/cloud/sql/connector/instance.py\", line 388, in _refresh_task\n",
      "    refresh_data = await refresh_task\n",
      "  File \"/home/nick_lee_berkeley_edu/anaconda3/lib/python3.10/site-packages/google/cloud/sql/connector/instance.py\", line 312, in _perform_refresh\n",
      "    metadata = await metadata_task\n",
      "  File \"/home/nick_lee_berkeley_edu/anaconda3/lib/python3.10/site-packages/google/cloud/sql/connector/refresh_utils.py\", line 101, in _get_metadata\n",
      "    resp = await client_session.get(url, headers=headers, raise_for_status=True)\n",
      "  File \"/home/nick_lee_berkeley_edu/anaconda3/lib/python3.10/site-packages/aiohttp/client.py\", line 640, in _request\n",
      "    resp.raise_for_status()\n",
      "  File \"/home/nick_lee_berkeley_edu/anaconda3/lib/python3.10/site-packages/aiohttp/client_reqrep.py\", line 1004, in raise_for_status\n",
      "    raise ClientResponseError(\n",
      "aiohttp.client_exceptions.ClientResponseError: 404, message='Not Found', url=URL('https://sqladmin.googleapis.com/sql/v1beta4/projects/w210-capstone-ta/instances/w210-therapeutic-accelerator/connectSettings')\n",
      "Task exception was never retrieved\n",
      "future: <Task finished name='Task-295' coro=<Instance._schedule_refresh.<locals>._refresh_task() done, defined at /home/nick_lee_berkeley_edu/anaconda3/lib/python3.10/site-packages/google/cloud/sql/connector/instance.py:377> exception=ClientResponseError(RequestInfo(url=URL('https://sqladmin.googleapis.com/sql/v1beta4/projects/w210-capstone-ta/instances/w210-therapeutic-accelerator/connectSettings'), method='GET', headers=<CIMultiDictProxy('Host': 'sqladmin.googleapis.com', 'x-goog-api-client': 'cloud-sql-python-connector/1.2.3+pg8000', 'User-Agent': 'cloud-sql-python-connector/1.2.3+pg8000', 'Content-Type': 'application/json', 'Authorization': 'Bearer ya29.c.b0Aaekm1IY-VGbVQF2xAnFKLraacz4aWWINrWwumL0oEKATtsm27z8JAkL6smOHDDuVMEZcnyunbg_ECSPwUBg_x8Q_idoiNN1VENVTxHGMVrB-BHG9Bml0sqQl3Xq9xEnwVY9Jr4dtL8qOn9Aw-aUFXqI2LWxu-91iNrBEfRfF55dwCi6cBzZ6pigHoQuQptIU-ifSHd9P1H7O2o7k856XmTaioHiOJ6MWPf5a_wzdzq8UHfuGnp9a4P1Wcm-_4E-tRLWVDL5gSoeE1aqUAA96xZFUH2AdTTk49W8RnJqO5WhGwk72sfLLE6D5tCFxuxMAf8p2N6G7_rC-CYS1djxCSs7diTa89LF3e8hnLgH368PpbaY7Mzm08eQ-Xgef35d1QOrmcu_zrpxSBeBax3Sy_oc0slsobSlgJ91etzv4qbFJnF5p3oj6RQV9her5dmez1Ohgo2oY6IY4yIxgc01v_l0ls3tx3IFlXu-e_hhkFQcpR4ZyB_qWXVo45Q58sIhwshbnJuRqVBxyRRentplIfiu4YS_t_9y3Mcbdt_Vu-Fs_3UeaBp8fXhieO2uwclM0VYY2vwq7ZSqYXUZBnkd7FOq9x1YZzYtqbr9oORnrQ9ZZ2gOWWnJqkqtJnZ0ghXspRm3rYaWB6lfpeWgl9hhw1oJsu2kiYcIodjy4b22hvtZ7r9UnBq3ez-c9_SlYxrQpqSZs_yiIXqclzuqt6Byy9i73_z0nMruJJ1IBqlOS2ZbqkMVcb_4ean8tgntbkQ0VasxBQpxgSVgMOivokRIhBB9Q5F_ysiF71jRFQzXfcj9lXgOm_Q_V8iwjaVfFb4bqg7qJdSiOV2Wls8gXdOSSnBjOI2tufkex63wFQ4nU38I6FIt0Fgo5qsuOUgFyX4W68B9Zn_Xqeko5d711VBxyeVza0_mwx__dcfSk20jbIfzxRZOl5xzi2Iy1Vpm-9W9rJ2OsqZt2WWJf54Iuviiwr8e_9iBvJzYIcFcq_05ykruqxu0ri6rWOJ', 'Accept': '*/*', 'Accept-Encoding': 'gzip, deflate')>, real_url=URL('https://sqladmin.googleapis.com/sql/v1beta4/projects/w210-capstone-ta/instances/w210-therapeutic-accelerator/connectSettings')), (), status=404, message='Not Found', headers=<CIMultiDictProxy('Vary': 'Origin', 'Vary': 'X-Origin', 'Vary': 'Referer', 'Content-Type': 'application/json; charset=UTF-8', 'Content-Encoding': 'gzip', 'Date': 'Thu, 08 Jun 2023 00:37:42 GMT', 'Server': 'ESF', 'Cache-Control': 'private', 'X-XSS-Protection': '0', 'X-Frame-Options': 'SAMEORIGIN', 'X-Content-Type-Options': 'nosniff', 'Transfer-Encoding': 'chunked')>)>\n",
      "Traceback (most recent call last):\n",
      "  File \"/home/nick_lee_berkeley_edu/anaconda3/lib/python3.10/site-packages/google/cloud/sql/connector/instance.py\", line 388, in _refresh_task\n",
      "    refresh_data = await refresh_task\n",
      "  File \"/home/nick_lee_berkeley_edu/anaconda3/lib/python3.10/site-packages/google/cloud/sql/connector/instance.py\", line 312, in _perform_refresh\n",
      "    metadata = await metadata_task\n",
      "  File \"/home/nick_lee_berkeley_edu/anaconda3/lib/python3.10/site-packages/google/cloud/sql/connector/refresh_utils.py\", line 101, in _get_metadata\n",
      "    resp = await client_session.get(url, headers=headers, raise_for_status=True)\n",
      "  File \"/home/nick_lee_berkeley_edu/anaconda3/lib/python3.10/site-packages/aiohttp/client.py\", line 640, in _request\n",
      "    resp.raise_for_status()\n",
      "  File \"/home/nick_lee_berkeley_edu/anaconda3/lib/python3.10/site-packages/aiohttp/client_reqrep.py\", line 1004, in raise_for_status\n",
      "    raise ClientResponseError(\n",
      "aiohttp.client_exceptions.ClientResponseError: 404, message='Not Found', url=URL('https://sqladmin.googleapis.com/sql/v1beta4/projects/w210-capstone-ta/instances/w210-therapeutic-accelerator/connectSettings')\n"
     ]
    }
   ],
   "source": [
    "# connect to connection pool\n",
    "with pool.connect() as db_conn:\n",
    "  # create ratings table in our sandwiches database\n",
    "  db_conn.execute(\n",
    "    sqlalchemy.text(\n",
    "      \"CREATE TABLE IF NOT EXISTS semantic \"\n",
    "      \"( id SERIAL NOT NULL, \"\n",
    "      \" paper_id VARCHAR(255) NOT NULL, \"\n",
    "      \" title VARCHAR(255) NOT NULL, \"\n",
    "      \" reference_count integer, \"\n",
    "      \" citation_count integer, \"\n",
    "      \" embeddings double precision[],\"\n",
    "      \"PRIMARY KEY (id));\"\n",
    "    )\n",
    "  )\n",
    "\n",
    "  # commit transaction (SQLAlchemy v2.X.X is commit as you go)\n",
    "  db_conn.commit()\n",
    "\n",
    "  # insert data into our ratings table\n",
    "  insert_stmt = sqlalchemy.text(\n",
    "      \"INSERT INTO semantic (paper_id, title, reference_count) VALUES (:paper_id, :title, :reference_count)\",\n",
    "  )\n",
    "\n",
    "  # insert entries into table\n",
    "  db_conn.execute(insert_stmt, parameters={\"paper_id\": \"649def34f8be52c8b66281af98ae884c09aef38b\", \"title\": \"Construction of the Literature Graph in Semantic Scholar\", \"reference_count\": 27})\n",
    "  db_conn.execute(insert_stmt, parameters={\"paper_id\": \"f712fab0d58ae6492e3cdfc1933dae103ec12d5d\", \"title\": \"Reinfection and low cross-immunity as drivers of epidemic resurgence under high seroprevalence: a model-based approach with application to Amazonas, Brazil\", \"reference_count\": 13})\n",
    "\n",
    "  # commit transactions\n",
    "  db_conn.commit()\n",
    "\n",
    "  # query and fetch ratings table\n",
    "  results = db_conn.execute(sqlalchemy.text(\"SELECT * FROM semantic\")).fetchall()\n",
    "\n",
    "  # show results\n",
    "  for row in results:\n",
    "    print(row)\n",
    "\n",
    "# cleanup connector object\n",
    "connector.close()"
   ]
  },
  {
   "cell_type": "code",
   "execution_count": null,
   "metadata": {},
   "outputs": [],
   "source": [
    "# filename = 'papers-part0.jsonl'\n",
    "# import jsonlines\n",
    "\n",
    "# with jsonlines.open('your-filename.jsonl') as f:\n",
    "\n",
    "#     for line in f.iter():\n",
    "\n",
    "#         print line['doi'] # or whatever else you'd like to do"
   ]
  },
  {
   "cell_type": "code",
   "execution_count": 3,
   "metadata": {},
   "outputs": [],
   "source": [
    "import os\n",
    "import json\n",
    "from zipfile import ZipFile\n",
    "\n",
    "import pandas as pd\n",
    "import numpy as np"
   ]
  },
  {
   "cell_type": "code",
   "execution_count": 8,
   "metadata": {},
   "outputs": [],
   "source": []
  },
  {
   "cell_type": "code",
   "execution_count": 9,
   "metadata": {},
   "outputs": [
    {
     "data": {
      "text/plain": [
       "'/home/nick_lee_berkeley_edu/mount-folder'"
      ]
     },
     "execution_count": 9,
     "metadata": {},
     "output_type": "execute_result"
    }
   ],
   "source": [
    "mount_path"
   ]
  },
  {
   "cell_type": "code",
   "execution_count": 15,
   "metadata": {},
   "outputs": [],
   "source": [
    "z_files = []\n",
    "for root, dirs, files in os.walk(mount_path, topdown=False):\n",
    "    for name in files:\n",
    "        z_files.append(os.path.join(root, name))"
   ]
  },
  {
   "cell_type": "code",
   "execution_count": 16,
   "metadata": {
    "scrolled": true
   },
   "outputs": [
    {
     "data": {
      "text/plain": [
       "['/home/nick_lee_berkeley_edu/mount-folder/20230526_112152_00030_xnreq_04b16e60-4286-40b0-a62f-e8837f4b2aa0.gz',\n",
       " '/home/nick_lee_berkeley_edu/mount-folder/20230526_112152_00030_xnreq_100832cd-a187-47dd-b091-29981f6b612c.gz',\n",
       " '/home/nick_lee_berkeley_edu/mount-folder/20230526_112152_00030_xnreq_196048cb-e25f-49ff-b821-5e08014f9c2b.gz',\n",
       " '/home/nick_lee_berkeley_edu/mount-folder/20230526_112152_00030_xnreq_1d70c526-9586-42f5-a525-5c98c50f0da4.gz',\n",
       " '/home/nick_lee_berkeley_edu/mount-folder/20230526_112152_00030_xnreq_3749204d-196a-4f70-8425-636c169e5d14.gz',\n",
       " '/home/nick_lee_berkeley_edu/mount-folder/20230526_112152_00030_xnreq_3e5fe054-6c1f-47e9-bbb2-80fef44856c1.gz',\n",
       " '/home/nick_lee_berkeley_edu/mount-folder/20230526_112152_00030_xnreq_42f02e7a-6814-43e7-a667-e958bc8daeab.gz',\n",
       " '/home/nick_lee_berkeley_edu/mount-folder/20230526_112152_00030_xnreq_49b9cbc6-07bb-4bae-9d68-b1958d5d7fec.gz',\n",
       " '/home/nick_lee_berkeley_edu/mount-folder/20230526_112152_00030_xnreq_522379af-d3ac-4b56-a378-c33a121fb9f5.gz',\n",
       " '/home/nick_lee_berkeley_edu/mount-folder/20230526_112152_00030_xnreq_60e89b62-be43-4fe6-9401-bba6269656c3.gz',\n",
       " '/home/nick_lee_berkeley_edu/mount-folder/20230526_112152_00030_xnreq_7ae327f0-feb4-44d8-96b3-1ab1781e2456.gz',\n",
       " '/home/nick_lee_berkeley_edu/mount-folder/20230526_112152_00030_xnreq_86552c09-ff7d-4082-83af-63039bd348d6.gz',\n",
       " '/home/nick_lee_berkeley_edu/mount-folder/20230526_112152_00030_xnreq_8703e006-4a83-4880-89ab-274b4c85e60a.gz',\n",
       " '/home/nick_lee_berkeley_edu/mount-folder/20230526_112152_00030_xnreq_8d3ddfed-6d7c-4fd4-8b94-6ebb2286a185.gz',\n",
       " '/home/nick_lee_berkeley_edu/mount-folder/20230526_112152_00030_xnreq_95516b1f-426c-4e45-aaec-915d0e76772f.gz',\n",
       " '/home/nick_lee_berkeley_edu/mount-folder/20230526_112152_00030_xnreq_a38bd4d0-0750-4f6d-b2b0-49da05f8ca1f.gz',\n",
       " '/home/nick_lee_berkeley_edu/mount-folder/20230526_112152_00030_xnreq_a3eb50d4-3261-4728-9f5e-e9d2b55dde6b.gz',\n",
       " '/home/nick_lee_berkeley_edu/mount-folder/20230526_112152_00030_xnreq_aa943505-789a-43ab-b47d-1a280128e8d2.gz',\n",
       " '/home/nick_lee_berkeley_edu/mount-folder/20230526_112152_00030_xnreq_ab7bc293-50fb-4a69-8e6a-03d59a5665c8.gz',\n",
       " '/home/nick_lee_berkeley_edu/mount-folder/20230526_112152_00030_xnreq_c052ec90-f34a-4d20-ab6d-1cbe8cc0df08.gz',\n",
       " '/home/nick_lee_berkeley_edu/mount-folder/20230526_112152_00030_xnreq_c2be56fb-94d5-4c53-b798-bbf963388703.gz',\n",
       " '/home/nick_lee_berkeley_edu/mount-folder/20230526_112152_00030_xnreq_d38c3c25-a8e6-4290-8ca9-af90f4a54473.gz',\n",
       " '/home/nick_lee_berkeley_edu/mount-folder/20230526_112152_00030_xnreq_d93fc755-a3a6-4dd3-a058-dab3b0006725.gz',\n",
       " '/home/nick_lee_berkeley_edu/mount-folder/20230526_112152_00030_xnreq_efdad894-f791-45ab-8db8-f66c8df333cf.gz',\n",
       " '/home/nick_lee_berkeley_edu/mount-folder/20230526_112152_00030_xnreq_f7bde050-545f-4106-b867-fff568dd735c.gz',\n",
       " '/home/nick_lee_berkeley_edu/mount-folder/20230526_112152_00030_xnreq_f928f687-34a3-4e00-9bb6-9ff5b4110824.gz']"
      ]
     },
     "execution_count": 16,
     "metadata": {},
     "output_type": "execute_result"
    }
   ],
   "source": [
    "z_files"
   ]
  },
  {
   "cell_type": "code",
   "execution_count": null,
   "metadata": {},
   "outputs": [],
   "source": [
    "import gzip\n",
    "import shutil\n",
    "with gzip.open(z_files[0], 'rb') as f:\n",
    "    file_content = f.read()"
   ]
  },
  {
   "cell_type": "code",
   "execution_count": null,
   "metadata": {},
   "outputs": [],
   "source": [
    "file_content"
   ]
  },
  {
   "cell_type": "code",
   "execution_count": null,
   "metadata": {},
   "outputs": [],
   "source": [
    "# get embeddings\n",
    "from typing import Dict, List\n",
    "import json\n",
    "\n",
    "import requests\n",
    "\n",
    "\n",
    "URL = \"https://model-apis.semanticscholar.org/specter/v1/invoke\"\n",
    "MAX_BATCH_SIZE = 16\n",
    "\n",
    "def chunks(lst, chunk_size=MAX_BATCH_SIZE):\n",
    "    \"\"\"Splits a longer list to respect batch size\"\"\"\n",
    "    for i in range(0, len(lst), chunk_size):\n",
    "        yield lst[i : i + chunk_size]\n",
    "\n",
    "\n",
    "SAMPLE_PAPERS = [\n",
    "    {\n",
    "        \"paper_id\": \"A\",\n",
    "        \"title\": \"Angiotensin-converting enzyme 2 is a functional receptor for the SARS coronavirus\",\n",
    "        \"abstract\": \"Spike (S) proteins of coronaviruses ...\",\n",
    "    },\n",
    "    {\n",
    "        \"paper_id\": \"B\",\n",
    "        \"title\": \"Hospital outbreak of Middle East respiratory syndrome coronavirus\",\n",
    "        \"abstract\": \"Between April 1 and May 23, 2013, a total of 23 cases of MERS-CoV ...\",\n",
    "    },\n",
    "]\n",
    "\n",
    "\n",
    "def embed(papers):\n",
    "    embeddings_by_paper_id: Dict[str, List[float]] = {}\n",
    "\n",
    "    for chunk in chunks(papers):\n",
    "        # Allow Python requests to convert the data above to JSON\n",
    "        response = requests.post(URL, json=chunk)\n",
    "\n",
    "        if response.status_code != 200:\n",
    "            raise RuntimeError(\"Sorry, something went wrong, please try later!\")\n",
    "\n",
    "        for paper in response.json()[\"preds\"]:\n",
    "            embeddings_by_paper_id[paper[\"paper_id\"]] = paper[\"embedding\"]\n",
    "\n",
    "    return embeddings_by_paper_id\n",
    "\n",
    "if __name__ == \"__main__\":\n",
    "    all_embeddings = embed(SAMPLE_PAPERS)\n",
    "\n",
    "    # Prints { 'A': [4.089589595794678, ...], 'B': [-0.15814849734306335, ...] }\n",
    "    print(all_embeddings)"
   ]
  }
 ],
 "metadata": {
  "kernelspec": {
   "display_name": "base",
   "language": "python",
   "name": "base"
  },
  "language_info": {
   "codemirror_mode": {
    "name": "ipython",
    "version": 3
   },
   "file_extension": ".py",
   "mimetype": "text/x-python",
   "name": "python",
   "nbconvert_exporter": "python",
   "pygments_lexer": "ipython3",
   "version": "3.10.9"
  }
 },
 "nbformat": 4,
 "nbformat_minor": 4
}
